Workbook

Sheet 铝耗
A1: 序号 | B1: 适用 牌号 | C1: 分类 序号 | D1: 最小厚度mm | E1: 最大厚度mm | F1: 炼钢 牌号 | G1: 钢种类型 | H1: 液相线温度℃ | I1: 内控成分目标值/wt% | AA1: 备注 | AB1: 铝块---方法1 | AC1: 铝块---方法2 | AD1: 实际铝铝耗2026年 | AE1: 实际铝铝耗2025年 | AF1: 实际铝铝耗
I2: C | J2: Si | K2: Mn | L2: P | M2: S | N2: V | O2: Nb | P2: Ti | Q2: Als | R2: Alt | S2: Ca | T2: Cr | U2: Ni | V2: Cu | W2: Mo | X2: B | Y2: Sb | Z2: N | AB2: 99
B3: 合金不含税价格 | AB3: ='[1]6.合金辅料价格'!K8 -> 22337.168
A4: 1 | B4: Q195 | C4: 01 | D4: 1.5 | E4: 12 | F4: Q195-1 | G4: A 碳素钢-碳素结构钢-A20 Q195 | H4: 1527 | I4: 0.07 | J4: 0.15 | K4: 0.25 | L4: 0.02 | M4: 0.015 | P4: 0.01 | Q4: 0.01 | Z4: 60 | AB4: {=IF(R4="",IF(Q4="",0,(_xlfn.IFS(Q4=0.01,0.67,Q4=0.015,1,Q4=0.015,1.33,Q4=0.02,1.67,Q4=0.025,2,Q4=0.03,2.33,Q4=0.035,2.67,Q4=0.04,3)+IF(J4<=0.03,"0.33",0))),(_xlfn.IFS(R4=0.01,0.67,R4=0.015,1,R4=0.015,1.33,R4=0.02,1.67,R4=0.025,2,R4=0.03,2.33,R4=0.035,2.67,R4=0.04,3)+IF(J4<=0.03,"0.33",0)))} -> 0.67 | AC4: =IF(R4="",IF(Q4="",0.3,Q4/100/0.99/0.15*1000+IF(J4<=0.03,"0.33",0)),R4/100/0.99/0.15*1000+IF(J4<=0.03,"0.33",0)) -> 0.67340067 | AD4: =VLOOKUP(F4,铝耗2026年!$A$2:$B$5000,2,0) -> #N/A | AE4: =VLOOKUP(F4,铝耗2025年!$A$2:$B$5000,2,0) -> 1.45 | AF4: 1.45
A5: 2 | B5: Q195 | C5: 02 | D5: 12.01 | E5: 28 | F5: Q195-2 | G5: A 碳素钢-碳素结构钢-A20 Q195 | H5: 1527 | I5: 0.07 | J5: 0.15 | K5: 0.32 | L5: 0.02 | M5: 0.015 | Q5: 0.01 | Z5: 60 | AB5: {=IF(R5="",IF(Q5="",0,(_xlfn.IFS(Q5=0.01,0.67,Q5=0.015,1,Q5=0.015,1.33,Q5=0.02,1.67,Q5=0.025,2,Q5=0.03,2.33,Q5=0.035,2.67,Q5=0.04,3)+IF(J5<=0.03,"0.33",0))),(_xlfn.IFS(R5=0.01,0.67,R5=0.015,1,R5=0.015,1.33,R5=0.02,1.67,R5=0.025,2,R5=0.03,2.33,R5=0.035,2.67,R5=0.04,3)+IF(J5<=0.03,"0.33",0)))} -> 0.67 | AC5: =IF(R5="",IF(Q5="",0.3,Q5/100/0.99/0.15*1000+IF(J5<=0.03,"0.33",0)),R5/100/0.99/0.15*1000+IF(J5<=0.03,"0.33",0)) -> 0.67340067 | AD5: =VLOOKUP(F5,铝耗2026年!$A$2:$B$5000,2,0) -> #N/A | AE5: =VLOOKUP(F5,铝耗2025年!$A$2:$B$5000,2,0) -> #N/A | AF5: 1.45
A6: 3 | B6: Q235B | C6: 01 | D6: 1.45 | E6: 12 | F6: Q235B-1 | G6: A 碳素钢-碳素结构钢-A01 Q235B | H6: 1519 | I6: 0.16 | J6: 0.08 | K6: 0.23 | L6: 0.025 | M6: 0.02 | Q6: 0.01 | AB6: {=IF(R6="",IF(Q6="",0,(_xlfn.IFS(Q6=0.01,0.67,Q6=0.015,1,Q6=0.015,1.33,Q6=0.02,1.67,Q6=0.025,2,Q6=0.03,2.33,Q6=0.035,2.67,Q6=0.04,3)+IF(J6<=0.03,"0.33",0))),(_xlfn.IFS(R6=0.01,0.67,R6=0.015,1,R6=0.015,1.33,R6=0.02,1.67,R6=0.025,2,R6=0.03,2.33,R6=0.035,2.67,R6=0.04,3)+IF(J6<=0.03,"0.33",0)))} -> 0.67 | AC6: =IF(R6="",IF(Q6="",0.3,Q6/100/0.99/0.15*1000+IF(J6<=0.03,"0.33",0)),R6/100/0.99/0.15*1000+IF(J6<=0.03,"0.33",0)) -> 0.67340067 | AD6: =VLOOKUP(F6,铝耗2026年!$A$2:$B$5000,2,0) -> 1.2022258 | AE6: =VLOOKUP(F6,铝耗2025年!$A$2:$B$5000,2,0) -> 1.2 | AF6: =MAX(AD6:AE6) -> 1.2022258
A7: 4 | B7: Q235B | C7: 02 | D7: 12.01 | E7: 28 | F7: Q235B-2 | G7: A 碳素钢-碳素结构钢-A01 Q235B | H7: 1519 | I7: 0.16 | J7: 0.08 | K7: 0.38 | L7: 0.025 | M7: 0.02 | Q7: 0.01 | AB7: {=IF(R7="",IF(Q7="",0,(_xlfn.IFS(Q7=0.01,0.67,Q7=0.015,1,Q7=0.015,1.33,Q7=0.02,1.67,Q7=0.025,2,Q7=0.03,2.33,Q7=0.035,2.67,Q7=0.04,3)+IF(J7<=0.03,"0.33",0))),(_xlfn.IFS(R7=0.01,0.67,R7=0.015,1,R7=0.015,1.33,R7=0.02,1.67,R7=0.025,2,R7=0.03,2.33,R7=0.035,2.67,R7=0.04,3)+IF(J7<=0.03,"0.33",0)))} -> 0.67 | AC7: =IF(R7="",IF(Q7="",0.3,Q7/100/0.99/0.15*1000+IF(J7<=0.03,"0.33",0)),R7/100/0.99/0.15*1000+IF(J7<=0.03,"0.33",0)) -> 0.67340067 | AD7: =VLOOKUP(F7,铝耗2026年!$A$2:$B$5000,2,0) -> 1.1762267 | AE7: =VLOOKUP(F7,铝耗2025年!$A$2:$B$5000,2,0) -> 1.2 | AF7: =MAX(AD7:AE7) -> 1.2
A8: 5 | B8: Q235C | C8: 01 | D8: 1.6 | E8: 12 | F8: Q235C-1 | G8: A 碳素钢-碳素结构钢-A02 Q235C | H8: 1519 | I8: 0.15 | J8: 0.1 | K8: 0.35 | L8: 0.015 | M8: 0.01 | Q8: 0.025 | AB8: {=IF(R8="",IF(Q8="",0,(_xlfn.IFS(Q8=0.01,0.67,Q8=0.015,1,Q8=0.015,1.33,Q8=0.02,1.67,Q8=0.025,2,Q8=0.03,2.33,Q8=0.035,2.67,Q8=0.04,3)+IF(J8<=0.03,"0.33",0))),(_xlfn.IFS(R8=0.01,0.67,R8=0.015,1,R8=0.015,1.33,R8=0.02,1.67,R8=0.025,2,R8=0.03,2.33,R8=0.035,2.67,R8=0.04,3)+IF(J8<=0.03,"0.33",0)))} -> 2 | AC8: =IF(R8="",IF(Q8="",0.3,Q8/100/0.99/0.15*1000+IF(J8<=0.03,"0.33",0)),R8/100/0.99/0.15*1000+IF(J8<=0.03,"0.33",0)) -> 1.6835017 | AD8: =VLOOKUP(F8,铝耗2026年!$A$2:$B$5000,2,0) -> 1.318726 | AE8: =VLOOKUP(F8,铝耗2025年!$A$2:$B$5000,2,0) -> 1.33 | AF8: =MAX(AD8:AE8) -> 1.33
A9: 6 | B9: Q235C | C9: 02 | D9: 12.01 | E9: 25.4 | F9: Q235C-2 | G9: A 碳素钢-碳素结构钢-A02 Q235C | H9: 1519 | I9: 0.15 | J9: 0.1 | K9: 0.5 | L9: 0.015 | M9: 0.01 | Q9: 0.025 | AB9: {=IF(R9="",IF(Q9="",0,(_xlfn.IFS(Q9=0.01,0.67,Q9=0.015,1,Q9=0.015,1.33,Q9=0.02,1.67,Q9=0.025,2,Q9=0.03,2.33,Q9=0.035,2.67,Q9=0.04,3)+IF(J9<=0.03,"0.33",0))),(_xlfn.IFS(R9=0.01,0.67,R9=0.015,1,R9=0.015,1.33,R9=0.02,1.67,R9=0.025,2,R9=0.03,2.33,R9=0.035,2.67,R9=0.04,3)+IF(J9<=0.03,"0.33",0)))} -> 2 | AC9: =IF(R9="",IF(Q9="",0.3,Q9/100/0.99/0.15*1000+IF(J9<=0.03,"0.33",0)),R9/100/0.99/0.15*1000+IF(J9<=0.03,"0.33",0)) -> 1.6835017 | AD9: =VLOOKUP(F9,铝耗2026年!$A$2:$B$5000,2,0) -> #N/A | AE9: =VLOOKUP(F9,铝耗2025年!$A$2:$B$5000,2,0) -> 1.33 | AF9: 1.33
A10: 7 | B10: Q235B-WJ | C10: 01 | D10: 1.45 | E10: 12 | F10: Q235B-1 | G10: A 碳素钢-碳素结构钢-A01 Q235B | H10: 1519 | I10: 0.16 | J10: 0.08 | K10: 0.23 | L10: 0.025 | M10: 0.02 | Q10: 0.01 | AB10: {=IF(R10="",IF(Q10="",0,(_xlfn.IFS(Q10=0.01,0.67,Q10=0.015,1,Q10=0.015,1.33,Q10=0.02,1.67,Q10=0.025,2,Q10=0.03,2.33,Q10=0.035,2.67,Q10=0.04,3)+IF(J10<=0.03,"0.33",0))),(_xlfn.IFS(R10=0.01,0.67,R10=0.015,1,R10=0.015,1.33,R10=0.02,1.67,R10=0.025,2,R10=0.03,2.33,R10=0.035,2.67,R10=0.04,3)+IF(J10<=0.03,"0.33",0)))} -> 0.67 | AC10: =IF(R10="",IF(Q10="",0.3,Q10/100/0.99/0.15*1000+IF(J10<=0.03,"0.33",0)),R10/100/0.99/0.15*1000+IF(J10<=0.03,"0.33",0)) -> 0.67340067 | AD10: =VLOOKUP(F10,铝耗2026年!$A$2:$B$5000,2,0) -> 1.2022258 | AE10: =VLOOKUP(F10,铝耗2025年!$A$2:$B$5000,2,0) -> 1.2 | AF10: =MAX(AD10:AE10) -> 1.2022258
A11: 8 | B11: Q235B-WJ | C11: 02 | D11: 12.01 | E11: 28 | F11: Q235B-2 | G11: A 碳素钢-碳素结构钢-A01 Q235B | H11: 1519 | I11: 0.16 | J11: 0.08 | K11: 0.38 | L11: 0.025 | M11: 0.02 | Q11: 0.01 | AB11: {=IF(R11="",IF(Q11="",0,(_xlfn.IFS(Q11=0.01,0.67,Q11=0.015,1,Q11=0.015,1.33,Q11=0.02,1.67,Q11=0.025,2,Q11=0.03,2.33,Q11=0.035,2.67,Q11=0.04,3)+IF(J11<=0.03,"0.33",0))),(_xlfn.IFS(R11=0.01,0.67,R11=0.015,1,R11=0.015,1.33,R11=0.02,1.67,R11=0.025,2,R11=0.03,2.33,R11=0.035,2.67,R11=0.04,3)+IF(J11<=0.03,"0.33",0)))} -> 0.67 | AC11: =IF(R11="",IF(Q11="",0.3,Q11/100/0.99/0.15*1000+IF(J11<=0.03,"0.33",0)),R11/100/0.99/0.15*1000+IF(J11<=0.03,"0.33",0)) -> 0.67340067 | AD11: =VLOOKUP(F11,铝耗2026年!$A$2:$B$5000,2,0) -> 1.1762267 | AE11: =VLOOKUP(F11,铝耗2025年!$A$2:$B$5000,2,0) -> 1.2 | AF11: =MAX(AD11:AE11) -> 1.2
A12: 9 | B12: Q235B-LX | C12: 01 | D12: 1.45 | E12: 12 | F12: Q235B-1 | G12: A 碳素钢-碳素结构钢-A01 Q235B | H12: 1519 | I12: 0.16 | J12: 0.08 | K12: 0.23 | L12: 0.025 | M12: 0.02 | Q12: 0.01 | AB12: {=IF(R12="",IF(Q12="",0,(_xlfn.IFS(Q12=0.01,0.67,Q12=0.015,1,Q12=0.015,1.33,Q12=0.02,1.67,Q12=0.025,2,Q12=0.03,2.33,Q12=0.035,2.67,Q12=0.04,3)+IF(J12<=0.03,"0.33",0))),(_xlfn.IFS(R12=0.01,0.67,R12=0.015,1,R12=0.015,1.33,R12=0.02,1.67,R12=0.025,2,R12=0.03,2.33,R12=0.035,2.67,R12=0.04,3)+IF(J12<=0.03,"0.33",0)))} -> 0.67 | AC12: =IF(R12="",IF(Q12="",0.3,Q12/100/0.99/0.15*1000+IF(J12<=0.03,"0.33",0)),R12/100/0.99/0.15*1000+IF(J12<=0.03,"0.33",0)) -> 0.67340067 | AD12: =VLOOKUP(F12,铝耗2026年!$A$2:$B$5000,2,0) -> 1.2022258 | AE12: =VLOOKUP(F12,铝耗2025年!$A$2:$B$5000,2,0) -> 1.2 | AF12: =MAX(AD12:AE12) -> 1.2022258
A13: 10 | B13: Q235B-LX | C13: 02 | D13: 12.01 | E13: 28 | F13: Q235B-2 | G13: A 碳素钢-碳素结构钢-A01 Q235B | H13: 1519 | I13: 0.16 | J13: 0.08 | K13: 0.38 | L13: 0.025 | M13: 0.02 | Q13: 0.01 | AB13: {=IF(R13="",IF(Q13="",0,(_xlfn.IFS(Q13=0.01,0.67,Q13=0.015,1,Q13=0.015,1.33,Q13=0.02,1.67,Q13=0.025,2,Q13=0.03,2.33,Q13=0.035,2.67,Q13=0.04,3)+IF(J13<=0.03,"0.33",0))),(_xlfn.IFS(R13=0.01,0.67,R13=0.015,1,R13=0.015,1.33,R13=0.02,1.67,R13=0.025,2,R13=0.03,2.33,R13=0.035,2.67,R13=0.04,3)+IF(J13<=0.03,"0.33",0)))} -> 0.67 | AC13: =IF(R13="",IF(Q13="",0.3,Q13/100/0.99/0.15*1000+IF(J13<=0.03,"0.33",0)),R13/100/0.99/0.15*1000+IF(J13<=0.03,"0.33",0)) -> 0.67340067 | AD13: =VLOOKUP(F13,铝耗2026年!$A$2:$B$5000,2,0) -> 1.1762267 | AE13: =VLOOKUP(F13,铝耗2025年!$A$2:$B$5000,2,0) -> 1.2 | AF13: =MAX(AD13:AE13) -> 1.2
A14: 11 | B14: Q235B-HX | C14: 01 | D14: 1.45 | E14: 12 | F14: Q235B-1 | G14: A 碳素钢-碳素结构钢-A01 Q235B | H14: 1519 | I14: 0.16 | J14: 0.08 | K14: 0.23 | L14: 0.025 | M14: 0.02 | Q14: 0.01 | AB14: {=IF(R14="",IF(Q14="",0,(_xlfn.IFS(Q14=0.01,0.67,Q14=0.015,1,Q14=0.015,1.33,Q14=0.02,1.67,Q14=0.025,2,Q14=0.03,2.33,Q14=0.035,2.67,Q14=0.04,3)+IF(J14<=0.03,"0.33",0))),(_xlfn.IFS(R14=0.01,0.67,R14=0.015,1,R14=0.015,1.33,R14=0.02,1.67,R14=0.025,2,R14=0.03,2.33,R14=0.035,2.67,R14=0.04,3)+IF(J14<=0.03,"0.33",0)))} -> 0.67 | AC14: =IF(R14="",IF(Q14="",0.3,Q14/100/0.99/0.15*1000+IF(J14<=0.03,"0.33",0)),R14/100/0.99/0.15*1000+IF(J14<=0.03,"0.33",0)) -> 0.67340067 | AD14: =VLOOKUP(F14,铝耗2026年!$A$2:$B$5000,2,0) -> 1.2022258 | AE14: =VLOOKUP(F14,铝耗2025年!$A$2:$B$5000,2,0) -> 1.2 | AF14: =MAX(AD14:AE14) -> 1.2022258
A15: 12 | B15: Q235B-HX | C15: 02 | D15: 12.01 | E15: 28 | F15: Q235B-2 | G15: A 碳素钢-碳素结构钢-A01 Q235B | H15: 1519 | I15: 0.16 | J15: 0.08 | K15: 0.38 | L15: 0.025 | M15: 0.02 | Q15: 0.01 | AB15: {=IF(R15="",IF(Q15="",0,(_xlfn.IFS(Q15=0.01,0.67,Q15=0.015,1,Q15=0.015,1.33,Q15=0.02,1.67,Q15=0.025,2,Q15=0.03,2.33,Q15=0.035,2.67,Q15=0.04,3)+IF(J15<=0.03,"0.33",0))),(_xlfn.IFS(R15=0.01,0.67,R15=0.015,1,R15=0.015,1.33,R15=0.02,1.67,R15=0.025,2,R15=0.03,2.33,R15=0.035,2.67,R15=0.04,3)+IF(J15<=0.03,"0.33",0)))} -> 0.67 | AC15: =IF(R15="",IF(Q15="",0.3,Q15/100/0.99/0.15*1000+IF(J15<=0.03,"0.33",0)),R15/100/0.99/0.15*1000+IF(J15<=0.03,"0.33",0)) -> 0.67340067 | AD15: =VLOOKUP(F15,铝耗2026年!$A$2:$B$5000,2,0) -> 1.1762267 | AE15: =VLOOKUP(F15,铝耗2025年!$A$2:$B$5000,2,0) -> 1.2 | AF15: =MAX(AD15:AE15) -> 1.2
A16: 13 | B16: Q235B-GL | C16: 01 | D16: 1.6 | E16: 5 | F16: Q235B-GL1 | G16: A 碳素钢-碳素结构钢-A06 Q235B-GL | H16: 1520 | I16: 0.15 | J16: 0.12 | K16: 0.25 | L16: 0.015 | M16: 0.005 | Q16: 0.015 | AB16: {=IF(R16="",IF(Q16="",0,(_xlfn.IFS(Q16=0.01,0.67,Q16=0.015,1,Q16=0.015,1.33,Q16=0.02,1.67,Q16=0.025,2,Q16=0.03,2.33,Q16=0.035,2.67,Q16=0.04,3)+IF(J16<=0.03,"0.33",0))),(_xlfn.IFS(R16=0.01,0.67,R16=0.015,1,R16=0.015,1.33,R16=0.02,1.67,R16=0.025,2,R16=0.03,2.33,R16=0.035,2.67,R16=0.04,3)+IF(J16<=0.03,"0.33",0)))} -> 1 | AC16: =IF(R16="",IF(Q16="",0.3,Q16/100/0.99/0.15*1000+IF(J16<=0.03,"0.33",0)),R16/100/0.99/0.15*1000+IF(J16<=0.03,"0.33",0)) -> 1.010101 | AD16: =VLOOKUP(F16,铝耗2026年!$A$2:$B$5000,2,0) -> #N/A | AE16: =VLOOKUP(F16,铝耗2025年!$A$2:$B$5000,2,0) -> #N/A | AF16: 1.3
A17: 14 | B17: Q235B-GL | C17: 02 | D17: 5.01 | E17: 14 | F17: Q235B-GL2 | G17: A 碳素钢-碳素结构钢-A06 Q235B-GL | H17: 1520 | I17: 0.15 | J17: 0.12 | K17: 0.35 | L17: 0.015 | M17: 0.005 | Q17: 0.015 | AB17: {=IF(R17="",IF(Q17="",0,(_xlfn.IFS(Q17=0.01,0.67,Q17=0.015,1,Q17=0.015,1.33,Q17=0.02,1.67,Q17=0.025,2,Q17=0.03,2.33,Q17=0.035,2.67,Q17=0.04,3)+IF(J17<=0.03,"0.33",0))),(_xlfn.IFS(R17=0.01,0.67,R17=0.015,1,R17=0.015,1.33,R17=0.02,1.67,R17=0.025,2,R17=0.03,2.33,R17=0.035,2.67,R17=0.04,3)+IF(J17<=0.03,"0.33",0)))} -> 1 | AC17: =IF(R17="",IF(Q17="",0.3,Q17/100/0.99/0.15*1000+IF(J17<=0.03,"0.33",0)),R17/100/0.99/0.15*1000+IF(J17<=0.03,"0.33",0)) -> 1.010101 | AD17: =VLOOKUP(F17,铝耗2026年!$A$2:$B$5000,2,0) -> #N/A | AE17: =VLOOKUP(F17,铝耗2025年!$A$2:$B$5000,2,0) -> #N/A | AF17: 1.3
A18: 15 | B18: Q235B-GC | C18: 01 | D18: 3 | E18: 12 | F18: Q235B-GC1 | G18: A 碳素钢-碳素结构钢-A33 Q235B-GC | H18: 1519 | I18: 0.15 | J18: 0.05 | K18: 0.25 | L18: 0.018 | M18: 0.008 | Q18: 0.01 | AB18: {=IF(R18="",IF(Q18="",0,(_xlfn.IFS(Q18=0.01,0.67,Q18=0.015,1,Q18=0.015,1.33,Q18=0.02,1.67,Q18=0.025,2,Q18=0.03,2.33,Q18=0.035,2.67,Q18=0.04,3)+IF(J18<=0.03,"0.33",0))),(_xlfn.IFS(R18=0.01,0.67,R18=0.015,1,R18=0.015,1.33,R18=0.02,1.67,R18=0.025,2,R18=0.03,2.33,R18=0.035,2.67,R18=0.04,3)+IF(J18<=0.03,"0.33",0)))} -> 0.67 | AC18: =IF(R18="",IF(Q18="",0.3,Q18/100/0.99/0.15*1000+IF(J18<=0.03,"0.33",0)),R18/100/0.99/0.15*1000+IF(J18<=0.03,"0.33",0)) -> 0.67340067 | AD18: =VLOOKUP(F18,铝耗2026年!$A$2:$B$5000,2,0) -> 1.304391 | AE18: =VLOOKUP(F18,铝耗2025年!$A$2:$B$5000,2,0) -> 1.3 | AF18: =MAX(AD18:AE18) -> 1.304391
A19: 16 | B19: Q235B-GC | C19: 02 | D19: 12.01 | E19: 25.4 | F19: Q235B-GC2 | G19: A 碳素钢-碳素结构钢-A33 Q235B-GC | H19: 1519 | I19: 0.15 | J19: 0.05 | K19: 0.38 | L19: 0.018 | M19: 0.008 | Q19: 0.01 | AB19: {=IF(R19="",IF(Q19="",0,(_xlfn.IFS(Q19=0.01,0.67,Q19=0.015,1,Q19=0.015,1.33,Q19=0.02,1.67,Q19=0.025,2,Q19=0.03,2.33,Q19=0.035,2.67,Q19=0.04,3)+IF(J19<=0.03,"0.33",0))),(_xlfn.IFS(R19=0.01,0.67,R19=0.015,1,R19=0.015,1.33,R19=0.02,1.67,R19=0.025,2,R19=0.03,2.33,R19=0.035,2.67,R19=0.04,3)+IF(J19<=0.03,"0.33",0)))} -> 0.67 | AC19: =IF(R19="",IF(Q19="",0.3,Q19/100/0.99/0.15*1000+IF(J19<=0.03,"0.33",0)),R19/100/0.99/0.15*1000+IF(J19<=0.03,"0.33",0)) -> 0.67340067 | AD19: =VLOOKUP(F19,铝耗2026年!$A$2:$B$5000,2,0) -> 1.2566435 | AE19: =VLOOKUP(F19,铝耗2025年!$A$2:$B$5000,2,0) -> #N/A | AF19: 1.3
A20: 17 | B20: Q235B-SD | C20: 01 | D20: 3 | E20: 12 | F20: Q235B-SD1 | G20: A 碳素钢-碳素结构钢-A22 Q235B-SD | H20: 1519 | I20: 0.15 | J20: 0.05 | K20: 0.25 | L20: 0.018 | M20: 0.008 | Q20: 0.01 | AB20: {=IF(R20="",IF(Q20="",0,(_xlfn.IFS(Q20=0.01,0.67,Q20=0.015,1,Q20=0.015,1.33,Q20=0.02,1.67,Q20=0.025,2,Q20=0.03,2.33,Q20=0.035,2.67,Q20=0.04,3)+IF(J20<=0.03,"0.33",0))),(_xlfn.IFS(R20=0.01,0.67,R20=0.015,1,R20=0.015,1.33,R20=0.02,1.67,R20=0.025,2,R20=0.03,2.33,R20=0.035,2.67,R20=0.04,3)+IF(J20<=0.03,"0.33",0)))} -> 0.67 | AC20: =IF(R20="",IF(Q20="",0.3,Q20/100/0.99/0.15*1000+IF(J20<=0.03,"0.33",0)),R20/100/0.99/0.15*1000+IF(J20<=0.03,"0.33",0)) -> 0.67340067 | AD20: =VLOOKUP(F20,铝耗2026年!$A$2:$B$5000,2,0) -> 1.2553618 | AE20: =VLOOKUP(F20,铝耗2025年!$A$2:$B$5000,2,0) -> 1.3 | AF20: =MAX(AD20:AE20) -> 1.3
A21: 18 | B21: Q235B-SD | C21: 02 | D21: 12.01 | E21: 25.4 | F21: Q235B-SD2 | G21: A 碳素钢-碳素结构钢-A22 Q235B-SD | H21: 1519 | I21: 0.15 | J21: 0.05 | K21: 0.38 | L21: 0.018 | M21: 0.008 | Q21: 0.01 | AB21: {=IF(R21="",IF(Q21="",0,(_xlfn.IFS(Q21=0.01,0.67,Q21=0.015,1,Q21=0.015,1.33,Q21=0.02,1.67,Q21=0.025,2,Q21=0.03,2.33,Q21=0.035,2.67,Q21=0.04,3)+IF(J21<=0.03,"0.33",0))),(_xlfn.IFS(R21=0.01,0.67,R21=0.015,1,R21=0.015,1.33,R21=0.02,1.67,R21=0.025,2,R21=0.03,2.33,R21=0.035,2.67,R21=0.04,3)+IF(J21<=0.03,"0.33",0)))} -> 0.67 | AC21: =IF(R21="",IF(Q21="",0.3,Q21/100/0.99/0.15*1000+IF(J21<=0.03,"0.33",0)),R21/100/0.99/0.15*1000+IF(J21<=0.03,"0.33",0)) -> 0.67340067 | AD21: =VLOOKUP(F21,铝耗2026年!$A$2:$B$5000,2,0) -> 1.2798339 | AE21: =VLOOKUP(F21,铝耗2025年!$A$2:$B$5000,2,0) -> 1.3 | AF21: =MAX(AD21:AE21) -> 1.3
A22: 19 | B22: Q235B-HG | C22: 01 | D22: 1.5 | E22: 28 | F22: Q235B-HG | G22: A 碳素钢-碳素结构钢-A05 Q235B-HG | H22: 1519 | I22: 0.16 | J22: 0.1 | K22: 0.4 | L22: 0.025 | M22: 0.02 | Q22: 0.01 | AB22: {=IF(R22="",IF(Q22="",0,(_xlfn.IFS(Q22=0.01,0.67,Q22=0.015,1,Q22=0.015,1.33,Q22=0.02,1.67,Q22=0.025,2,Q22=0.03,2.33,Q22=0.035,2.67,Q22=0.04,3)+IF(J22<=0.03,"0.33",0))),(_xlfn.IFS(R22=0.01,0.67,R22=0.015,1,R22=0.015,1.33,R22=0.02,1.67,R22=0.025,2,R22=0.03,2.33,R22=0.035,2.67,R22=0.04,3)+IF(J22<=0.03,"0.33",0)))} -> 0.67 | AC22: =IF(R22="",IF(Q22="",0.3,Q22/100/0.99/0.15*1000+IF(J22<=0.03,"0.33",0)),R22/100/0.99/0.15*1000+IF(J22<=0.03,"0.33",0)) -> 0.67340067 | AD22: =VLOOKUP(F22,铝耗2026年!$A$2:$B$5000,2,0) -> 1.154719 | AE22: =VLOOKUP(F22,铝耗2025年!$A$2:$B$5000,2,0) -> 1.25 | AF22: =MAX(AD22:AE22) -> 1.25
A23: 20 | B23: A36 | C23: 01 | D23: 1.5 | E23: 12 | F23: A36-1 | G23: A 碳素钢-碳素结构钢-A09 A36 | H23: 1519 | I23: 0.16 | J23: 0.08 | K23: 0.25 | L23: 0.015 | M23: 0.01 | Q23: 0.02 | AB23: {=IF(R23="",IF(Q23="",0,(_xlfn.IFS(Q23=0.01,0.67,Q23=0.015,1,Q23=0.015,1.33,Q23=0.02,1.67,Q23=0.025,2,Q23=0.03,2.33,Q23=0.035,2.67,Q23=0.04,3)+IF(J23<=0.03,"0.33",0))),(_xlfn.IFS(R23=0.01,0.67,R23=0.015,1,R23=0.015,1.33,R23=0.02,1.67,R23=0.025,2,R23=0.03,2.33,R23=0.035,2.67,R23=0.04,3)+IF(J23<=0.03,"0.33",0)))} -> 1.67 | AC23: =IF(R23="",IF(Q23="",0.3,Q23/100/0.99/0.15*1000+IF(J23<=0.03,"0.33",0)),R23/100/0.99/0.15*1000+IF(J23<=0.03,"0.33",0)) -> 1.3468013 | AD23: =VLOOKUP(F23,铝耗2026年!$A$2:$B$5000,2,0) -> 1.4320019 | AE23: =VLOOKUP(F23,铝耗2025年!$A$2:$B$5000,2,0) -> 1.45 | AF23: =MAX(AD23:AE23) -> 1.45
A24: 21 | B24: A36 | C24: 02 | D24: 12.01 | E24: 25 | F24: A36-2 | G24: A 碳素钢-碳素结构钢-A09 A36 | H24: 1519 | I24: 0.16 | J24: 0.08 | K24: 0.38 | L24: 0.015 | M24: 0.01 | Q24: 0.02 | AB24: {=IF(R24="",IF(Q24="",0,(_xlfn.IFS(Q24=0.01,0.67,Q24=0.015,1,Q24=0.015,1.33,Q24=0.02,1.67,Q24=0.025,2,Q24=0.03,2.33,Q24=0.035,2.67,Q24=0.04,3)+IF(J24<=0.03,"0.33",0))),(_xlfn.IFS(R24=0.01,0.67,R24=0.015,1,R24=0.015,1.33,R24=0.02,1.67,R24=0.025,2,R24=0.03,2.33,R24=0.035,2.67,R24=0.04,3)+IF(J24<=0.03,"0.33",0)))} -> 1.67 | AC24: =IF(R24="",IF(Q24="",0.3,Q24/100/0.99/0.15*1000+IF(J24<=0.03,"0.33",0)),R24/100/0.99/0.15*1000+IF(J24<=0.03,"0.33",0)) -> 1.3468013 | AD24: =VLOOKUP(F24,铝耗2026年!$A$2:$B$5000,2,0) -> 1.4091815 | AE24: =VLOOKUP(F24,铝耗2025年!$A$2:$B$5000,2,0) -> 1.45 | AF24: =MAX(AD24:AE24) -> 1.45
A25: 22 | B25: A36-DX | C25: 01 | D25: 1.5 | E25: 12 | F25: A36-DX1 | G25: A 碳素钢-碳素结构钢-A36 A36-DX | H25: 1519 | I25: 0.16 | J25: 0 | K25: 0.3 | L25: 0.02 | M25: 0.015 | Q25: 0.02 | AB25: {=IF(R25="",IF(Q25="",0,(_xlfn.IFS(Q25=0.01,0.67,Q25=0.015,1,Q25=0.015,1.33,Q25=0.02,1.67,Q25=0.025,2,Q25=0.03,2.33,Q25=0.035,2.67,Q25=0.04,3)+IF(J25<=0.03,"0.33",0))),(_xlfn.IFS(R25=0.01,0.67,R25=0.015,1,R25=0.015,1.33,R25=0.02,1.67,R25=0.025,2,R25=0.03,2.33,R25=0.035,2.67,R25=0.04,3)+IF(J25<=0.03,"0.33",0)))} -> 2 | AC25: =IF(R25="",IF(Q25="",0.3,Q25/100/0.99/0.15*1000+IF(J25<=0.03,"0.33",0)),R25/100/0.99/0.15*1000+IF(J25<=0.03,"0.33",0)) -> 1.6768013 | AD25: =VLOOKUP(F25,铝耗2026年!$A$2:$B$5000,2,0) -> 1.5404523 | AE25: =VLOOKUP(F25,铝耗2025年!$A$2:$B$5000,2,0) -> 1.6 | AF25: =MAX(AD25:AE25) -> 1.6
A26: 23 | B26: A36-DX | C26: 02 | D26: 12.01 | E26: 20 | F26: A36-DX2 | G26: A 碳素钢-碳素结构钢-A36 A36-DX | H26: 1519 | I26: 0.16 | J26: 0 | K26: 0.4 | L26: 0.02 | M26: 0.015 | Q26: 0.02 | AB26: {=IF(R26="",IF(Q26="",0,(_xlfn.IFS(Q26=0.01,0.67,Q26=0.015,1,Q26=0.015,1.33,Q26=0.02,1.67,Q26=0.025,2,Q26=0.03,2.33,Q26=0.035,2.67,Q26=0.04,3)+IF(J26<=0.03,"0.33",0))),(_xlfn.IFS(R26=0.01,0.67,R26=0.015,1,R26=0.015,1.33,R26=0.02,1.67,R26=0.025,2,R26=0.03,2.33,R26=0.035,2.67,R26=0.04,3)+IF(J26<=0.03,"0.33",0)))} -> 2 | AC26: =IF(R26="",IF(Q26="",0.3,Q26/100/0.99/0.15*1000+IF(J26<=0.03,"0.33",0)),R26/100/0.99/0.15*1000+IF(J26<=0.03,"0.33",0)) -> 1.6768013 | AD26: =VLOOKUP(F26,铝耗2026年!$A$2:$B$5000,2,0) -> #N/A | AE26: =VLOOKUP(F26,铝耗2025年!$A$2:$B$5000,2,0) -> 1.6 | AF26: =AE26 -> 1.6
A27: 24 | B27: SS400 | C27: 01 | D27: 1.6 | E27: 12 | F27: SS400-1 | G27: A 碳素钢-碳素结构钢-A18 SS400 | H27: 1519 | I27: 0.16 | J27: 0.08 | K27: 0.35 | L27: 0.02 | M27: 0.015 | Q27: 0.01 | AB27: {=IF(R27="",IF(Q27="",0,(_xlfn.IFS(Q27=0.01,0.67,Q27=0.015,1,Q27=0.015,1.33,Q27=0.02,1.67,Q27=0.025,2,Q27=0.03,2.33,Q27=0.035,2.67,Q27=0.04,3)+IF(J27<=0.03,"0.33",0))),(_xlfn.IFS(R27=0.01,0.67,R27=0.015,1,R27=0.015,1.33,R27=0.02,1.67,R27=0.025,2,R27=0.03,2.33,R27=0.035,2.67,R27=0.04,3)+IF(J27<=0.03,"0.33",0)))} -> 0.67 | AC27: =IF(R27="",IF(Q27="",0.3,Q27/100/0.99/0.15*1000+IF(J27<=0.03,"0.33",0)),R27/100/0.99/0.15*1000+IF(J27<=0.03,"0.33",0)) -> 0.67340067 | AD27: =VLOOKUP(F27,铝耗2026年!$A$2:$B$5000,2,0) -> 1.2356426 | AE27: =VLOOKUP(F27,铝耗2025年!$A$2:$B$5000,2,0) -> 1.2 | AF27: =MAX(AD27:AE27) -> 1.2356426
A28: 25 | B28: SS400 | C28: 02 | D28: 12.01 | E28: 25.4 | F28: SS400-2 | G28: A 碳素钢-碳素结构钢-A18 SS400 | H28: 1519 | I28: 0.16 | J28: 0.08 | K28: 0.5 | L28: 0.02 | M28: 0.015 | Q28: 0.025 | AB28: {=IF(R28="",IF(Q28="",0,(_xlfn.IFS(Q28=0.01,0.67,Q28=0.015,1,Q28=0.015,1.33,Q28=0.02,1.67,Q28=0.025,2,Q28=0.03,2.33,Q28=0.035,2.67,Q28=0.04,3)+IF(J28<=0.03,"0.33",0))),(_xlfn.IFS(R28=0.01,0.67,R28=0.015,1,R28=0.015,1.33,R28=0.02,1.67,R28=0.025,2,R28=0.03,2.33,R28=0.035,2.67,R28=0.04,3)+IF(J28<=0.03,"0.33",0)))} -> 2 | AC28: =IF(R28="",IF(Q28="",0.3,Q28/100/0.99/0.15*1000+IF(J28<=0.03,"0.33",0)),R28/100/0.99/0.15*1000+IF(J28<=0.03,"0.33",0)) -> 1.6835017 | AD28: =VLOOKUP(F28,铝耗2026年!$A$2:$B$5000,2,0) -> 1.3715183 | AE28: =VLOOKUP(F28,铝耗2025年!$A$2:$B$5000,2,0) -> 1.4 | AF28: =MAX(AD28:AE28) -> 1.4
A29: 26 | B29: A36-HW | C29: 01 | D29: 1.5 | E29: 12 | F29: A36-1 | G29: A 碳素钢-碳素结构钢-A09 A36 | H29: 1519 | I29: 0.16 | J29: 0.08 | K29: 0.25 | L29: 0.015 | M29: 0.01 | Q29: 0.02 | AB29: {=IF(R29="",IF(Q29="",0,(_xlfn.IFS(Q29=0.01,0.67,Q29=0.015,1,Q29=0.015,1.33,Q29=0.02,1.67,Q29=0.025,2,Q29=0.03,2.33,Q29=0.035,2.67,Q29=0.04,3)+IF(J29<=0.03,"0.33",0))),(_xlfn.IFS(R29=0.01,0.67,R29=0.015,1,R29=0.015,1.33,R29=0.02,1.67,R29=0.025,2,R29=0.03,2.33,R29=0.035,2.67,R29=0.04,3)+IF(J29<=0.03,"0.33",0)))} -> 1.67 | AC29: =IF(R29="",IF(Q29="",0.3,Q29/100/0.99/0.15*1000+IF(J29<=0.03,"0.33",0)),R29/100/0.99/0.15*1000+IF(J29<=0.03,"0.33",0)) -> 1.3468013 | AD29: =VLOOKUP(F29,铝耗2026年!$A$2:$B$5000,2,0) -> 1.4320019 | AE29: =VLOOKUP(F29,铝耗2025年!$A$2:$B$5000,2,0) -> 1.45 | AF29: =MAX(AD29:AE29) -> 1.45
A30: 27 | B30: Q235-HW | C30: 01 | D30: 1.5 | E30: 16 | F30: Q235-HW | G30: E 花纹板-花纹板类钢材-E01 Q235-HW | H30: 1519 | I30: 0.16 | J30: 0.1 | K30: 0.25 | L30: 0.035 | M30: 0.02 | AB30: {=IF(R30="",IF(Q30="",0,(_xlfn.IFS(Q30=0.01,0.67,Q30=0.015,1,Q30=0.015,1.33,Q30=0.02,1.67,Q30=0.025,2,Q30=0.03,2.33,Q30=0.035,2.67,Q30=0.04,3)+IF(J30<=0.03,"0.33",0))),(_xlfn.IFS(R30=0.01,0.67,R30=0.015,1,R30=0.015,1.33,R30=0.02,1.67,R30=0.025,2,R30=0.03,2.33,R30=0.035,2.67,R30=0.04,3)+IF(J30<=0.03,"0.33",0)))} -> 0 | AC30: =IF(R30="",IF(Q30="",0.3,Q30/100/0.99/0.15*1000+IF(J30<=0.03,"0.33",0)),R30/100/0.99/0.15*1000+IF(J30<=0.03,"0.33",0)) -> 0.3 | AD30: =VLOOKUP(F30,铝耗2026年!$A$2:$B$5000,2,0) -> 0.22554574 | AE30: =VLOOKUP(F30,铝耗2025年!$A$2:$B$5000,2,0) -> 0.25 | AF30: =MAX(AD30:AE30) -> 0.25
A31: 28 | B31: Q355-HW | C31: 01 | D31: 3 | E31: 6 | F31: Q355-HW1 | G31: E 花纹板-花纹板类钢材-E04 Q355-HW | H31: 1518 | I31: 0.16 | J31: 0.08 | K31: 0.35 | L31: 0.02 | M31: 0.01 | P31: 0.04 | Q31: 0.02 | AA31: Q355级别花纹板 | AB31: {=IF(R31="",IF(Q31="",0,(_xlfn.IFS(Q31=0.01,0.67,Q31=0.015,1,Q31=0.015,1.33,Q31=0.02,1.67,Q31=0.025,2,Q31=0.03,2.33,Q31=0.035,2.67,Q31=0.04,3)+IF(J31<=0.03,"0.33",0))),(_xlfn.IFS(R31=0.01,0.67,R31=0.015,1,R31=0.015,1.33,R31=0.02,1.67,R31=0.025,2,R31=0.03,2.33,R31=0.035,2.67,R31=0.04,3)+IF(J31<=0.03,"0.33",0)))} -> 1.67 | AC31: =IF(R31="",IF(Q31="",0.3,Q31/100/0.99/0.15*1000+IF(J31<=0.03,"0.33",0)),R31/100/0.99/0.15*1000+IF(J31<=0.03,"0.33",0)) -> 1.3468013 | AD31: =VLOOKUP(F31,铝耗2026年!$A$2:$B$5000,2,0) -> #N/A | AE31: =VLOOKUP(F31,铝耗2025年!$A$2:$B$5000,2,0) -> #N/A | AF31: 1.4
A32: 29 | B32: Q355-HW | C32: 02 | D32: 6.01 | E32: 10 | F32: Q355-HW2 | G32: E 花纹板-花纹板类钢材-E04 Q355-HW | H32: 1517 | I32: 0.16 | J32: 0.08 | K32: 0.5 | L32: 0.02 | M32: 0.01 | P32: 0.04 | Q32: 0.02 | AA32: Q355级别花纹板 | AB32: {=IF(R32="",IF(Q32="",0,(_xlfn.IFS(Q32=0.01,0.67,Q32=0.015,1,Q32=0.015,1.33,Q32=0.02,1.67,Q32=0.025,2,Q32=0.03,2.33,Q32=0.035,2.67,Q32=0.04,3)+IF(J32<=0.03,"0.33",0))),(_xlfn.IFS(R32=0.01,0.67,R32=0.015,1,R32=0.015,1.33,R32=0.02,1.67,R32=0.025,2,R32=0.03,2.33,R32=0.035,2.67,R32=0.04,3)+IF(J32<=0.03,"0.33",0)))} -> 1.67 | AC32: =IF(R32="",IF(Q32="",0.3,Q32/100/0.99/0.15*1000+IF(J32<=0.03,"0.33",0)),R32/100/0.99/0.15*1000+IF(J32<=0.03,"0.33",0)) -> 1.3468013 | AD32: =VLOOKUP(F32,铝耗2026年!$A$2:$B$5000,2,0) -> #N/A | AE32: =VLOOKUP(F32,铝耗2025年!$A$2:$B$5000,2,0) -> #N/A | AF32: 1.4
A33: 30 | B33: SPHC | C33: 01 | D33: 1.6 | E33: 8 | F33: SPHC-ZT | G33: C 热轧低碳钢-冷轧基料-C01 SPHC | H33: 1531 | I33: 0.05 | J33: 0.015 | K33: 0.23 | L33: 0.015 | M33: 0.01 | Q33: 0.025 | Z33: 40 | AB33: {=IF(R33="",IF(Q33="",0,(_xlfn.IFS(Q33=0.01,0.67,Q33=0.015,1,Q33=0.015,1.33,Q33=0.02,1.67,Q33=0.025,2,Q33=0.03,2.33,Q33=0.035,2.67,Q33=0.04,3)+IF(J33<=0.03,"0.33",0))),(_xlfn.IFS(R33=0.01,0.67,R33=0.015,1,R33=0.015,1.33,R33=0.02,1.67,R33=0.025,2,R33=0.03,2.33,R33=0.035,2.67,R33=0.04,3)+IF(J33<=0.03,"0.33",0)))} -> 2.33 | AC33: =IF(R33="",IF(Q33="",0.3,Q33/100/0.99/0.15*1000+IF(J33<=0.03,"0.33",0)),R33/100/0.99/0.15*1000+IF(J33<=0.03,"0.33",0)) -> 2.0135017 | AD33: =VLOOKUP(F33,铝耗2026年!$A$2:$B$5000,2,0) -> #N/A | AE33: =VLOOKUP(F33,铝耗2025年!$A$2:$B$5000,2,0) -> #N/A | AF33: 1.2
A34: 31 | B34: SPHC | C34: 02 | D34: 8.01 | E34: 16 | F34: SPHC-SX | G34: C 热轧低碳钢-冷轧基料-C01 SPHC | H34: 1531 | I34: 0.05 | J34: 0.015 | K34: 0.23 | L34: 0.015 | M34: 0.01 | Q34: 0.025 | Z34: 40 | AB34: {=IF(R34="",IF(Q34="",0,(_xlfn.IFS(Q34=0.01,0.67,Q34=0.015,1,Q34=0.015,1.33,Q34=0.02,1.67,Q34=0.025,2,Q34=0.03,2.33,Q34=0.035,2.67,Q34=0.04,3)+IF(J34<=0.03,"0.33",0))),(_xlfn.IFS(R34=0.01,0.67,R34=0.015,1,R34=0.015,1.33,R34=0.02,1.67,R34=0.025,2,R34=0.03,2.33,R34=0.035,2.67,R34=0.04,3)+IF(J34<=0.03,"0.33",0)))} -> 2.33 | AC34: =IF(R34="",IF(Q34="",0.3,Q34/100/0.99/0.15*1000+IF(J34<=0.03,"0.33",0)),R34/100/0.99/0.15*1000+IF(J34<=0.03,"0.33",0)) -> 2.0135017 | AD34: =VLOOKUP(F34,铝耗2026年!$A$2:$B$5000,2,0) -> #N/A | AE34: =VLOOKUP(F34,铝耗2025年!$A$2:$B$5000,2,0) -> 2.5 | AF34: 1.2
A35: 32 | B35: SPHC | C35: 01 | D35: 8.01 | E35: 16 | F35: SPHC-SX | G35: C 热轧低碳钢-冷轧基料-C01 SPHC | H35: 1531 | I35: 0.05 | J35: 0.015 | K35: 0.23 | L35: 0.015 | M35: 0.01 | Q35: 0.025 | Z35: 40 | AA35: SPHC-SX | AB35: {=IF(R35="",IF(Q35="",0,(_xlfn.IFS(Q35=0.01,0.67,Q35=0.015,1,Q35=0.015,1.33,Q35=0.02,1.67,Q35=0.025,2,Q35=0.03,2.33,Q35=0.035,2.67,Q35=0.04,3)+IF(J35<=0.03,"0.33",0))),(_xlfn.IFS(R35=0.01,0.67,R35=0.015,1,R35=0.015,1.33,R35=0.02,1.67,R35=0.025,2,R35=0.03,2.33,R35=0.035,2.67,R35=0.04,3)+IF(J35<=0.03,"0.33",0)))} -> 2.33 | AC35: =IF(R35="",IF(Q35="",0.3,Q35/100/0.99/0.15*1000+IF(J35<=0.03,"0.33",0)),R35/100/0.99/0.15*1000+IF(J35<=0.03,"0.33",0)) -> 2.0135017 | AD35: =VLOOKUP(F35,铝耗2026年!$A$2:$B$5000,2,0) -> #N/A | AE35: =VLOOKUP(F35,铝耗2025年!$A$2:$B$5000,2,0) -> 2.5 | AF35: 1.2
A36: 33 | B36: SPHC-M | C36: 01 | D36: 2.5 | E36: 5 | F36: SPHC-M | G36: C 热轧低碳钢-冷轧基料-C02 SPHC-M | H36: 1531 | I36: 0.045 | J36: 0.02 | K36: 0.25 | L36: 0.015 | M36: 0.006 | Q36: 0.025 | Z36: 45 | AB36: {=IF(R36="",IF(Q36="",0,(_xlfn.IFS(Q36=0.01,0.67,Q36=0.015,1,Q36=0.015,1.33,Q36=0.02,1.67,Q36=0.025,2,Q36=0.03,2.33,Q36=0.035,2.67,Q36=0.04,3)+IF(J36<=0.03,"0.33",0))),(_xlfn.IFS(R36=0.01,0.67,R36=0.015,1,R36=0.015,1.33,R36=0.02,1.67,R36=0.025,2,R36=0.03,2.33,R36=0.035,2.67,R36=0.04,3)+IF(J36<=0.03,"0.33",0)))} -> 2.33 | AC36: =IF(R36="",IF(Q36="",0.3,Q36/100/0.99/0.15*1000+IF(J36<=0.03,"0.33",0)),R36/100/0.99/0.15*1000+IF(J36<=0.03,"0.33",0)) -> 2.0135017 | AD36: =VLOOKUP(F36,铝耗2026年!$A$2:$B$5000,2,0) -> #N/A | AE36: =VLOOKUP(F36,铝耗2025年!$A$2:$B$5000,2,0) -> 2.5 | AF36: 1.2
A37: 34 | B37: SPHC-M(B) | C37: 01 | D37: 2.5 | E37: 6 | F37: SPHC-M(B) | G37: C 热轧低碳钢-冷轧基料-C05 SPHC-M(B) | H37: 1531 | I37: 0.045 | J37: 0.02 | K37: 0.25 | L37: 0.015 | M37: 0.006 | Q37: 0.025 | X37: 0.0014 | AA37: 含硼马口铁 | AB37: {=IF(R37="",IF(Q37="",0,(_xlfn.IFS(Q37=0.01,0.67,Q37=0.015,1,Q37=0.015,1.33,Q37=0.02,1.67,Q37=0.025,2,Q37=0.03,2.33,Q37=0.035,2.67,Q37=0.04,3)+IF(J37<=0.03,"0.33",0))),(_xlfn.IFS(R37=0.01,0.67,R37=0.015,1,R37=0.015,1.33,R37=0.02,1.67,R37=0.025,2,R37=0.03,2.33,R37=0.035,2.67,R37=0.04,3)+IF(J37<=0.03,"0.33",0)))} -> 2.33 | AC37: =IF(R37="",IF(Q37="",0.3,Q37/100/0.99/0.15*1000+IF(J37<=0.03,"0.33",0)),R37/100/0.99/0.15*1000+IF(J37<=0.03,"0.33",0)) -> 2.0135017 | AD37: =VLOOKUP(F37,铝耗2026年!$A$2:$B$5000,2,0) -> #N/A | AE37: =VLOOKUP(F37,铝耗2025年!$A$2:$B$5000,2,0) -> #N/A | AF37: 1.2
A38: 35 | B38: MRT2.5 | C38: 01 | D38: 2.5 | E38: 6 | F38: MRT2.5 | G38: C 热轧低碳钢-冷轧基料-C03 MRT2.5 | H38: 1529 | I38: 0.06 | J38: 0 | K38: 0.28 | L38: 0.015 | M38: 0.006 | Q38: 0.03 | AA38: 供日照昱岚新材料有限公司冷轧用热轧卷板 | AB38: {=IF(R38="",IF(Q38="",0,(_xlfn.IFS(Q38=0.01,0.67,Q38=0.015,1,Q38=0.015,1.33,Q38=0.02,1.67,Q38=0.025,2,Q38=0.03,2.33,Q38=0.035,2.67,Q38=0.04,3)+IF(J38<=0.03,"0.33",0))),(_xlfn.IFS(R38=0.01,0.67,R38=0.015,1,R38=0.015,1.33,R38=0.02,1.67,R38=0.025,2,R38=0.03,2.33,R38=0.035,2.67,R38=0.04,3)+IF(J38<=0.03,"0.33",0)))} -> 2.66 | AC38: =IF(R38="",IF(Q38="",0.3,Q38/100/0.99/0.15*1000+IF(J38<=0.03,"0.33",0)),R38/100/0.99/0.15*1000+IF(J38<=0.03,"0.33",0)) -> 2.350202 | AD38: =VLOOKUP(F38,铝耗2026年!$A$2:$B$5000,2,0) -> 2.8450493 | AE38: =VLOOKUP(F38,铝耗2025年!$A$2:$B$5000,2,0) -> 2.5 | AF38: 1.2
A39: 36 | B39: YFMRT2.5 | C39: 01 | D39: 2.5 | E39: 6 | F39: YFMRT2.5 | G39: C 热轧低碳钢-冷轧基料-C07 YFMRT2.5 | H39: 1529 | I39: 0.06 | J39: 0 | K39: 0.28 | L39: 0.015 | M39: 0.006 | Q39: 0.03 | AA39: 供友富用热轧卷板 | AB39: {=IF(R39="",IF(Q39="",0,(_xlfn.IFS(Q39=0.01,0.67,Q39=0.015,1,Q39=0.015,1.33,Q39=0.02,1.67,Q39=0.025,2,Q39=0.03,2.33,Q39=0.035,2.67,Q39=0.04,3)+IF(J39<=0.03,"0.33",0))),(_xlfn.IFS(R39=0.01,0.67,R39=0.015,1,R39=0.015,1.33,R39=0.02,1.67,R39=0.025,2,R39=0.03,2.33,R39=0.035,2.67,R39=0.04,3)+IF(J39<=0.03,"0.33",0)))} -> 2.66 | AC39: =IF(R39="",IF(Q39="",0.3,Q39/100/0.99/0.15*1000+IF(J39<=0.03,"0.33",0)),R39/100/0.99/0.15*1000+IF(J39<=0.03,"0.33",0)) -> 2.350202 | AD39: =VLOOKUP(F39,铝耗2026年!$A$2:$B$5000,2,0) -> #N/A | AE39: =VLOOKUP(F39,铝耗2025年!$A$2:$B$5000,2,0) -> 2.5 | AF39: 1.2
A40: 37 | B40: YLMRT3 | C40: 01 | D40: 2.5 | E40: 3.5 | F40: YLMRT3 | G40: C 热轧低碳钢-冷轧基料-C04 YLMRT3 | H40: 1528 | I40: 0.07 | J40: 0 | K40: 0.35 | L40: 0.015 | M40: 0.006 | Q40: 0.03 | AA40: 供日照昱岚新材料有限公司冷轧用热轧卷板 | AB40: {=IF(R40="",IF(Q40="",0,(_xlfn.IFS(Q40=0.01,0.67,Q40=0.015,1,Q40=0.015,1.33,Q40=0.02,1.67,Q40=0.025,2,Q40=0.03,2.33,Q40=0.035,2.67,Q40=0.04,3)+IF(J40<=0.03,"0.33",0))),(_xlfn.IFS(R40=0.01,0.67,R40=0.015,1,R40=0.015,1.33,R40=0.02,1.67,R40=0.025,2,R40=0.03,2.33,R40=0.035,2.67,R40=0.04,3)+IF(J40<=0.03,"0.33",0)))} -> 2.66 | AC40: =IF(R40="",IF(Q40="",0.3,Q40/100/0.99/0.15*1000+IF(J40<=0.03,"0.33",0)),R40/100/0.99/0.15*1000+IF(J40<=0.03,"0.33",0)) -> 2.350202 | AD40: =VLOOKUP(F40,铝耗2026年!$A$2:$B$5000,2,0) -> #N/A | AE40: =VLOOKUP(F40,铝耗2025年!$A$2:$B$5000,2,0) -> #N/A | AF40: 1.2
...

Sheet Sheet2

Sheet 铝耗2026年
A1: 钢种号 | B1: 平均值项:铝耗 | K1: 钢种号 | L1: 铝块 | M1: 铝粒 | N1: 喂铝线长度（m） | O1: 出站天车钢水净重（t） | P1: 铝耗
A2: 26MnB5 | B2: 1.8156195 | K2: 26MnB5 | L2: 301.22 | M2: 184.6571 | N2: 80.1 | O2: 279.08 | P2: 1.8156195
A3: 330CL-1 | B3: 2.8328548 | K3: 330CL-1 | L3: 300.78 | M3: 265.382 | N3: 700.22 | O3: 281.23 | P3: 2.6605241
A4: 380CL-2 | B4: 1.8379556 | K4: 330CL-1 | L4: 300.78 | M4: 311.846 | N4: 800 | O4: 273.07 | P4: 3.0051855
A5: 380CL-JD2 | B5: 2.0161054 | K5: 380CL-2 | L5: 300.35 | M5: 115.8131 | N5: 250.01 | O5: 282.83 | P5: 1.7012541
A6: 420CL-1 | B6: 2.1633805 | K6: 380CL-2 | L6: 300.78 | M6: 94.0394 | N6: 400.11 | O6: 277.08 | P6: 1.8003753
A7: 510L-1 | B7: 2.1263345 | K7: 380CL-2 | L7: 300.78 | M7: 139.757 | N7: 290.2 | O7: 278.14 | P7: 1.8551413
A8: 510L-2 | B8: 2.0576579 | K8: 380CL-2 | L8: 300.35 | M8: 148.7804 | N8: 383.11 | O8: 275.05 | P8: 1.9950518
A9: 610L-1 | B9: 1.9493023 | K9: 380CL-JD2 | L9: 300.35 | M9: 103.2986 | N9: 350.1 | O9: 270.46 | P9: 1.8290121
A10: 610L-2 | B10: 1.9640105 | K10: 380CL-JD2 | L10: 300.78 | M10: 197.8038 | N10: 340.3 | O10: 285.76 | P10: 2.0543876
A11: 700L(HJKJ) | B11: 1.6989988 | K11: 380CL-JD2 | L11: 300.35 | M11: 195.2749 | N11: 300.3 | O11: 265 | P11: 2.1649166
A12: 700L-1 | B12: 2.1674722 | K12: 420CL-1 | L12: 300.35 | M12: 149.8828 | N12: 338.11 | O12: 275.34 | P12: 1.9544614
A13: 700L-2 | B13: 2.0394424 | K13: 420CL-1 | L13: 300.35 | M13: 206.0185 | N13: 330.1 | O13: 269.6 | P13: 2.1965671
... A112: YF700BL-3 | B112: 2.236359 | K112: 700L-2 | L112: 300.35 | M112: 111.2196 | N112: 215 | O112: 278.23 | P112: 1.6801553
A113: (空白) | K113: 700L-2 | L113: 300.78 | M113: 168.4549 | N113: 150.1 | O113: 287.12 | P113: 1.7702037
A114: 总计 | B114: 1.4127211 | K114: 700L-2 | L114: 300.78 | M114: 121.2558 | N114: 270.1 | O114: 269.03 | P114: 1.8297655
K115: 700L-2 | L115: 300.35 | M115: 158.2031 | N115: 100.1 | O115: 264.4 | P115: 1.83275
K116: 700L-2 | L116: 300.78 | M116: 110.1346 | N116: 374.2 | O116: 275.94 | P116: 1.8417286
K117: 700L-2 | L117: 300.35 | M117: 125.3791 | N117: 351.8 | O117: 272.47 | P117: 1.89818
K118: 700L-2 | L118: 293.4 | M118: 179.5399 | N118: 177 | O118: 271.33 | P118: 1.9126521
K119: 700L-2 | L119: 300.78 | M119: 139.158 | N119: 290.1 | O119: 268.73 | P119: 1.9177762
K120: 700L-2 | L120: 308.59 | M120: 145.1823 | N120: 320.1 | O120: 278.77 | P120: 1.9263131
K121: 700L-2 | L121: 300.78 | M121: 190.1346 | N121: 160.2 | O121: 273.34 | P121: 1.9483669
K122: 700L-2 | L122: 300.35 | M122: 154.6224 | N122: 395.11 | O122: 284.86 | P122: 1.9578073
K123: 700L-2 | L123: 300.78 | M123: 177.6953 | N123: 350.01 | O123: 289.43 | P123: 1.9675842
K124: 700L-2 | L124: 308.59 | M124: 136.6102 | N124: 320 | O124: 267 | P124: 1.979027
K125: 700L-2 | L125: 300.35 | M125: 134.511 | N125: 495.11 | O125: 281.97 | P125: 1.9987573
K126: 700L-2 | L126: 308.59 | M126: 185.9809 | N126: 190.2 | O126: 271 | P126: 2.0074646
... K155: 700L-S1 | L155: 307.73 | M155: 217.3177 | N155: 450.11 | O155: 276.8 | P155: 2.3196398
K156: 800L-AC | L156: 307.73 | N156: 530.12 | O156: 270 | P156: 1.6502267
K157: 800L-AC | L157: 308.59 | M157: 105.2517 | N157: 350.1 | O157: 281.96 | P157: 1.790565
K158: 800L-AC | L158: 307.73 | M158: 113.9323 | N158: 140.2 | O158: 254.09 | P158: 1.8029608
K159: 800L-AC | L159: 307.73 | M159: 155.382 | N159: 200.3 | O159: 282.84 | P159: 1.8214892
K160: 800L-AC | L160: 307.73 | M160: 197.5695 | N160: 130.2 | O160: 295.55 | P160: 1.8242311
K161: 800L-AC | L161: 301.22 | M161: 114.4387 | N161: 400.11 | O161: 276.79 | P161: 1.8775509
K162: 800L-AC | L162: 307.73 | M162: 113.86 | N162: 439.2 | O162: 272.16 | P162: 1.9686287
K163: 800L-AC | L163: 293.4 | M163: 153.7876 | N163: 500.11 | O163: 270.5 | P163: 2.1338861
K164: 800L-AC | L164: 293.4 | M164: 203.559 | N164: 430.11 | O164: 274.2 | P164: 2.2202319
K165: 800L-AC | L165: 301.22 | M165: 211.1111 | N165: 480.2 | O165: 274.21 | P165: 2.3237048
K166: 800L-AC | L166: 293.4 | M166: 204.4271 | N166: 580.12 | O166: 276.52 | P166: 2.3457916
...

Sheet 铝耗2025年
A1: 炼钢 牌号 | B1: 修正后铝耗
A2: Q195-1 | B2: 1.45
A3: Q235B-1 | B3: 1.2
A4: Q235B-2 | B4: 1.2
A5: Q235C-1 | B5: 1.33
A6: Q235C-2 | B6: 1.33
A7: Q235B-GC1 | B7: 1.3
A8: Q235B-SD1 | B8: 1.3
A9: Q235B-SD2 | B9: 1.3
A10: Q235B-HG | B10: 1.25
A11: A36-1 | B11: 1.45
A12: A36-2 | B12: 1.45
A13: A36-DX1 | B13: 1.6
... A141: AH36-2 | B141: 1.9

Sheet Sheet1
A1: 炉号 | B1: 钢种 | C1: 铝粒
E2: 日期 | F2: 炉次号 | G2: 钢种号 | H2: 自产石灰块炼钢石灰窑二车间 | I2: 高铝预熔渣 | J2: 高铝钢包渣改质剂 | K2: 铝块 | L2: 铝粒
E3: 2026-04-20 | F3: L1G2Z426D00764 | G3: MRT2.5 | H3: 810.44 | K3: 360.24
E4: 2026-04-20 | F4: L1G2Z426D00765 | G4: MRT2.5 | H4: 538.27 | I4: 420 | L4: 50 | M4: L1G2Z426D00765 | N4: MRT2.5 | O4: 258.57 | P4: =O4+L4 -> 308.57
E5: 2026-04-20 | F5: L1G2Z426D00766 | G5: MRT2.5 | H5: 459.78 | I5: 370 | L5: 50 | M5: L1G2Z426D00766 | N5: MRT2.5 | O5: 178.71 | P5: =O5+L5 -> 228.71
E6: 2026-04-20 | F6: L1G2Z426D00767 | G6: MRT2.5 | H6: 533.96 | I6: 330 | L6: 50 | M6: L1G2Z426D00767 | N6: MRT2.5 | O6: 243.06 | P6: =O6+L6 -> 293.06
E7: 2026-04-20 | F7: L1G2Z426D00768 | G7: MRT2.5 | H7: 525.35 | I7: 420 | L7: 50 | M7: L1G2Z426D00768 | N7: MRT2.5 | O7: 236.66 | P7: =O7+L7 -> 286.66
E8: 2026-04-20 | F8: L1G2Z426D00769 | G8: MRT2.5 | H8: 525.35 | I8: 420 | L8: 50 | M8: L1G2Z426D00769 | N8: MRT2.5 | O8: 194.77 | P8: =O8+L8 -> 244.77
E9: 2026-04-20 | F9: L1G2Z426D00770 | G9: MRT2.5 | H9: 516.75 | I9: 420 | L9: 50 | M9: L1G2Z426D00770 | N9: MRT2.5 | O9: 381.94 | P9: =O9+L9 -> 431.94
E10: 2026-04-20 | F10: L1G2Z426D00771 | G10: MRT2.5 | H10: 534.47 | I10: 370 | L10: 50 | M10: L1G2Z426D00771 | N10: MRT2.5 | O10: 209.42 | P10: =O10+L10 -> 259.42
E11: 2026-04-30 | F11: L1G2Z426D01160 | G11: MRT2.5 | H11: 529.66 | I11: 470 | L11: 50 | M11: L1G2Z426D01160 | N11: MRT2.5 | O11: 451.39 | P11: =O11+L11 -> 501.39
E12: 2026-04-30 | F12: L1G2Z426D01161 | G12: MRT2.5 | H12: 534.72 | I12: 470 | L12: 50 | M12: L1G2Z426D01161 | N12: MRT2.5 | O12: 241.64 | P12: =O12+L12 -> 291.64
E13: 2026-04-30 | F13: L1G2Z426D01162 | G13: MRT2.5 | H13: 394.21 | I13: 430 | L13: 50 | M13: L1G2Z426D01162 | N13: MRT2.5 | O13: 220.38 | P13: =O13+L13 -> 270.38
E14: 2026-04-30 | F14: L1G2Z426D01163 | G14: MRT2.5 | H14: 538.27 | I14: 400 | L14: 50 | M14: L1G2Z426D01163 | N14: MRT2.5 | O14: 202.15 | P14: =O14+L14 -> 252.15
E15: 2026-04-30 | F15: L1G2Z426D01164 | G15: MRT2.5 | H15: 529.66 | I15: 400 | L15: 50 | M15: L1G2Z426D01164 | N15: MRT2.5 | O15: 179.8 | P15: =O15+L15 -> 229.8
E16: 2026-04-30 | F16: L1G2Z426D01165 | G16: MRT2.5 | H16: 543.08 | I16: 430 | L16: 50 | M16: L1G2Z426D01165 | N16: MRT2.5 | O16: 231.77 | P16: =O16+L16 -> 281.77
E17: 2026-05-08 | F17: L1G2Z426E00296 | G17: MRT2.5 | H17: 538.27 | J17: 500 | L17: 50 | P17: =O17+L17 -> 50
E18: 2026-05-08 | F18: L1G2Z426E00297 | G18: MRT2.5 | H18: 525.61 | J18: 500 | L18: 50 | P18: =O18+L18 -> 50
E19: 2026-05-08 | F19: L1G2Z426E00298 | G19: MRT2.5 | H19: 538.52 | J19: 480 | L19: 50 | P19: =O19+L19 -> 50
E20: 2026-05-08 | F20: L1G2Z426E00299 | G20: MRT2.5 | H20: 538.77 | J20: 470 | L20: 50 | P20: =O20+L20 -> 50
E21: 2026-05-08 | F21: L1G2Z426E00300 | G21: MRT2.5 | H21: 547.38 | J21: 470 | L21: 50 | P21: =O21+L21 -> 50
E22: 2026-05-08 | F22: L1G2Z426E00301 | G22: MRT2.5 | H22: 542.82 | J22: 470 | L22: 50 | P22: =O22+L22 -> 50
E23: 2026-05-18 | F23: L1G2Z426E00713 | G23: MRT2.5 | H23: 534.47 | J23: 500 | L23: 50 | P23: =O23+L23 -> 50
E24: 2026-05-18 | F24: L1G2Z426E00714 | G24: MRT2.5 | H24: 525.86 | J24: 430 | L24: 50 | P24: =O24+L24 -> 50
E25: 2026-05-18 | F25: L1G2Z426E00715 | G25: MRT2.5 | H25: 530.16 | J25: 470 | L25: 50 | P25: =O25+L25 -> 50
E26: 2026-05-18 | F26: L1G2Z426E00716 | G26: MRT2.5 | H26: 543.08 | J26: 470 | L26: 50 | P26: =O26+L26 -> 50
E27: 2026-05-18 | F27: L1G2Z426E00717 | G27: MRT2.5 | H27: 231.92 | J27: 430 | L27: 50 | P27: =O27+L27 -> 50
E28: 2026-05-18 | F28: L1G2Z426E00718 | G28: MRT2.5 | H28: 236.73 | J28: 430 | L28: 50 | M28: L1G2Z426E00718 | N28: MRT2.5 | O28: 170.79 | P28: =O28+L28 -> 220.79 | Q28: =P28/260 -> 0.84919231
E29: 2026-05-18 | F29: L1G2Z426E00719 | G29: MRT2.5 | H29: 241.03 | J29: 430 | L29: 50 | M29: L1G2Z426E00719 | N29: MRT2.5 | O29: 176.22 | P29: =O29+L29 -> 226.22 | Q29: =P29/260 -> 0.87007692
E30: 2026-05-18 | F30: L1G2Z426E00720 | G30: MRT2.5 | H30: 192.42 | J30: 470 | L30: 50 | M30: L1G2Z426E00720 | N30: MRT2.5 | O30: 223.96 | P30: =O30+L30 -> 273.96 | Q30: =P30/260 -> 1.0536923
E31: 2026-05-22 | F31: L1G2Z426E00862 | G31: MRT2.5 | H31: 499.02 | J31: 470 | L31: 70 | M31: L1G2Z426E00862 | N31: MRT2.5 | O31: 278.97 | P31: =O31+L31 -> 348.97 | Q31: =P31/260 -> 1.3421923
E32: 2026-05-22 | F32: L1G2Z426E00863 | G32: MRT2.5 | H32: 499.02 | J32: 470 | L32: 50 | M32: L1G2Z426E00863 | N32: MRT2.5 | O32: 231.23 | P32: =O32+L32 -> 281.23 | Q32: =P32/260 -> 1.0816538
E33: 2026-05-22 | F33: L1G2Z426E00864 | G33: MRT2.5 | H33: 481.55 | J33: 400 | L33: 50 | M33: L1G2Z426E00864 | N33: MRT2.5 | O33: 179.69 | P33: =O33+L33 -> 229.69 | Q33: =P33/260 -> 0.88342308
E34: 2026-05-22 | F34: L1G2Z426E00865 | G34: MRT2.5 | H34: 516.75 | J34: 400 | M34: L1G2Z426E00865 | N34: MRT2.5 | O34: 266.38 | P34: =O34+L34 -> 266.38 | Q34: =P34/260 -> 1.0245385
E35: 2026-05-22 | F35: L1G2Z426E00866 | G35: MRT2.5 | H35: 512.44 | J35: 470 | M35: L1G2Z426E00866 | N35: MRT2.5 | O35: 268.99 | P35: =O35+L35 -> 268.99 | Q35: =P35/260 -> 1.0345769
E36: 2026-05-22 | F36: L1G2Z426E00867 | G36: MRT2.5 | H36: 525.61 | J36: 470 | M36: L1G2Z426E00867 | N36: MRT2.5 | O36: 291.02 | P36: =O36+L36 -> 291.02 | Q36: =P36/260 -> 1.1193077
E37: 2026-05-22 | F37: L1G2Z426E00868 | G37: MRT2.5 | H37: 503.83 | J37: 470 | M37: L1G2Z426E00868 | N37: MRT2.5 | O37: 304.36 | P37: =O37+L37 -> 304.36 | Q37: =P37/260 -> 1.1706154
E38: 2026-05-22 | F38: L1G2Z426E00869 | G38: MRT2.5 | H38: 503.83 | J38: 400 | M38: L1G2Z426E00869 | N38: MRT2.5 | O38: 267.58 | P38: =O38+L38 -> 267.58 | Q38: =P38/260 -> 1.0291538
E39: 2026-05-23 | F39: L1G2Z426E00901 | G39: MRT2.5 | H39: 490.42 | J39: 470 | M39: L1G2Z426E00901 | N39: MRT2.5 | O39: 263.13 | P39: =O39+L39 -> 263.13 | Q39: =P39/260 -> 1.0120385
E40: 2026-05-23 | F40: L1G2Z426E00902 | G40: MRT2.5 | H40: 477.25 | J40: 430 | M40: L1G2Z426E00902 | N40: MRT2.5 | O40: 263.56 | P40: =O40+L40 -> 263.56 | Q40: =P40/260 -> 1.0136923
...
