Workbook
Name _1_200808: #REF!
Name _2_555: #REF!
Name _4_200808: #REF!
Name _8_555: #REF!
Name _总帐6: #REF!
Name GZ: {0,500,2000,5000,20000,40000,60000,80000,100000}
Name shangyue: {0,500,2000,5000,20000,40000,60000,80000,100000}
Name UFPrn20051001103221: #N/A
Name UFPrn20051001103243: #N/A
Name UFPrn20060404091403: '[1]#REF!'!$A$1:$C$22
Name UFPrn20060404091433: '[1]#REF!'!$A$23:$C$39
Name UFPrn20060502142416: '[1]#REF!'!$A$1:$B$31
Name UFPrn20070324165129: #REF!
Name UFPrn20070425083825: #REF!
Name UFPrn20070601163318: #REF!
Name UFPrn20070701155357: #REF!
Name UFPrn20070801153911: #REF!
Name UFPrn20070801154019: #REF!
Name UFPrn20070807161608: #REF!
Name UFPrn20070825093512: #REF!
Name UFPrn20070901164942: #REF!
Name UFPrn20070925145437: #REF!
Name UFPrn20071001143409: #REF!
Name UFPrn20071201135008: #REF!
Name UFPrn20080101132617: #REF!
Name UFPrn20080201152428: #REF!
Name UFPrn20080201152859: #REF!
Name UFPrn20080301151152: #REF!
Name UFPrn20080401143728: #REF!
Name UFPrn20080408163922: #REF!
Name UFPrn20080501151850: #REF!
Name UFPrn20080601120518: #REF!
Name UFPrn20080701144303: #REF!
Name UFPrn20080801091948: #REF!
Name UFPrn20081001113629: #REF!
Name UFPrn20081101133625: #REF!
Name UFPrn20081201112019: #REF!
Name UFPrn20090101161302: #REF!
Name UFPrn20090201154349: #REF!
Name UFPrn20090301100312: #REF!
Name UFPrn20090401161106: #REF!
Name x: {0,500,2000,5000,20000,40000,60000,80000,100000}
Name YD: 648/0.818
Name YY: 800/1.14
Name 啊: #REF!
Name 成本: #REF!
Name 成本合计: [2]制氧成本!$F$1,[2]制氧成本!$H$1:$N$1
Name 代码: OFFSET([3]引用!$A$1,0,0,COUNTA([3]引用!$A$1:$A$65536),3)
Name 电调整: OFFSET([2]水电!$A$161,,,2,COUNTA([2]水电!$A$161:$AZ$161))
Name 废: {0,500,2000,5000,20000,40000,60000,80000,100000}
Name 辅助列: #N/A
Name 高线啊: {0,500,2000,5000,20000,40000,60000,80000,100000}
Name 合计: #N/A
Name 汇总: #REF!
Name 扣除: [4]动力成本!$J$2,[4]动力成本!$T$2,[4]动力成本!$Y$2,[4]动力成本!$AA$2
Name 新: #REF!
Name 新工艺: #REF!
Name 月份: #N/A
Name 咋: {0,500,2000,5000,20000,40000,60000,80000,100000}
Name 直接费用: [4]动力成本!#REF!

Sheet 炼钢参数表
A2: 序号 | B2: 适用牌号 | C2: 厚度mm | D2: 厚度mm | E2: 厚度mm | F2: 炼钢牌号 | G2: 钢种类型 | H2: 液相线温度℃ | I2: 终点碳 | J2: 终点锰 | K2: 硅回收率 | L2: 锰回收率 | M2: 钒回收率 | N2: 铌回收率 | O2: 钛回收率 | P2: 铬回收率 | Q2: 镍回收率 | R2: 铜回收率 | S2: 钼回收率 | T2: 硼回收率 | U2: 锑回收率 | V2: 磷回收率 | W2: 硫回收率 | X2: 碳回收率
A5: 1 | B5: Q195 | C5: 01 | D5: 1.5 | E5: 12 | F5: Q195-1 | G5: A 碳素钢-碳素结构钢-A20 Q195 | H5: 1527 | I5: 0.041666667 | J5: 0.103 | K5: 0.75 | L5: 0.98 | M5: 0.98 | N5: 0.98 | O5: 0.7 | P5: 0.96 | Q5: 0.98 | R5: 0.98 | S5: 0.98 | T5: 0.7 | U5: 0.96 | V5: 0.96 | W5: 0.96 | X5: 0.9
A6: 2 | B6: Q195 | C6: 02 | D6: 12.01 | E6: 28 | F6: Q195-2 | G6: A 碳素钢-碳素结构钢-A20 Q195 | H6: 1527 | I6: 0.041666667 | J6: 0.103 | K6: 0.75 | L6: 0.98 | M6: 0.98 | N6: 0.98 | O6: 0.7 | P6: 0.96 | Q6: 0.98 | R6: 0.98 | S6: 0.98 | T6: 0.7 | U6: 0.96 | V6: 0.96 | W6: 0.96 | X6: 0.9
A7: 3 | B7: Q235B | C7: 01 | D7: 1.45 | E7: 12 | F7: Q235B-1 | G7: A 碳素钢-碳素结构钢-A01 Q235B | H7: 1519 | I7: 0.07293667 | J7: 0.12229229 | K7: 0.75 | L7: 0.98 | M7: 0.98 | N7: 0.98 | O7: 0.7 | P7: 0.96 | Q7: 0.98 | R7: 0.98 | S7: 0.98 | T7: 0.7 | U7: 0.96 | V7: 0.96 | W7: 0.96 | X7: 0.9
A8: 4 | B8: Q235B | C8: 02 | D8: 12.01 | E8: 28 | F8: Q235B-2 | G8: A 碳素钢-碳素结构钢-A01 Q235B | H8: 1519 | I8: 0.074405858 | J8: 0.12264435 | K8: 0.75 | L8: 0.98 | M8: 0.98 | N8: 0.98 | O8: 0.7 | P8: 0.96 | Q8: 0.98 | R8: 0.98 | S8: 0.98 | T8: 0.7 | U8: 0.96 | V8: 0.96 | W8: 0.96 | X8: 0.9
A9: 5 | B9: Q235C | C9: 01 | D9: 1.6 | E9: 12 | F9: Q235C-1 | G9: A 碳素钢-碳素结构钢-A02 Q235C | H9: 1519 | I9: 0.068953488 | J9: 0.11909302 | K9: 0.8 | L9: 0.98 | M9: 0.98 | N9: 0.98 | O9: 0.7 | P9: 0.96 | Q9: 0.98 | R9: 0.98 | S9: 0.98 | T9: 0.7 | U9: 0.96 | V9: 0.96 | W9: 0.96 | X9: 0.9
A10: 6 | B10: Q235C | C10: 02 | D10: 12.01 | E10: 25.4 | F10: Q235C-2 | G10: A 碳素钢-碳素结构钢-A02 Q235C | H10: 1519 | I10: 0.0625 | J10: 0.1289 | K10: 0.8 | L10: 0.98 | M10: 0.98 | N10: 0.98 | O10: 0.7 | P10: 0.96 | Q10: 0.98 | R10: 0.98 | S10: 0.98 | T10: 0.7 | U10: 0.96 | V10: 0.96 | W10: 0.96 | X10: 0.9
A11: 7 | B11: Q235B-WJ | C11: 01 | D11: 1.45 | E11: 12 | F11: Q235B-1 | G11: A 碳素钢-碳素结构钢-A01 Q235B | H11: 1519 | I11: 0.07293667 | J11: 0.12229229 | K11: 0.75 | L11: 0.98 | M11: 0.98 | N11: 0.98 | O11: 0.7 | P11: 0.96 | Q11: 0.98 | R11: 0.98 | S11: 0.98 | T11: 0.7 | U11: 0.96 | V11: 0.96 | W11: 0.96 | X11: 0.9
A12: 8 | B12: Q235B-WJ | C12: 02 | D12: 12.01 | E12: 28 | F12: Q235B-2 | G12: A 碳素钢-碳素结构钢-A01 Q235B | H12: 1519 | I12: 0.074405858 | J12: 0.12264435 | K12: 0.75 | L12: 0.98 | M12: 0.98 | N12: 0.98 | O12: 0.7 | P12: 0.96 | Q12: 0.98 | R12: 0.98 | S12: 0.98 | T12: 0.7 | U12: 0.96 | V12: 0.96 | W12: 0.96 | X12: 0.9
A13: 9 | B13: Q235B-LX | C13: 01 | D13: 1.45 | E13: 12 | F13: Q235B-1 | G13: A 碳素钢-碳素结构钢-A01 Q235B | H13: 1519 | I13: 0.07293667 | J13: 0.12229229 | K13: 0.75 | L13: 0.98 | M13: 0.98 | N13: 0.98 | O13: 0.7 | P13: 0.96 | Q13: 0.98 | R13: 0.98 | S13: 0.98 | T13: 0.7 | U13: 0.96 | V13: 0.96 | W13: 0.96 | X13: 0.9
A14: 10 | B14: Q235B-LX | C14: 02 | D14: 12.01 | E14: 28 | F14: Q235B-2 | G14: A 碳素钢-碳素结构钢-A01 Q235B | H14: 1519 | I14: 0.074405858 | J14: 0.12264435 | K14: 0.75 | L14: 0.98 | M14: 0.98 | N14: 0.98 | O14: 0.7 | P14: 0.96 | Q14: 0.98 | R14: 0.98 | S14: 0.98 | T14: 0.7 | U14: 0.96 | V14: 0.96 | W14: 0.96 | X14: 0.9
A15: 11 | B15: Q235B-HX | C15: 01 | D15: 1.45 | E15: 12 | F15: Q235B-1 | G15: A 碳素钢-碳素结构钢-A01 Q235B | H15: 1519 | I15: 0.07293667 | J15: 0.12229229 | K15: 0.75 | L15: 0.98 | M15: 0.98 | N15: 0.98 | O15: 0.7 | P15: 0.96 | Q15: 0.98 | R15: 0.98 | S15: 0.98 | T15: 0.7 | U15: 0.96 | V15: 0.96 | W15: 0.96 | X15: 0.9
A16: 12 | B16: Q235B-HX | C16: 02 | D16: 12.01 | E16: 28 | F16: Q235B-2 | G16: A 碳素钢-碳素结构钢-A01 Q235B | H16: 1519 | I16: 0.074405858 | J16: 0.12264435 | K16: 0.75 | L16: 0.98 | M16: 0.98 | N16: 0.98 | O16: 0.7 | P16: 0.96 | Q16: 0.98 | R16: 0.98 | S16: 0.98 | T16: 0.7 | U16: 0.96 | V16: 0.96 | W16: 0.96 | X16: 0.9
... A196: 192 | B196: Q235PL | C196: 02 | D196: 7.56 | E196: 18 | F196: Q235PL-2 | G196: D 汽车用钢-汽车车轮用钢-D04 Q235PL | H196: 1519 | I196: 0.076057895 | J196: 0.12388947 | K196: 0.75 | L196: 0.98 | M196: 0.98 | N196: 0.98 | O196: 0.7 | P196: 0.96 | Q196: 0.98 | R196: 0.98 | S196: 0.98 | T196: 0.7 | U196: 0.96 | V196: 0.96 | W196: 0.96 | X196: 0.9
B197: Q255PL-KP | C197: 01 | D197: 3 | E197: 7.55 | F197: Q255PL-KP1 | G197: D 汽车用钢-汽车车轮用钢-D27 Q255PL-KP | I197: 0.073317829 | J197: 0.12324031 | K197: 0.75 | L197: 0.98 | M197: 0.98 | N197: 0.98 | O197: 0.7 | P197: 0.96 | Q197: 0.98 | R197: 0.98 | S197: 0.98 | T197: 0.7 | U197: 0.96 | V197: 0.96 | W197: 0.96 | X197: 0.9
B198: Q255PL-KP | C198: 02 | D198: 7.56 | E198: 20 | F198: Q255PL-KP2 | G198: D 汽车用钢-汽车车轮用钢-D27 Q255PL-KP | I198: 0.076057895 | J198: 0.12388947 | K198: 0.75 | L198: 0.98 | M198: 0.98 | N198: 0.98 | O198: 0.7 | P198: 0.96 | Q198: 0.98 | R198: 0.98 | S198: 0.98 | T198: 0.7 | U198: 0.96 | V198: 0.96 | W198: 0.96 | X198: 0.9
A199: 193 | B199: 330CL | C199: 01 | D199: 2 | E199: 10.49 | F199: 330CL-1 | G199: D 汽车用钢-汽车车轮用钢-D08 330CL | H199: 1529 | I199: 0.054 | J199: 0.095333333 | K199: 0 | L199: 0.98 | M199: 0.98 | N199: 0.98 | O199: 0.7 | P199: 0.96 | Q199: 0.98 | R199: 0.98 | S199: 0.98 | T199: 0.7 | U199: 0.96 | V199: 0.96 | W199: 0.96 | X199: 0.9
A200: 194 | B200: 330CL | C200: 02 | D200: 10.5 | E200: 14 | F200: 330CL-2 | G200: D 汽车用钢-汽车车轮用钢-D08 330CL | H200: 1527 | I200: 0.053 | J200: 0.11916667 | K200: 0 | L200: 0.98 | M200: 0.98 | N200: 0.98 | O200: 0.7 | P200: 0.96 | Q200: 0.98 | R200: 0.98 | S200: 0.98 | T200: 0.7 | U200: 0.96 | V200: 0.96 | W200: 0.96 | X200: 0.9
A201: 195 | B201: 380CL | C201: 01 | D201: 2 | E201: 4.99 | F201: 380CL-1 | G201: D 汽车用钢-汽车车轮用钢-D02 380CL | H201: 1525 | I201: 0.0448 | J201: 0.1058 | K201: 0 | L201: 0.98 | M201: 0.98 | N201: 0.98 | O201: 0.7 | P201: 0.96 | Q201: 0.98 | R201: 0.98 | S201: 0.98 | T201: 0.7 | U201: 0.96 | V201: 0.96 | W201: 0.96 | X201: 0.9
A202: 196 | B202: 380CL | C202: 02 | D202: 5 | E202: 18 | F202: 380CL-2 | G202: D 汽车用钢-汽车车轮用钢-D02 380CL | H202: 1524 | I202: 0.0448 | J202: 0.1058 | K202: 0.8 | L202: 0.98 | M202: 0.98 | N202: 0.98 | O202: 0.7 | P202: 0.96 | Q202: 0.98 | R202: 0.98 | S202: 0.98 | T202: 0.7 | U202: 0.96 | V202: 0.96 | W202: 0.96 | X202: 0.9
A203: 197 | B203: 380CL-QL | C203: 01 | D203: 2 | E203: 4.99 | F203: 380CL-QL1 | G203: D 汽车用钢-汽车车轮用钢-D23 380CL-QL | H203: 1525 | I203: 0.041125 | J203: 0.09225 | K203: 0 | L203: 0.98 | M203: 0.98 | N203: 0.98 | O203: 0.7 | P203: 0.96 | Q203: 0.98 | R203: 0.98 | S203: 0.98 | T203: 0.7 | U203: 0.96 | V203: 0.96 | W203: 0.96 | X203: 0.9
A204: 198 | B204: 380CL-QL | C204: 02 | D204: 5 | E204: 18 | F204: 380CL-QL2 | G204: D 汽车用钢-汽车车轮用钢-D23 380CL-QL | H204: 1524 | I204: 0.041125 | J204: 0.09225 | K204: 0.8 | L204: 0.98 | M204: 0.98 | N204: 0.98 | O204: 0.7 | P204: 0.96 | Q204: 0.98 | R204: 0.98 | S204: 0.98 | T204: 0.7 | U204: 0.96 | V204: 0.96 | W204: 0.96 | X204: 0.9
A205: 199 | B205: 380CL-JD | C205: 01 | D205: 4 | E205: 6 | F205: 380CL-JD1 | G205: D 汽车用钢-汽车车轮用钢-D25 380CL-JD | H205: 1523.8 | I205: 0.041125 | J205: 0.09225 | K205: 0.8 | L205: 0.98 | M205: 0.98 | N205: 0.98 | O205: 0.7 | P205: 0.96 | Q205: 0.98 | R205: 0.98 | S205: 0.98 | T205: 0.7 | U205: 0.96 | V205: 0.96 | W205: 0.96 | X205: 0.9
A206: 200 | B206: 380CL-JD | C206: 02 | D206: 6.01 | E206: 12 | F206: 380CL-JD2 | G206: D 汽车用钢-汽车车轮用钢-D25 380CL-JD | H206: 1522.9 | I206: 0.041125 | J206: 0.09225 | K206: 0.8 | L206: 0.98 | M206: 0.98 | N206: 0.98 | O206: 0.7 | P206: 0.96 | Q206: 0.98 | R206: 0.98 | S206: 0.98 | T206: 0.7 | U206: 0.96 | V206: 0.96 | W206: 0.96 | X206: 0.9
A207: 201 | B207: 380CL-JD | C207: 03 | D207: 12.01 | E207: 20 | F207: 380CL-JD3 | G207: D 汽车用钢-汽车车轮用钢-D25 380CL-JD | H207: 1522.9 | I207: 0.041125 | J207: 0.09225 | K207: 0.8 | L207: 0.98 | M207: 0.98 | N207: 0.98 | O207: 0.7 | P207: 0.96 | Q207: 0.98 | R207: 0.98 | S207: 0.98 | T207: 0.7 | U207: 0.96 | V207: 0.96 | W207: 0.96 | X207: 0.9
A208: 202 | B208: 420CL | C208: 01 | D208: 2 | E208: 5.99 | F208: 420CL-1 | G208: D 汽车用钢-汽车车轮用钢-D18 420CL | H208: 1525 | I208: 0.043 | J208: 0.080833333 | K208: 0.8 | L208: 0.98 | M208: 0.98 | N208: 0.98 | O208: 0.7 | P208: 0.96 | Q208: 0.98 | R208: 0.98 | S208: 0.98 | T208: 0.7 | U208: 0.96 | V208: 0.96 | W208: 0.96 | X208: 0.9
A209: 203 | B209: 420CL | C209: 02 | D209: 6 | E209: 14 | F209: 420CL-2 | G209: D 汽车用钢-汽车车轮用钢-D18 420CL | H209: 1525 | I209: 0.043 | J209: 0.080833333 | K209: 0.8 | L209: 0.98 | M209: 0.98 | N209: 0.98 | O209: 0.7 | P209: 0.96 | Q209: 0.98 | R209: 0.98 | S209: 0.98 | T209: 0.7 | U209: 0.96 | V209: 0.96 | W209: 0.96 | X209: 0.9
A210: 204 | B210: SL440 | C210: 01 | D210: 20 | E210: 26 | F210: SL440 | G210: D 汽车用钢-汽车车轮用钢-D21 SL440 | H210: 1522 | I210: 0.048333333 | J210: 0.082 | K210: 0.8 | L210: 0.98 | M210: 0.98 | N210: 0.98 | O210: 0.7 | P210: 0.96 | Q210: 0.98 | R210: 0.98 | S210: 0.98 | T210: 0.7 | U210: 0.96 | V210: 0.96 | W210: 0.96 | X210: 0.9
... A278: 272 | B278: NM450 | C278: 01 | D278: 6 | E278: 15.99 | F278: NM450-1 | G278: J 耐磨钢-450级别-J06 NM450 | H278: 1508 | I278: 0.052 | J278: 0.11366667 | K278: 0.8 | L278: 0.98 | M278: 0.98 | N278: 0.98 | O278: 0.7 | P278: 0.96 | Q278: 0.98 | R278: 0.98 | S278: 0.98 | T278: 0.7 | U278: 0.96 | V278: 0.96 | W278: 0.96 | X278: 0.9
A279: 273 | B279: NM450 | C279: 02 | D279: 16 | E279: 28 | F279: NM450-2 | G279: J 耐磨钢-450级别-J06 NM450 | H279: 1508 | I279: 0.06075 | J279: 0.114375 | K279: 0.8 | L279: 0.98 | M279: 0.98 | N279: 0.98 | O279: 0.7 | P279: 0.96 | Q279: 0.98 | R279: 0.98 | S279: 0.98 | T279: 0.7 | U279: 0.96 | V279: 0.96 | W279: 0.96 | X279: 0.9 | Y279: 0.0065326633
A280: 274 | B280: NM500 | C280: 01 | D280: 6 | E280: 15.99 | F280: NM500-1 | G280: J 耐磨钢-500级别-J07 NM500 | H280: 1504 | I280: 0.05 | J280: 0.11 | K280: 0.8 | L280: 0.98 | M280: 0.98 | N280: 0.98 | O280: 0.7 | P280: 0.96 | Q280: 0.98 | R280: 0.98 | S280: 0.98 | T280: 0.7 | U280: 0.96 | V280: 0.96 | W280: 0.96 | X280: 0.9
A281: 275 | B281: NM500 | C281: 02 | D281: 16 | E281: 28 | F281: NM500-2 | G281: J 耐磨钢-500级别-J07 NM500 | H281: 1504 | I281: 0.05 | J281: 0.11 | K281: 0.8 | L281: 0.98 | M281: 0.98 | N281: 0.98 | O281: 0.7 | P281: 0.96 | Q281: 0.98 | R281: 0.98 | S281: 0.98 | T281: 0.7 | U281: 0.96 | V281: 0.96 | W281: 0.96 | X281: 0.9
A282: 276 | B282: NM600 | C282: 01 | D282: 6 | E282: 15.99 | F282: NM600-1 | G282: J 耐磨钢-600级别-J10 NM600 | H282: 1492 | I282: 0.05 | J282: 0.11 | K282: 0.8 | L282: 0.98 | M282: 0.98 | N282: 0.98 | O282: 0.7 | P282: 0.96 | Q282: 0.98 | R282: 0.98 | S282: 0.98 | T282: 0.7 | U282: 0.96 | V282: 0.96 | W282: 0.96 | X282: 0.9
A283: 277 | B283: NM600 | C283: 02 | D283: 16 | E283: 25.4 | F283: NM600-2 | G283: J 耐磨钢-600级别-J10 NM600 | H283: 1492 | I283: 0.05 | J283: 0.11 | K283: 0.8 | L283: 0.98 | M283: 0.98 | N283: 0.98 | O283: 0.7 | P283: 0.96 | Q283: 0.98 | R283: 0.98 | S283: 0.98 | T283: 0.7 | U283: 0.96 | V283: 0.96 | W283: 0.96 | X283: 0.9
A284: 278 | B284: Q690D | C284: 01 | D284: 3 | E284: 20 | F284: Q690D-1 | G284: Q 高强钢-690系列-Q01 Q690D | H284: 1514 | I284: 0.0565 | J284: 0.1145 | K284: 0.8 | L284: 0.98 | M284: 0.98 | N284: 0.98 | O284: 0.7 | P284: 0.96 | Q284: 0.98 | R284: 0.98 | S284: 0.98 | T284: 0.7 | U284: 0.96 | V284: 0.96 | W284: 0.96 | X284: 0.9
A285: 279 | B285: A | C285: 01 | D285: 3.5 | E285: 25.4 | F285: A | G285: G 船舶结构用钢- 一般强度结构钢-G01 A | H285: 1519 | I285: 0.074291718 | J285: 0.12718789 | K285: 0.8 | L285: 0.98 | M285: 0.98 | N285: 0.98 | O285: 0.7 | P285: 0.96 | Q285: 0.98 | R285: 0.98 | S285: 0.98 | T285: 0.7 | U285: 0.96 | V285: 0.96 | W285: 0.96 | X285: 0.9
A286: 280 | B286: B | C286: 01 | D286: 4 | E286: 25.4 | F286: B | G286: G 船舶结构用钢- 一般强度结构钢-G01 A | H286: 1519 | I286: 0.073384615 | J286: 0.12594872 | K286: 0.8 | L286: 0.98 | M286: 0.98 | N286: 0.98 | O286: 0.7 | P286: 0.96 | Q286: 0.98 | R286: 0.98 | S286: 0.98 | T286: 0.7 | U286: 0.96 | V286: 0.96 | W286: 0.96 | X286: 0.9
A287: 281 | B287: AH32 | C287: 01 | D287: 4 | E287: 12.5 | F287: AH32-1 | G287: G 船舶结构用钢- 一般强度结构钢-G01 A | H287: 1521 | I287: 0.04 | J287: 0.094833333 | K287: 0.8 | L287: 0.98 | M287: 0.98 | N287: 0.98 | O287: 0.7 | P287: 0.96 | Q287: 0.98 | R287: 0.98 | S287: 0.98 | T287: 0.7 | U287: 0.96 | V287: 0.96 | W287: 0.96 | X287: 0.9
A288: 282 | B288: AH32 | C288: 02 | D288: 12.51 | E288: 25 | F288: AH32-2 | G288: G 船舶结构用钢- 一般强度结构钢-G01 A | H288: 1521 | I288: 0.044 | J288: 0.095 | K288: 0.8 | L288: 0.98 | M288: 0.98 | N288: 0.98 | O288: 0.7 | P288: 0.96 | Q288: 0.98 | R288: 0.98 | S288: 0.98 | T288: 0.7 | U288: 0.96 | V288: 0.96 | W288: 0.96 | X288: 0.9
A289: 283 | B289: AH36 | C289: 01 | D289: 4 | E289: 12.5 | F289: AH36-1 | G289: G 船舶结构用钢- 一般强度结构钢-G01 A | H289: 1521 | I289: 0.042963636 | J289: 0.089363636 | K289: 0.8 | L289: 0.98 | M289: 0.98 | N289: 0.98 | O289: 0.7 | P289: 0.96 | Q289: 0.98 | R289: 0.98 | S289: 0.98 | T289: 0.7 | U289: 0.96 | V289: 0.96 | W289: 0.96 | X289: 0.9
...

Sheet 1.合金成本
A2: 序号 | B2: 适用 牌号 | C2: 分类 序号 | D2: 最小厚度mm | E2: 最大厚度mm | F2: 炼钢 牌号 | G2: 钢种类型 | H2: 液相线温度℃ | I2: 内控成分目标值/wt% | AA2: 备注 | AB2: 硅锰 | AC2: 高碳锰铁 | AD2: 中碳锰铁 | AE2: 低碳锰铁 | AF2: 金属锰 | AG2: 硅铁合金 | AH2: 铝块 | AI2: 钒铁 | AJ2: 铌铁 | AK2: 钛铁 | AL2: 高碳铬铁 | AM2: 低碳铬铁 | AN2: 镍板 | AO2: 铜板 | AP2: 钼铁 | AQ2: 硼铁 | AR2: 锑锭 | AS2: 磷铁 | AT2: 硫铁 | AU2: 稀土合金 | AV2: 合金消耗 | AW2: 合金成本 | AY2: 钢种 | AZ2: 增碳验证 | BK2: 是否 验证 | BL2: 更新 日期
I3: C | J3: Si | K3: Mn | L3: P | M3: S | N3: V | O3: Nb | P3: Ti | Q3: Als | R3: Alt | S3: Ca | T3: Cr | U3: Ni | V3: Cu | W3: Mo | X3: B | Y3: Sb | Z3: N | AB3: 17.69/65.66 | AC3: 74.6 | AD3: 78.54 | AE3: 81.19 | AF3: 90 | AG3: 72.23 | AH3: 99 | AI3: 51.17 | AJ3: 65.04 | AK3: 71.58 | AL3: 52 | AM3: 59.44 | AN3: 99 | AO3: 99 | AP3: 57.7 | AQ3: 18 | AR3: 99.5 | AS3: 23.94 | AT3: 29 | AZ3: 转炉终点碳 | BA3: 增碳余量 | BB3: 硅锰 | BC3: 高碳锰铁 | BD3: 中碳锰铁 | BE3: 低碳锰铁 | BF3: 高碳铬铁 | BG3: 低碳铬铁 | BH3: 增碳量 | BI3: 预估钢水碳 | BJ3: 预估-目标
B4: 合金不含税价格 | AB4: 5424.7788 | AC4: 6044.2478 | AD4: 7730.0885 | AE4: 8407.0796 | AF4: 16725.664 | AG4: 5185.8407 | AH4: 22337.168 | AI4: 85398.23 | AJ4: 215376.11 | AK4: 24070.796 | AL4: 7778.7611 | AM4: 14407.08 | AN4: 137787.61 | AO4: 95982.301 | AP4: 272566.37 | AQ4: 24070.796 | AR4: 176106.11 | AS4: 3443.64 | AT4: 3000 | AU4: 0 | BB4: 1.72 | BC4: 6.69 | BD4: 1.5 | BE4: 0.64 | BF4: 10 | BG4: 0.12
A5: 1 | B5: Q195 | C5: 01 | D5: 1.5 | E5: 12 | F5: Q195-1 | G5: A 碳素钢-碳素结构钢-A20 Q195 | H5: 1527 | I5: 0.07 | J5: 0.15 | K5: 0.25 | L5: 0.02 | M5: 0.015 | P5: 0.01 | Q5: 0.01 | Z5: 60 | AB5: =IF(J5<=0.04,0,IF((BA5-AL5*BF$4*炼钢参数表!$X$5/1000-AM5*BG$4*炼钢参数表!$X$5/1000)<=0.03,0,IF((J5/100/0.1769/炼钢参数表!K5*1000)>(K5-炼钢参数表!J5)/100/0.6566/炼钢参数表!L5*1000,IF(K5<1.6,(K5-炼钢参数表!J5)/100/0.6566/炼钢参数表!L5*1000,(K5-0.08-炼钢参数表!J5)/100/0.6566/炼钢参数表!L5*1000),IF(K5<1.6,J5/100/0.1769/炼钢参数表!K5*1000,(J5-0.08)/100/0.1769/炼钢参数表!K5*1000)))) -> 0 | AC5: =IF((BA5-AB5*$BB$4*0.9/1000-AL5*BF$4*炼钢参数表!$X$5/1000-AM5*BG$4*炼钢参数表!$X$5/1000)<(K5-炼钢参数表!J5-AB5*0.6566*炼钢参数表!L5/10)*0.082,0,(K5-炼钢参数表!J5-AB5*0.6566*炼钢参数表!L5/10)/100/($AC$3/100)/炼钢参数表!L5*1000) -> 2.0107239 | AD5: =IF((BA5-AB5*$BB$4*0.9/1000-AC5*$BC$4*0.9/1000-AL5*BF$4*炼钢参数表!$X$5/1000-AM5*BG$4*炼钢参数表!$X$5/1000)<=(K5-炼钢参数表!J5-AB5*0.6566*炼钢参数表!L5/10-AC5*($AC$3/100)*炼钢参数表!L5/10)*0.02,0,((K5-炼钢参数表!J5-AB5*0.6566*炼钢参数表!L5/10-AC5*($AC$3/100)*炼钢参数表!L5/10)/100/($AD$3/100)/炼钢参数表!L5*1000)) -> 0 | AE5: =(K5-炼钢参数表!J5-AB5*0.6566*炼钢参数表!L5/10-AC5*($AC$3/100)*炼钢参数表!L5/10-AD5*($AD$3/100)*炼钢参数表!L5/10)/100/($AE$3/100)/炼钢参数表!L5*1000 -> 0 | AF5: 0 | AG5: =IF(J5<=0.04,0,((J5-(AB5*0.1769*炼钢参数表!K5/1000*100))/100/炼钢参数表!K5/($AG$3/100)*1000)) -> 2.7689326 | AH5: 1.45 | AI5: =IF(N5="",0,IF(N5<=0.002,0,((N5)/100)/($AI$3/100)/炼钢参数表!M5*1000)) -> 0 | AJ5: =IF(O5="",0,IF(O5<=0.002,0,((O5)/100)/($AJ$3/100)/炼钢参数表!N5*1000)) -> 0 | AK5: =IF(P5="",0,IF(P5<=0.002,0,((P5+0.005)/100)/($AK$3/100)/炼钢参数表!O5*1000)) -> 0.29936535 | AL5: =IF((BA5-J5*0.00003-K5*0.00024)<=0.05,0,IF(T5="",0,IF(T5<=0.03,0,IF(((BA5-J5*0.00003-K5*0.00024)-0.05)/0.18/100/($AL$3/100)/炼钢参数表!P5*1000<=T5/100/($AL$3/100)/炼钢参数表!P5*1000,((BA5-J5*0.00003-K5*0.00024)-0.05)/0.18/100/($AL$3/100)/炼钢参数表!P5*1000,T5/100/($AL$3/100)/炼钢参数表!P5*1000)))) -> 0 | AM5: =IF(T5="",0,IF(T5<=0.03,0,((T5-AL5*($AL$3/100)*炼钢参数表!P5/10)/100/($AM$3/100)/炼钢参数表!P5*1000))) -> 0 | AN5: =IF(U5="",0,IF(U5<=0.02,0,(U5/100)/($AN$3/100)/炼钢参数表!Q5*1000)) -> 0 | AO5: =IF(V5="",0,IF(V5<=0.02,0,(V5/100)/($AO$3/100)/炼钢参数表!R5*1000)) -> 0 | AP5: =IF(W5="",0,IF(W5<=0.02,0,(W5/100)/($AP$3/100)/炼钢参数表!S5*1000)) -> 0 | AQ5: =IF(X5="",0,IF(X5<=0.0002,0,(X5/100)/($AQ$3/100)/炼钢参数表!T5*1000)) -> 0 | AR5: =IF(Y5="",0,IF(Y5<=0.02,0,(Y5/100)/($AR$3/100)/炼钢参数表!U5*1000)) -> 0 | AS5: =IF(L5<=0.04,0,((L5-0.04)/100)/($AS$3/100)/炼钢参数表!V5*1000) -> 0 | AT5: =IF(M5<=0.03,0,((M5-0.03)/100)/($AT$3/100)/炼钢参数表!W5*1000) -> 0 | AV5: =SUM(AB5:AU5) -> 6.5290218 | AW5: {=SUMPRODUCT($AB$4:$AU$4,AB5:AU5)/1000} -> 66.107413 | AY5: =F5 -> Q195-1 | AZ5: =VLOOKUP(AY5,炼钢参数表!$F$5:$J$1027,4,0) -> 0.041666667 | BA5: =I5-AZ5 -> 0.028333333 | BB5: =AB5*$BB$4*炼钢参数表!$X$5/1000 -> 0 | BC5: =AC5*$BC$4*炼钢参数表!$X$5/1000 -> 0.012106568 | BD5: =AD5*$BD$4*炼钢参数表!$X$5/1000 -> 0 | BE5: =AE5*$BE$4*炼钢参数表!$X$5/1000 -> 0 | BF5: =AL5*$BF$4*炼钢参数表!$X$5/1000 -> 0 | BG5: =AM5*$BG$4*炼钢参数表!$X$5/1000 -> 0 | BH5: =SUM(BB5:BG5) -> 0.012106568 | BI5: =AZ5+BH5 -> 0.053773235 | BJ5: =BI5-I5 -> -0.016226765
A6: 2 | B6: Q195 | C6: 02 | D6: 12.01 | E6: 28 | F6: Q195-2 | G6: A 碳素钢-碳素结构钢-A20 Q195 | H6: 1527 | I6: 0.07 | J6: 0.15 | K6: 0.32 | L6: 0.02 | M6: 0.015 | Q6: 0.01 | Z6: 60 | AB6: =IF(J6<=0.04,0,IF((BA6-AL6*BF$4*炼钢参数表!$X$5/1000-AM6*BG$4*炼钢参数表!$X$5/1000)<=0.03,0,IF((J6/100/0.1769/炼钢参数表!K6*1000)>(K6-炼钢参数表!J6)/100/0.6566/炼钢参数表!L6*1000,IF(K6<1.6,(K6-炼钢参数表!J6)/100/0.6566/炼钢参数表!L6*1000,(K6-0.08-炼钢参数表!J6)/100/0.6566/炼钢参数表!L6*1000),IF(K6<1.6,J6/100/0.1769/炼钢参数表!K6*1000,(J6-0.08)/100/0.1769/炼钢参数表!K6*1000)))) -> 0 | AC6: =IF((BA6-AB6*$BB$4*0.9/1000-AL6*BF$4*炼钢参数表!$X$5/1000-AM6*BG$4*炼钢参数表!$X$5/1000)<(K6-炼钢参数表!J6-AB6*0.6566*炼钢参数表!L6/10)*0.082,0,(K6-炼钢参数表!J6-AB6*0.6566*炼钢参数表!L6/10)/100/($AC$3/100)/炼钢参数表!L6*1000) -> 2.9682114 | AD6: =IF((BA6-AB6*$BB$4*0.9/1000-AC6*$BC$4*0.9/1000-AL6*BF$4*炼钢参数表!$X$5/1000-AM6*BG$4*炼钢参数表!$X$5/1000)<=(K6-炼钢参数表!J6-AB6*0.6566*炼钢参数表!L6/10-AC6*($AC$3/100)*炼钢参数表!L6/10)*0.02,0,((K6-炼钢参数表!J6-AB6*0.6566*炼钢参数表!L6/10-AC6*($AC$3/100)*炼钢参数表!L6/10)/100/($AD$3/100)/炼钢参数表!L6*1000)) -> 0 | AE6: =(K6-炼钢参数表!J6-AB6*0.6566*炼钢参数表!L6/10-AC6*($AC$3/100)*炼钢参数表!L6/10-AD6*($AD$3/100)*炼钢参数表!L6/10)/100/($AE$3/100)/炼钢参数表!L6*1000 -> 0 | AF6: 0 | AG6: =IF(J6<=0.04,0,((J6-(AB6*0.1769*炼钢参数表!K6/1000*100))/100/炼钢参数表!K6/($AG$3/100)*1000)) -> 2.7689326 | AH6: 1.45 | AI6: =IF(N6="",0,IF(N6<=0.002,0,((N6)/100)/($AI$3/100)/炼钢参数表!M6*1000)) -> 0 | AJ6: =IF(O6="",0,IF(O6<=0.002,0,((O6)/100)/($AJ$3/100)/炼钢参数表!N6*1000)) -> 0 | AK6: =IF(P6="",0,IF(P6<=0.002,0,((P6+0.005)/100)/($AK$3/100)/炼钢参数表!O6*1000)) -> 0 | AL6: =IF((BA6-J6*0.00003-K6*0.00024)<=0.05,0,IF(T6="",0,IF(T6<=0.03,0,IF(((BA6-J6*0.00003-K6*0.00024)-0.05)/0.18/100/($AL$3/100)/炼钢参数表!P6*1000<=T6/100/($AL$3/100)/炼钢参数表!P6*1000,((BA6-J6*0.00003-K6*0.00024)-0.05)/0.18/100/($AL$3/100)/炼钢参数表!P6*1000,T6/100/($AL$3/100)/炼钢参数表!P6*1000)))) -> 0 | AM6: =IF(T6="",0,IF(T6<=0.03,0,((T6-AL6*($AL$3/100)*炼钢参数表!P6/10)/100/($AM$3/100)/炼钢参数表!P6*1000))) -> 0 | AN6: =IF(U6="",0,IF(U6<=0.02,0,(U6/100)/($AN$3/100)/炼钢参数表!Q6*1000)) -> 0 | AO6: =IF(V6="",0,IF(V6<=0.02,0,(V6/100)/($AO$3/100)/炼钢参数表!R6*1000)) -> 0 | AP6: =IF(W6="",0,IF(W6<=0.02,0,(W6/100)/($AP$3/100)/炼钢参数表!S6*1000)) -> 0 | AQ6: =IF(X6="",0,IF(X6<=0.0002,0,(X6/100)/($AQ$3/100)/炼钢参数表!T6*1000)) -> 0 | AR6: =IF(Y6="",0,IF(Y6<=0.02,0,(Y6/100)/($AR$3/100)/炼钢参数表!U6*1000)) -> 0 | AS6: =IF(L6<=0.04,0,((L6-0.04)/100)/($AS$3/100)/炼钢参数表!V6*1000) -> 0 | AT6: =IF(M6<=0.03,0,((M6-0.03)/100)/($AT$3/100)/炼钢参数表!W6*1000) -> 0 | AV6: =SUM(AB6:AU6) -> 7.187144 | AW6: {=SUMPRODUCT($AB$4:$AU$4,AB6:AU6)/1000} -> 64.688742 | AY6: =F6 -> Q195-2 | AZ6: =VLOOKUP(AY6,炼钢参数表!$F$5:$J$1027,4,0) -> 0.041666667 | BA6: =I6-AZ6 -> 0.028333333 | BB6: =AB6*$BB$4*炼钢参数表!$X$5/1000 -> 0 | BC6: =AC6*$BC$4*炼钢参数表!$X$5/1000 -> 0.017871601 | BD6: =AD6*$BD$4*炼钢参数表!$X$5/1000 -> 0 | BE6: =AE6*$BE$4*炼钢参数表!$X$5/1000 -> 0 | BF6: =AL6*$BF$4*炼钢参数表!$X$5/1000 -> 0 | BG6: =AM6*$BG$4*炼钢参数表!$X$5/1000 -> 0 | BH6: =SUM(BB6:BG6) -> 0.017871601 | BI6: =AZ6+BH6 -> 0.059538268 | BJ6: =BI6-I6 -> -0.010461732
A7: 3 | B7: Q235B | C7: 01 | D7: 1.45 | E7: 12 | F7: Q235B-1 | G7: A 碳素钢-碳素结构钢-A01 Q235B | H7: 1519 | I7: 0.16 | J7: 0.08 | K7: 0.23 | L7: 0.025 | M7: 0.02 | Q7: 0.01 | AB7: =IF(J7<=0.04,0,IF((BA7-AL7*BF$4*炼钢参数表!$X$5/1000-AM7*BG$4*炼钢参数表!$X$5/1000)<=0.03,0,IF((J7/100/0.1769/炼钢参数表!K7*1000)>(K7-炼钢参数表!J7)/100/0.6566/炼钢参数表!L7*1000,IF(K7<1.6,(K7-炼钢参数表!J7)/100/0.6566/炼钢参数表!L7*1000,(K7-0.08-炼钢参数表!J7)/100/0.6566/炼钢参数表!L7*1000),IF(K7<1.6,J7/100/0.1769/炼钢参数表!K7*1000,(J7-0.08)/100/0.1769/炼钢参数表!K7*1000)))) -> 1.6738627 | AC7: =IF((BA7-AB7*$BB$4*0.9/1000-AL7*BF$4*炼钢参数表!$X$5/1000-AM7*BG$4*炼钢参数表!$X$5/1000)<(K7-炼钢参数表!J7-AB7*0.6566*炼钢参数表!L7/10)*0.082,0,(K7-炼钢参数表!J7-AB7*0.6566*炼钢参数表!L7/10)/100/($AC$3/100)/炼钢参数表!L7*1000) -> 0 | AD7: =IF((BA7-AB7*$BB$4*0.9/1000-AC7*$BC$4*0.9/1000-AL7*BF$4*炼钢参数表!$X$5/1000-AM7*BG$4*炼钢参数表!$X$5/1000)<=(K7-炼钢参数表!J7-AB7*0.6566*炼钢参数表!L7/10-AC7*($AC$3/100)*炼钢参数表!L7/10)*0.02,0,((K7-炼钢参数表!J7-AB7*0.6566*炼钢参数表!L7/10-AC7*($AC$3/100)*炼钢参数表!L7/10)/100/($AD$3/100)/炼钢参数表!L7*1000)) -> 0 | AE7: =(K7-炼钢参数表!J7-AB7*0.6566*炼钢参数表!L7/10-AC7*($AC$3/100)*炼钢参数表!L7/10-AD7*($AD$3/100)*炼钢参数表!L7/10)/100/($AE$3/100)/炼钢参数表!L7*1000 -> 0 | AF7: 0 | AG7: =IF(J7<=0.04,0,((J7-(AB7*0.1769*炼钢参数表!K7/1000*100))/100/炼钢参数表!K7/($AG$3/100)*1000)) -> 1.0668148 | AH7: 1.2022258 | AI7: =IF(N7="",0,IF(N7<=0.002,0,((N7)/100)/($AI$3/100)/炼钢参数表!M7*1000)) -> 0 | AJ7: =IF(O7="",0,IF(O7<=0.002,0,((O7)/100)/($AJ$3/100)/炼钢参数表!N7*1000)) -> 0 | AK7: =IF(P7="",0,IF(P7<=0.002,0,((P7+0.005)/100)/($AK$3/100)/炼钢参数表!O7*1000)) -> 0 | AL7: =IF((BA7-J7*0.00003-K7*0.00024)<=0.05,0,IF(T7="",0,IF(T7<=0.03,0,IF(((BA7-J7*0.00003-K7*0.00024)-0.05)/0.18/100/($AL$3/100)/炼钢参数表!P7*1000<=T7/100/($AL$3/100)/炼钢参数表!P7*1000,((BA7-J7*0.00003-K7*0.00024)-0.05)/0.18/100/($AL$3/100)/炼钢参数表!P7*1000,T7/100/($AL$3/100)/炼钢参数表!P7*1000)))) -> 0 | AM7: =IF(T7="",0,IF(T7<=0.03,0,((T7-AL7*($AL$3/100)*炼钢参数表!P7/10)/100/($AM$3/100)/炼钢参数表!P7*1000))) -> 0 | AN7: =IF(U7="",0,IF(U7<=0.02,0,(U7/100)/($AN$3/100)/炼钢参数表!Q7*1000)) -> 0 | AO7: =IF(V7="",0,IF(V7<=0.02,0,(V7/100)/($AO$3/100)/炼钢参数表!R7*1000)) -> 0 | AP7: =IF(W7="",0,IF(W7<=0.02,0,(W7/100)/($AP$3/100)/炼钢参数表!S7*1000)) -> 0 | AQ7: =IF(X7="",0,IF(X7<=0.0002,0,(X7/100)/($AQ$3/100)/炼钢参数表!T7*1000)) -> 0 | AR7: =IF(Y7="",0,IF(Y7<=0.02,0,(Y7/100)/($AR$3/100)/炼钢参数表!U7*1000)) -> 0 | AS7: =IF(L7<=0.04,0,((L7-0.04)/100)/($AS$3/100)/炼钢参数表!V7*1000) -> 0 | AT7: =IF(M7<=0.03,0,((M7-0.03)/100)/($AT$3/100)/炼钢参数表!W7*1000) -> 0 | AV7: =SUM(AB7:AU7) -> 3.9429033 | AW7: {=SUMPRODUCT($AB$4:$AU$4,AB7:AU7)/1000} -> 41.466986 | AY7: =F7 -> Q235B-1 | AZ7: =VLOOKUP(AY7,炼钢参数表!$F$5:$J$1027,4,0) -> 0.07293667 | BA7: =I7-AZ7 -> 0.08706333 | BB7: =AB7*$BB$4*炼钢参数表!$X$5/1000 -> 0.0025911394 | BC7: =AC7*$BC$4*炼钢参数表!$X$5/1000 -> 0 | BD7: =AD7*$BD$4*炼钢参数表!$X$5/1000 -> 0 | BE7: =AE7*$BE$4*炼钢参数表!$X$5/1000 -> 0 | BF7: =AL7*$BF$4*炼钢参数表!$X$5/1000 -> 0 | BG7: =AM7*$BG$4*炼钢参数表!$X$5/1000 -> 0 | BH7: =SUM(BB7:BG7) -> 0.0025911394 | BI7: =AZ7+BH7 -> 0.075527809 | BJ7: =BI7-I7 -> -0.084472191
A8: 4 | B8: Q235B | C8: 02 | D8: 12.01 | E8: 28 | F8: Q235B-2 | G8: A 碳素钢-碳素结构钢-A01 Q235B | H8: 1519 | I8: 0.16 | J8: 0.08 | K8: 0.38 | L8: 0.025 | M8: 0.02 | Q8: 0.01 | AB8: =IF(J8<=0.04,0,IF((BA8-AL8*BF$4*炼钢参数表!$X$5/1000-AM8*BG$4*炼钢参数表!$X$5/1000)<=0.03,0,IF((J8/100/0.1769/炼钢参数表!K8*1000)>(K8-炼钢参数表!J8)/100/0.6566/炼钢参数表!L8*1000,IF(K8<1.6,(K8-炼钢参数表!J8)/100/0.6566/炼钢参数表!L8*1000,(K8-0.08-炼钢参数表!J8)/100/0.6566/炼钢参数表!L8*1000),IF(K8<1.6,J8/100/0.1769/炼钢参数表!K8*1000,(J8-0.08)/100/0.1769/炼钢参数表!K8*1000)))) -> 3.9995097 | AC8: =IF((BA8-AB8*$BB$4*0.9/1000-AL8*BF$4*炼钢参数表!$X$5/1000-AM8*BG$4*炼钢参数表!$X$5/1000)<(K8-炼钢参数表!J8-AB8*0.6566*炼钢参数表!L8/10)*0.082,0,(K8-炼钢参数表!J8-AB8*0.6566*炼钢参数表!L8/10)/100/($AC$3/100)/炼钢参数表!L8*1000) -> 0 | AD8: =IF((BA8-AB8*$BB$4*0.9/1000-AC8*$BC$4*0.9/1000-AL8*BF$4*炼钢参数表!$X$5/1000-AM8*BG$4*炼钢参数表!$X$5/1000)<=(K8-炼钢参数表!J8-AB8*0.6566*炼钢参数表!L8/10-AC8*($AC$3/100)*炼钢参数表!L8/10)*0.02,0,((K8-炼钢参数表!J8-AB8*0.6566*炼钢参数表!L8/10-AC8*($AC$3/100)*炼钢参数表!L8/10)/100/($AD$3/100)/炼钢参数表!L8*1000)) -> 0 | AE8: =(K8-炼钢参数表!J8-AB8*0.6566*炼钢参数表!L8/10-AC8*($AC$3/100)*炼钢参数表!L8/10-AD8*($AD$3/100)*炼钢参数表!L8/10)/100/($AE$3/100)/炼钢参数表!L8*1000 -> 0 | AF8: 0 | AG8: =IF(J8<=0.04,0,((J8-(AB8*0.1769*炼钢参数表!K8/1000*100))/100/炼钢参数表!K8/($AG$3/100)*1000)) -> 0.49723578 | AH8: 1.2 | AI8: =IF(N8="",0,IF(N8<=0.002,0,((N8)/100)/($AI$3/100)/炼钢参数表!M8*1000)) -> 0 | AJ8: =IF(O8="",0,IF(O8<=0.002,0,((O8)/100)/($AJ$3/100)/炼钢参数表!N8*1000)) -> 0 | AK8: =IF(P8="",0,IF(P8<=0.002,0,((P8+0.005)/100)/($AK$3/100)/炼钢参数表!O8*1000)) -> 0 | AL8: =IF((BA8-J8*0.00003-K8*0.00024)<=0.05,0,IF(T8="",0,IF(T8<=0.03,0,IF(((BA8-J8*0.00003-K8*0.00024)-0.05)/0.18/100/($AL$3/100)/炼钢参数表!P8*1000<=T8/100/($AL$3/100)/炼钢参数表!P8*1000,((BA8-J8*0.00003-K8*0.00024)-0.05)/0.18/100/($AL$3/100)/炼钢参数表!P8*1000,T8/100/($AL$3/100)/炼钢参数表!P8*1000)))) -> 0 | AM8: =IF(T8="",0,IF(T8<=0.03,0,((T8-AL8*($AL$3/100)*炼钢参数表!P8/10)/100/($AM$3/100)/炼钢参数表!P8*1000))) -> 0 | AN8: =IF(U8="",0,IF(U8<=0.02,0,(U8/100)/($AN$3/100)/炼钢参数表!Q8*1000)) -> 0 | AO8: =IF(V8="",0,IF(V8<=0.02,0,(V8/100)/($AO$3/100)/炼钢参数表!R8*1000)) -> 0 | AP8: =IF(W8="",0,IF(W8<=0.02,0,(W8/100)/($AP$3/100)/炼钢参数表!S8*1000)) -> 0 | AQ8: =IF(X8="",0,IF(X8<=0.0002,0,(X8/100)/($AQ$3/100)/炼钢参数表!T8*1000)) -> 0 | AR8: =IF(Y8="",0,IF(Y8<=0.02,0,(Y8/100)/($AR$3/100)/炼钢参数表!U8*1000)) -> 0 | AS8: =IF(L8<=0.04,0,((L8-0.04)/100)/($AS$3/100)/炼钢参数表!V8*1000) -> 0 | AT8: =IF(M8<=0.03,0,((M8-0.03)/100)/($AT$3/100)/炼钢参数表!W8*1000) -> 0 | AV8: =SUM(AB8:AU8) -> 5.6967454 | AW8: {=SUMPRODUCT($AB$4:$AU$4,AB8:AU8)/1000} -> 51.079642 | AY8: =F8 -> Q235B-2 | AZ8: =VLOOKUP(AY8,炼钢参数表!$F$5:$J$1027,4,0) -> 0.074405858 | BA8: =I8-AZ8 -> 0.085594142 | BB8: =AB8*$BB$4*炼钢参数表!$X$5/1000 -> 0.006191241 | BC8: =AC8*$BC$4*炼钢参数表!$X$5/1000 -> 0 | BD8: =AD8*$BD$4*炼钢参数表!$X$5/1000 -> 0 | BE8: =AE8*$BE$4*炼钢参数表!$X$5/1000 -> 0 | BF8: =AL8*$BF$4*炼钢参数表!$X$5/1000 -> 0 | BG8: =AM8*$BG$4*炼钢参数表!$X$5/1000 -> 0 | BH8: =SUM(BB8:BG8) -> 0.006191241 | BI8: =AZ8+BH8 -> 0.080597099 | BJ8: =BI8-I8 -> -0.079402901
A9: 5 | B9: Q235C | C9: 01 | D9: 1.6 | E9: 12 | F9: Q235C-1 | G9: A 碳素钢-碳素结构钢-A02 Q235C | H9: 1519 | I9: 0.15 | J9: 0.1 | K9: 0.35 | L9: 0.015 | M9: 0.01 | Q9: 0.025 | AB9: =IF(J9<=0.04,0,IF((BA9-AL9*BF$4*炼钢参数表!$X$5/1000-AM9*BG$4*炼钢参数表!$X$5/1000)<=0.03,0,IF((J9/100/0.1769/炼钢参数表!K9*1000)>(K9-炼钢参数表!J9)/100/0.6566/炼钢参数表!L9*1000,IF(K9<1.6,(K9-炼钢参数表!J9)/100/0.6566/炼钢参数表!L9*1000,(K9-0.08-炼钢参数表!J9)/100/0.6566/炼钢参数表!L9*1000),IF(K9<1.6,J9/100/0.1769/炼钢参数表!K9*1000,(J9-0.08)/100/0.1769/炼钢参数表!K9*1000)))) -> 3.5884765 | AC9: =IF((BA9-AB9*$BB$4*0.9/1000-AL9*BF$4*炼钢参数表!$X$5/1000-AM9*BG$4*炼钢参数表!$X$5/1000)<(K9-炼钢参数表!J9-AB9*0.6566*炼钢参数表!L9/10)*0.082,0,(K9-炼钢参数表!J9-AB9*0.6566*炼钢参数表!L9/10)/100/($AC$3/100)/炼钢参数表!L9*1000) -> 0 | AD9: =IF((BA9-AB9*$BB$4*0.9/1000-AC9*$BC$4*0.9/1000-AL9*BF$4*炼钢参数表!$X$5/1000-AM9*BG$4*炼钢参数表!$X$5/1000)<=(K9-炼钢参数表!J9-AB9*0.6566*炼钢参数表!L9/10-AC9*($AC$3/100)*炼钢参数表!L9/10)*0.02,0,((K9-炼钢参数表!J9-AB9*0.6566*炼钢参数表!L9/10-AC9*($AC$3/100)*炼钢参数表!L9/10)/100/($AD$3/100)/炼钢参数表!L9*1000)) -> 0 | AE9: =(K9-炼钢参数表!J9-AB9*0.6566*炼钢参数表!L9/10-AC9*($AC$3/100)*炼钢参数表!L9/10-AD9*($AD$3/100)*炼钢参数表!L9/10)/100/($AE$3/100)/炼钢参数表!L9*1000 -> 0 | AF9: 0 | AG9: =IF(J9<=0.04,0,((J9-(AB9*0.1769*炼钢参数表!K9/1000*100))/100/炼钢参数表!K9/($AG$3/100)*1000)) -> 0.8517216 | AH9: 1.33 | AI9: =IF(N9="",0,IF(N9<=0.002,0,((N9)/100)/($AI$3/100)/炼钢参数表!M9*1000)) -> 0 | AJ9: =IF(O9="",0,IF(O9<=0.002,0,((O9)/100)/($AJ$3/100)/炼钢参数表!N9*1000)) -> 0 | AK9: =IF(P9="",0,IF(P9<=0.002,0,((P9+0.005)/100)/($AK$3/100)/炼钢参数表!O9*1000)) -> 0 | AL9: =IF((BA9-J9*0.00003-K9*0.00024)<=0.05,0,IF(T9="",0,IF(T9<=0.03,0,IF(((BA9-J9*0.00003-K9*0.00024)-0.05)/0.18/100/($AL$3/100)/炼钢参数表!P9*1000<=T9/100/($AL$3/100)/炼钢参数表!P9*1000,((BA9-J9*0.00003-K9*0.00024)-0.05)/0.18/100/($AL$3/100)/炼钢参数表!P9*1000,T9/100/($AL$3/100)/炼钢参数表!P9*1000)))) -> 0 | AM9: =IF(T9="",0,IF(T9<=0.03,0,((T9-AL9*($AL$3/100)*炼钢参数表!P9/10)/100/($AM$3/100)/炼钢参数表!P9*1000))) -> 0 | AN9: =IF(U9="",0,IF(U9<=0.02,0,(U9/100)/($AN$3/100)/炼钢参数表!Q9*1000)) -> 0 | AO9: =IF(V9="",0,IF(V9<=0.02,0,(V9/100)/($AO$3/100)/炼钢参数表!R9*1000)) -> 0 | AP9: =IF(W9="",0,IF(W9<=0.02,0,(W9/100)/($AP$3/100)/炼钢参数表!S9*1000)) -> 0 | AQ9: =IF(X9="",0,IF(X9<=0.0002,0,(X9/100)/($AQ$3/100)/炼钢参数表!T9*1000)) -> 0 | AR9: =IF(Y9="",0,IF(Y9<=0.02,0,(Y9/100)/($AR$3/100)/炼钢参数表!U9*1000)) -> 0 | AS9: =IF(L9<=0.04,0,((L9-0.04)/100)/($AS$3/100)/炼钢参数表!V9*1000) -> 0 | AT9: =IF(M9<=0.03,0,((M9-0.03)/100)/($AT$3/100)/炼钢参数表!W9*1000) -> 0 | AV9: =SUM(AB9:AU9) -> 5.7701981 | AW9: {=SUMPRODUCT($AB$4:$AU$4,AB9:AU9)/1000} -> 53.592017 | AY9: =F9 -> Q235C-1 | AZ9: =VLOOKUP(AY9,炼钢参数表!$F$5:$J$1027,4,0) -> 0.068953488 | BA9: =I9-AZ9 -> 0.081046512 | BB9: =AB9*$BB$4*炼钢参数表!$X$5/1000 -> 0.0055549616 | BC9: =AC9*$BC$4*炼钢参数表!$X$5/1000 -> 0 | BD9: =AD9*$BD$4*炼钢参数表!$X$5/1000 -> 0 | BE9: =AE9*$BE$4*炼钢参数表!$X$5/1000 -> 0 | BF9: =AL9*$BF$4*炼钢参数表!$X$5/1000 -> 0 | BG9: =AM9*$BG$4*炼钢参数表!$X$5/1000 -> 0 | BH9: =SUM(BB9:BG9) -> 0.0055549616 | BI9: =AZ9+BH9 -> 0.07450845 | BJ9: =BI9-I9 -> -0.07549155
A10: 6 | B10: Q235C | C10: 02 | D10: 12.01 | E10: 25.4 | F10: Q235C-2 | G10: A 碳素钢-碳素结构钢-A02 Q235C | H10: 1519 | I10: 0.15 | J10: 0.1 | K10: 0.5 | L10: 0.015 | M10: 0.01 | Q10: 0.025 | AB10: =IF(J10<=0.04,0,IF((BA10-AL10*BF$4*炼钢参数表!$X$5/1000-AM10*BG$4*炼钢参数表!$X$5/1000)<=0.03,0,IF((J10/100/0.1769/炼钢参数表!K10*1000)>(K10-炼钢参数表!J10)/100/0.6566/炼钢参数表!L10*1000,IF(K10<1.6,(K10-炼钢参数表!J10)/100/0.6566/炼钢参数表!L10*1000,(K10-0.08-炼钢参数表!J10)/100/0.6566/炼钢参数表!L10*1000),IF(K10<1.6,J10/100/0.1769/炼钢参数表!K10*1000,(J10-0.08)/100/0.1769/炼钢参数表!K10*1000)))) -> 5.7671866 | AC10: =IF((BA10-AB10*$BB$4*0.9/1000-AL10*BF$4*炼钢参数表!$X$5/1000-AM10*BG$4*炼钢参数表!$X$5/1000)<(K10-炼钢参数表!J10-AB10*0.6566*炼钢参数表!L10/10)*0.082,0,(K10-炼钢参数表!J10-AB10*0.6566*炼钢参数表!L10/10)/100/($AC$3/100)/炼钢参数表!L10*1000) -> 0 | AD10: =IF((BA10-AB10*$BB$4*0.9/1000-AC10*$BC$4*0.9/1000-AL10*BF$4*炼钢参数表!$X$5/1000-AM10*BG$4*炼钢参数表!$X$5/1000)<=(K10-炼钢参数表!J10-AB10*0.6566*炼钢参数表!L10/10-AC10*($AC$3/100)*炼钢参数表!L10/10)*0.02,0,((K10-炼钢参数表!J10-AB10*0.6566*炼钢参数表!L10/10-AC10*($AC$3/100)*炼钢参数表!L10/10)/100/($AD$3/100)/炼钢参数表!L10*1000)) -> 0 | AE10: =(K10-炼钢参数表!J10-AB10*0.6566*炼钢参数表!L10/10-AC10*($AC$3/100)*炼钢参数表!L10/10-AD10*($AD$3/100)*炼钢参数表!L10/10)/100/($AE$3/100)/炼钢参数表!L10*1000 -> 0 | AF10: 0 | AG10: =IF(J10<=0.04,0,((J10-(AB10*0.1769*炼钢参数表!K10/1000*100))/100/炼钢参数表!K10/($AG$3/100)*1000)) -> 0.31812917 | AH10: 1.33 | AI10: =IF(N10="",0,IF(N10<=0.002,0,((N10)/100)/($AI$3/100)/炼钢参数表!M10*1000)) -> 0 | AJ10: =IF(O10="",0,IF(O10<=0.002,0,((O10)/100)/($AJ$3/100)/炼钢参数表!N10*1000)) -> 0 | AK10: =IF(P10="",0,IF(P10<=0.002,0,((P10+0.005)/100)/($AK$3/100)/炼钢参数表!O10*1000)) -> 0 | AL10: =IF((BA10-J10*0.00003-K10*0.00024)<=0.05,0,IF(T10="",0,IF(T10<=0.03,0,IF(((BA10-J10*0.00003-K10*0.00024)-0.05)/0.18/100/($AL$3/100)/炼钢参数表!P10*1000<=T10/100/($AL$3/100)/炼钢参数表!P10*1000,((BA10-J10*0.00003-K10*0.00024)-0.05)/0.18/100/($AL$3/100)/炼钢参数表!P10*1000,T10/100/($AL$3/100)/炼钢参数表!P10*1000)))) -> 0 | AM10: =IF(T10="",0,IF(T10<=0.03,0,((T10-AL10*($AL$3/100)*炼钢参数表!P10/10)/100/($AM$3/100)/炼钢参数表!P10*1000))) -> 0 | AN10: =IF(U10="",0,IF(U10<=0.02,0,(U10/100)/($AN$3/100)/炼钢参数表!Q10*1000)) -> 0 | AO10: =IF(V10="",0,IF(V10<=0.02,0,(V10/100)/($AO$3/100)/炼钢参数表!R10*1000)) -> 0 | AP10: =IF(W10="",0,IF(W10<=0.02,0,(W10/100)/($AP$3/100)/炼钢参数表!S10*1000)) -> 0 | AQ10: =IF(X10="",0,IF(X10<=0.0002,0,(X10/100)/($AQ$3/100)/炼钢参数表!T10*1000)) -> 0 | AR10: =IF(Y10="",0,IF(Y10<=0.02,0,(Y10/100)/($AR$3/100)/炼钢参数表!U10*1000)) -> 0 | AS10: =IF(L10<=0.04,0,((L10-0.04)/100)/($AS$3/100)/炼钢参数表!V10*1000) -> 0 | AT10: =IF(M10<=0.03,0,((M10-0.03)/100)/($AT$3/100)/炼钢参数表!W10*1000) -> 0 | AV10: =SUM(AB10:AU10) -> 7.4153157 | AW10: {=SUMPRODUCT($AB$4:$AU$4,AB10:AU10)/1000} -> 62.643912 | AY10: =F10 -> Q235C-2 | AZ10: =VLOOKUP(AY10,炼钢参数表!$F$5:$J$1027,4,0) -> 0.0625 | BA10: =I10-AZ10 -> 0.0875 | BB10: =AB10*$BB$4*炼钢参数表!$X$5/1000 -> 0.0089276048 | BC10: =AC10*$BC$4*炼钢参数表!$X$5/1000 -> 0 | BD10: =AD10*$BD$4*炼钢参数表!$X$5/1000 -> 0 | BE10: =AE10*$BE$4*炼钢参数表!$X$5/1000 -> 0 | BF10: =AL10*$BF$4*炼钢参数表!$X$5/1000 -> 0 | BG10: =AM10*$BG$4*炼钢参数表!$X$5/1000 -> 0 | BH10: =SUM(BB10:BG10) -> 0.0089276048 | BI10: =AZ10+BH10 -> 0.071427605 | BJ10: =BI10-I10 -> -0.078572395
A11: 7 | B11: Q235B-WJ | C11: 01 | D11: 1.45 | E11: 12 | F11: Q235B-1 | G11: A 碳素钢-碳素结构钢-A01 Q235B | H11: 1519 | I11: 0.16 | J11: 0.08 | K11: 0.23 | L11: 0.025 | M11: 0.02 | Q11: 0.01 | AB11: =IF(J11<=0.04,0,IF((BA11-AL11*BF$4*炼钢参数表!$X$5/1000-AM11*BG$4*炼钢参数表!$X$5/1000)<=0.03,0,IF((J11/100/0.1769/炼钢参数表!K11*1000)>(K11-炼钢参数表!J11)/100/0.6566/炼钢参数表!L11*1000,IF(K11<1.6,(K11-炼钢参数表!J11)/100/0.6566/炼钢参数表!L11*1000,(K11-0.08-炼钢参数表!J11)/100/0.6566/炼钢参数表!L11*1000),IF(K11<1.6,J11/100/0.1769/炼钢参数表!K11*1000,(J11-0.08)/100/0.1769/炼钢参数表!K11*1000)))) -> 1.6738627 | AC11: =IF((BA11-AB11*$BB$4*0.9/1000-AL11*BF$4*炼钢参数表!$X$5/1000-AM11*BG$4*炼钢参数表!$X$5/1000)<(K11-炼钢参数表!J11-AB11*0.6566*炼钢参数表!L11/10)*0.082,0,(K11-炼钢参数表!J11-AB11*0.6566*炼钢参数表!L11/10)/100/($AC$3/100)/炼钢参数表!L11*1000) -> 0 | AD11: =IF((BA11-AB11*$BB$4*0.9/1000-AC11*$BC$4*0.9/1000-AL11*BF$4*炼钢参数表!$X$5/1000-AM11*BG$4*炼钢参数表!$X$5/1000)<=(K11-炼钢参数表!J11-AB11*0.6566*炼钢参数表!L11/10-AC11*($AC$3/100)*炼钢参数表!L11/10)*0.02,0,((K11-炼钢参数表!J11-AB11*0.6566*炼钢参数表!L11/10-AC11*($AC$3/100)*炼钢参数表!L11/10)/100/($AD$3/100)/炼钢参数表!L11*1000)) -> 0 | AE11: =(K11-炼钢参数表!J11-AB11*0.6566*炼钢参数表!L11/10-AC11*($AC$3/100)*炼钢参数表!L11/10-AD11*($AD$3/100)*炼钢参数表!L11/10)/100/($AE$3/100)/炼钢参数表!L11*1000 -> 0 | AF11: 0 | AG11: =IF(J11<=0.04,0,((J11-(AB11*0.1769*炼钢参数表!K11/1000*100))/100/炼钢参数表!K11/($AG$3/100)*1000)) -> 1.0668148 | AH11: 1.2022258 | AI11: =IF(N11="",0,IF(N11<=0.002,0,((N11)/100)/($AI$3/100)/炼钢参数表!M11*1000)) -> 0 | AJ11: =IF(O11="",0,IF(O11<=0.002,0,((O11)/100)/($AJ$3/100)/炼钢参数表!N11*1000)) -> 0 | AK11: =IF(P11="",0,IF(P11<=0.002,0,((P11+0.005)/100)/($AK$3/100)/炼钢参数表!O11*1000)) -> 0 | AL11: =IF((BA11-J11*0.00003-K11*0.00024)<=0.05,0,IF(T11="",0,IF(T11<=0.03,0,IF(((BA11-J11*0.00003-K11*0.00024)-0.05)/0.18/100/($AL$3/100)/炼钢参数表!P11*1000<=T11/100/($AL$3/100)/炼钢参数表!P11*1000,((BA11-J11*0.00003-K11*0.00024)-0.05)/0.18/100/($AL$3/100)/炼钢参数表!P11*1000,T11/100/($AL$3/100)/炼钢参数表!P11*1000)))) -> 0 | AM11: =IF(T11="",0,IF(T11<=0.03,0,((T11-AL11*($AL$3/100)*炼钢参数表!P11/10)/100/($AM$3/100)/炼钢参数表!P11*1000))) -> 0 | AN11: =IF(U11="",0,IF(U11<=0.02,0,(U11/100)/($AN$3/100)/炼钢参数表!Q11*1000)) -> 0 | AO11: =IF(V11="",0,IF(V11<=0.02,0,(V11/100)/($AO$3/100)/炼钢参数表!R11*1000)) -> 0 | AP11: =IF(W11="",0,IF(W11<=0.02,0,(W11/100)/($AP$3/100)/炼钢参数表!S11*1000)) -> 0 | AQ11: =IF(X11="",0,IF(X11<=0.0002,0,(X11/100)/($AQ$3/100)/炼钢参数表!T11*1000)) -> 0 | AR11: =IF(Y11="",0,IF(Y11<=0.02,0,(Y11/100)/($AR$3/100)/炼钢参数表!U11*1000)) -> 0 | AS11: =IF(L11<=0.04,0,((L11-0.04)/100)/($AS$3/100)/炼钢参数表!V11*1000) -> 0 | AT11: =IF(M11<=0.03,0,((M11-0.03)/100)/($AT$3/100)/炼钢参数表!W11*1000) -> 0 | AV11: =SUM(AB11:AU11) -> 3.9429033 | AW11: {=SUMPRODUCT($AB$4:$AU$4,AB11:AU11)/1000} -> 41.466986 | AY11: =F11 -> Q235B-1 | AZ11: =VLOOKUP(AY11,炼钢参数表!$F$5:$J$1027,4,0) -> 0.07293667 | BA11: =I11-AZ11 -> 0.08706333 | BB11: =AB11*$BB$4*炼钢参数表!$X$5/1000 -> 0.0025911394 | BC11: =AC11*$BC$4*炼钢参数表!$X$5/1000 -> 0 | BD11: =AD11*$BD$4*炼钢参数表!$X$5/1000 -> 0 | BE11: =AE11*$BE$4*炼钢参数表!$X$5/1000 -> 0 | BF11: =AL11*$BF$4*炼钢参数表!$X$5/1000 -> 0 | BG11: =AM11*$BG$4*炼钢参数表!$X$5/1000 -> 0 | BH11: =SUM(BB11:BG11) -> 0.0025911394 | BI11: =AZ11+BH11 -> 0.075527809 | BJ11: =BI11-I11 -> -0.084472191
A12: 8 | B12: Q235B-WJ | C12: 02 | D12: 12.01 | E12: 28 | F12: Q235B-2 | G12: A 碳素钢-碳素结构钢-A01 Q235B | H12: 1519 | I12: 0.16 | J12: 0.08 | K12: 0.38 | L12: 0.025 | M12: 0.02 | Q12: 0.01 | AB12: =IF(J12<=0.04,0,IF((BA12-AL12*BF$4*炼钢参数表!$X$5/1000-AM12*BG$4*炼钢参数表!$X$5/1000)<=0.03,0,IF((J12/100/0.1769/炼钢参数表!K12*1000)>(K12-炼钢参数表!J12)/100/0.6566/炼钢参数表!L12*1000,IF(K12<1.6,(K12-炼钢参数表!J12)/100/0.6566/炼钢参数表!L12*1000,(K12-0.08-炼钢参数表!J12)/100/0.6566/炼钢参数表!L12*1000),IF(K12<1.6,J12/100/0.1769/炼钢参数表!K12*1000,(J12-0.08)/100/0.1769/炼钢参数表!K12*1000)))) -> 3.9995097 | AC12: =IF((BA12-AB12*$BB$4*0.9/1000-AL12*BF$4*炼钢参数表!$X$5/1000-AM12*BG$4*炼钢参数表!$X$5/1000)<(K12-炼钢参数表!J12-AB12*0.6566*炼钢参数表!L12/10)*0.082,0,(K12-炼钢参数表!J12-AB12*0.6566*炼钢参数表!L12/10)/100/($AC$3/100)/炼钢参数表!L12*1000) -> 0 | AD12: =IF((BA12-AB12*$BB$4*0.9/1000-AC12*$BC$4*0.9/1000-AL12*BF$4*炼钢参数表!$X$5/1000-AM12*BG$4*炼钢参数表!$X$5/1000)<=(K12-炼钢参数表!J12-AB12*0.6566*炼钢参数表!L12/10-AC12*($AC$3/100)*炼钢参数表!L12/10)*0.02,0,((K12-炼钢参数表!J12-AB12*0.6566*炼钢参数表!L12/10-AC12*($AC$3/100)*炼钢参数表!L12/10)/100/($AD$3/100)/炼钢参数表!L12*1000)) -> 0 | AE12: =(K12-炼钢参数表!J12-AB12*0.6566*炼钢参数表!L12/10-AC12*($AC$3/100)*炼钢参数表!L12/10-AD12*($AD$3/100)*炼钢参数表!L12/10)/100/($AE$3/100)/炼钢参数表!L12*1000 -> 0 | AF12: 0 | AG12: =IF(J12<=0.04,0,((J12-(AB12*0.1769*炼钢参数表!K12/1000*100))/100/炼钢参数表!K12/($AG$3/100)*1000)) -> 0.49723578 | AH12: 1.2 | AI12: =IF(N12="",0,IF(N12<=0.002,0,((N12)/100)/($AI$3/100)/炼钢参数表!M12*1000)) -> 0 | AJ12: =IF(O12="",0,IF(O12<=0.002,0,((O12)/100)/($AJ$3/100)/炼钢参数表!N12*1000)) -> 0 | AK12: =IF(P12="",0,IF(P12<=0.002,0,((P12+0.005)/100)/($AK$3/100)/炼钢参数表!O12*1000)) -> 0 | AL12: =IF((BA12-J12*0.00003-K12*0.00024)<=0.05,0,IF(T12="",0,IF(T12<=0.03,0,IF(((BA12-J12*0.00003-K12*0.00024)-0.05)/0.18/100/($AL$3/100)/炼钢参数表!P12*1000<=T12/100/($AL$3/100)/炼钢参数表!P12*1000,((BA12-J12*0.00003-K12*0.00024)-0.05)/0.18/100/($AL$3/100)/炼钢参数表!P12*1000,T12/100/($AL$3/100)/炼钢参数表!P12*1000)))) -> 0 | AM12: =IF(T12="",0,IF(T12<=0.03,0,((T12-AL12*($AL$3/100)*炼钢参数表!P12/10)/100/($AM$3/100)/炼钢参数表!P12*1000))) -> 0 | AN12: =IF(U12="",0,IF(U12<=0.02,0,(U12/100)/($AN$3/100)/炼钢参数表!Q12*1000)) -> 0 | AO12: =IF(V12="",0,IF(V12<=0.02,0,(V12/100)/($AO$3/100)/炼钢参数表!R12*1000)) -> 0 | AP12: =IF(W12="",0,IF(W12<=0.02,0,(W12/100)/($AP$3/100)/炼钢参数表!S12*1000)) -> 0 | AQ12: =IF(X12="",0,IF(X12<=0.0002,0,(X12/100)/($AQ$3/100)/炼钢参数表!T12*1000)) -> 0 | AR12: =IF(Y12="",0,IF(Y12<=0.02,0,(Y12/100)/($AR$3/100)/炼钢参数表!U12*1000)) -> 0 | AS12: =IF(L12<=0.04,0,((L12-0.04)/100)/($AS$3/100)/炼钢参数表!V12*1000) -> 0 | AT12: =IF(M12<=0.03,0,((M12-0.03)/100)/($AT$3/100)/炼钢参数表!W12*1000) -> 0 | AV12: =SUM(AB12:AU12) -> 5.6967454 | AW12: {=SUMPRODUCT($AB$4:$AU$4,AB12:AU12)/1000} -> 51.079642 | AY12: =F12 -> Q235B-2 | AZ12: =VLOOKUP(AY12,炼钢参数表!$F$5:$J$1027,4,0) -> 0.074405858 | BA12: =I12-AZ12 -> 0.085594142 | BB12: =AB12*$BB$4*炼钢参数表!$X$5/1000 -> 0.006191241 | BC12: =AC12*$BC$4*炼钢参数表!$X$5/1000 -> 0 | BD12: =AD12*$BD$4*炼钢参数表!$X$5/1000 -> 0 | BE12: =AE12*$BE$4*炼钢参数表!$X$5/1000 -> 0 | BF12: =AL12*$BF$4*炼钢参数表!$X$5/1000 -> 0 | BG12: =AM12*$BG$4*炼钢参数表!$X$5/1000 -> 0 | BH12: =SUM(BB12:BG12) -> 0.006191241 | BI12: =AZ12+BH12 -> 0.080597099 | BJ12: =BI12-I12 -> -0.079402901
A13: 9 | B13: Q235B-LX | C13: 01 | D13: 1.45 | E13: 12 | F13: Q235B-1 | G13: A 碳素钢-碳素结构钢-A01 Q235B | H13: 1519 | I13: 0.16 | J13: 0.08 | K13: 0.23 | L13: 0.025 | M13: 0.02 | Q13: 0.01 | AB13: =IF(J13<=0.04,0,IF((BA13-AL13*BF$4*炼钢参数表!$X$5/1000-AM13*BG$4*炼钢参数表!$X$5/1000)<=0.03,0,IF((J13/100/0.1769/炼钢参数表!K13*1000)>(K13-炼钢参数表!J13)/100/0.6566/炼钢参数表!L13*1000,IF(K13<1.6,(K13-炼钢参数表!J13)/100/0.6566/炼钢参数表!L13*1000,(K13-0.08-炼钢参数表!J13)/100/0.6566/炼钢参数表!L13*1000),IF(K13<1.6,J13/100/0.1769/炼钢参数表!K13*1000,(J13-0.08)/100/0.1769/炼钢参数表!K13*1000)))) -> 1.6738627 | AC13: =IF((BA13-AB13*$BB$4*0.9/1000-AL13*BF$4*炼钢参数表!$X$5/1000-AM13*BG$4*炼钢参数表!$X$5/1000)<(K13-炼钢参数表!J13-AB13*0.6566*炼钢参数表!L13/10)*0.082,0,(K13-炼钢参数表!J13-AB13*0.6566*炼钢参数表!L13/10)/100/($AC$3/100)/炼钢参数表!L13*1000) -> 0 | AD13: =IF((BA13-AB13*$BB$4*0.9/1000-AC13*$BC$4*0.9/1000-AL13*BF$4*炼钢参数表!$X$5/1000-AM13*BG$4*炼钢参数表!$X$5/1000)<=(K13-炼钢参数表!J13-AB13*0.6566*炼钢参数表!L13/10-AC13*($AC$3/100)*炼钢参数表!L13/10)*0.02,0,((K13-炼钢参数表!J13-AB13*0.6566*炼钢参数表!L13/10-AC13*($AC$3/100)*炼钢参数表!L13/10)/100/($AD$3/100)/炼钢参数表!L13*1000)) -> 0 | AE13: =(K13-炼钢参数表!J13-AB13*0.6566*炼钢参数表!L13/10-AC13*($AC$3/100)*炼钢参数表!L13/10-AD13*($AD$3/100)*炼钢参数表!L13/10)/100/($AE$3/100)/炼钢参数表!L13*1000 -> 0 | AF13: 0 | AG13: =IF(J13<=0.04,0,((J13-(AB13*0.1769*炼钢参数表!K13/1000*100))/100/炼钢参数表!K13/($AG$3/100)*1000)) -> 1.0668148 | AH13: 1.2022258 | AI13: =IF(N13="",0,IF(N13<=0.002,0,((N13)/100)/($AI$3/100)/炼钢参数表!M13*1000)) -> 0 | AJ13: =IF(O13="",0,IF(O13<=0.002,0,((O13)/100)/($AJ$3/100)/炼钢参数表!N13*1000)) -> 0 | AK13: =IF(P13="",0,IF(P13<=0.002,0,((P13+0.005)/100)/($AK$3/100)/炼钢参数表!O13*1000)) -> 0 | AL13: =IF((BA13-J13*0.00003-K13*0.00024)<=0.05,0,IF(T13="",0,IF(T13<=0.03,0,IF(((BA13-J13*0.00003-K13*0.00024)-0.05)/0.18/100/($AL$3/100)/炼钢参数表!P13*1000<=T13/100/($AL$3/100)/炼钢参数表!P13*1000,((BA13-J13*0.00003-K13*0.00024)-0.05)/0.18/100/($AL$3/100)/炼钢参数表!P13*1000,T13/100/($AL$3/100)/炼钢参数表!P13*1000)))) -> 0 | AM13: =IF(T13="",0,IF(T13<=0.03,0,((T13-AL13*($AL$3/100)*炼钢参数表!P13/10)/100/($AM$3/100)/炼钢参数表!P13*1000))) -> 0 | AN13: =IF(U13="",0,IF(U13<=0.02,0,(U13/100)/($AN$3/100)/炼钢参数表!Q13*1000)) -> 0 | AO13: =IF(V13="",0,IF(V13<=0.02,0,(V13/100)/($AO$3/100)/炼钢参数表!R13*1000)) -> 0 | AP13: =IF(W13="",0,IF(W13<=0.02,0,(W13/100)/($AP$3/100)/炼钢参数表!S13*1000)) -> 0 | AQ13: =IF(X13="",0,IF(X13<=0.0002,0,(X13/100)/($AQ$3/100)/炼钢参数表!T13*1000)) -> 0 | AR13: =IF(Y13="",0,IF(Y13<=0.02,0,(Y13/100)/($AR$3/100)/炼钢参数表!U13*1000)) -> 0 | AS13: =IF(L13<=0.04,0,((L13-0.04)/100)/($AS$3/100)/炼钢参数表!V13*1000) -> 0 | AT13: =IF(M13<=0.03,0,((M13-0.03)/100)/($AT$3/100)/炼钢参数表!W13*1000) -> 0 | AV13: =SUM(AB13:AU13) -> 3.9429033 | AW13: {=SUMPRODUCT($AB$4:$AU$4,AB13:AU13)/1000} -> 41.466986 | AY13: =F13 -> Q235B-1 | AZ13: =VLOOKUP(AY13,炼钢参数表!$F$5:$J$1027,4,0) -> 0.07293667 | BA13: =I13-AZ13 -> 0.08706333 | BB13: =AB13*$BB$4*炼钢参数表!$X$5/1000 -> 0.0025911394 | BC13: =AC13*$BC$4*炼钢参数表!$X$5/1000 -> 0 | BD13: =AD13*$BD$4*炼钢参数表!$X$5/1000 -> 0 | BE13: =AE13*$BE$4*炼钢参数表!$X$5/1000 -> 0 | BF13: =AL13*$BF$4*炼钢参数表!$X$5/1000 -> 0 | BG13: =AM13*$BG$4*炼钢参数表!$X$5/1000 -> 0 | BH13: =SUM(BB13:BG13) -> 0.0025911394 | BI13: =AZ13+BH13 -> 0.075527809 | BJ13: =BI13-I13 -> -0.084472191
A14: 10 | B14: Q235B-LX | C14: 02 | D14: 12.01 | E14: 28 | F14: Q235B-2 | G14: A 碳素钢-碳素结构钢-A01 Q235B | H14: 1519 | I14: 0.16 | J14: 0.08 | K14: 0.38 | L14: 0.025 | M14: 0.02 | Q14: 0.01 | AB14: =IF(J14<=0.04,0,IF((BA14-AL14*BF$4*炼钢参数表!$X$5/1000-AM14*BG$4*炼钢参数表!$X$5/1000)<=0.03,0,IF((J14/100/0.1769/炼钢参数表!K14*1000)>(K14-炼钢参数表!J14)/100/0.6566/炼钢参数表!L14*1000,IF(K14<1.6,(K14-炼钢参数表!J14)/100/0.6566/炼钢参数表!L14*1000,(K14-0.08-炼钢参数表!J14)/100/0.6566/炼钢参数表!L14*1000),IF(K14<1.6,J14/100/0.1769/炼钢参数表!K14*1000,(J14-0.08)/100/0.1769/炼钢参数表!K14*1000)))) -> 3.9995097 | AC14: =IF((BA14-AB14*$BB$4*0.9/1000-AL14*BF$4*炼钢参数表!$X$5/1000-AM14*BG$4*炼钢参数表!$X$5/1000)<(K14-炼钢参数表!J14-AB14*0.6566*炼钢参数表!L14/10)*0.082,0,(K14-炼钢参数表!J14-AB14*0.6566*炼钢参数表!L14/10)/100/($AC$3/100)/炼钢参数表!L14*1000) -> 0 | AD14: =IF((BA14-AB14*$BB$4*0.9/1000-AC14*$BC$4*0.9/1000-AL14*BF$4*炼钢参数表!$X$5/1000-AM14*BG$4*炼钢参数表!$X$5/1000)<=(K14-炼钢参数表!J14-AB14*0.6566*炼钢参数表!L14/10-AC14*($AC$3/100)*炼钢参数表!L14/10)*0.02,0,((K14-炼钢参数表!J14-AB14*0.6566*炼钢参数表!L14/10-AC14*($AC$3/100)*炼钢参数表!L14/10)/100/($AD$3/100)/炼钢参数表!L14*1000)) -> 0 | AE14: =(K14-炼钢参数表!J14-AB14*0.6566*炼钢参数表!L14/10-AC14*($AC$3/100)*炼钢参数表!L14/10-AD14*($AD$3/100)*炼钢参数表!L14/10)/100/($AE$3/100)/炼钢参数表!L14*1000 -> 0 | AF14: 0 | AG14: =IF(J14<=0.04,0,((J14-(AB14*0.1769*炼钢参数表!K14/1000*100))/100/炼钢参数表!K14/($AG$3/100)*1000)) -> 0.49723578 | AH14: 1.2 | AI14: =IF(N14="",0,IF(N14<=0.002,0,((N14)/100)/($AI$3/100)/炼钢参数表!M14*1000)) -> 0 | AJ14: =IF(O14="",0,IF(O14<=0.002,0,((O14)/100)/($AJ$3/100)/炼钢参数表!N14*1000)) -> 0 | AK14: =IF(P14="",0,IF(P14<=0.002,0,((P14+0.005)/100)/($AK$3/100)/炼钢参数表!O14*1000)) -> 0 | AL14: =IF((BA14-J14*0.00003-K14*0.00024)<=0.05,0,IF(T14="",0,IF(T14<=0.03,0,IF(((BA14-J14*0.00003-K14*0.00024)-0.05)/0.18/100/($AL$3/100)/炼钢参数表!P14*1000<=T14/100/($AL$3/100)/炼钢参数表!P14*1000,((BA14-J14*0.00003-K14*0.00024)-0.05)/0.18/100/($AL$3/100)/炼钢参数表!P14*1000,T14/100/($AL$3/100)/炼钢参数表!P14*1000)))) -> 0 | AM14: =IF(T14="",0,IF(T14<=0.03,0,((T14-AL14*($AL$3/100)*炼钢参数表!P14/10)/100/($AM$3/100)/炼钢参数表!P14*1000))) -> 0 | AN14: =IF(U14="",0,IF(U14<=0.02,0,(U14/100)/($AN$3/100)/炼钢参数表!Q14*1000)) -> 0 | AO14: =IF(V14="",0,IF(V14<=0.02,0,(V14/100)/($AO$3/100)/炼钢参数表!R14*1000)) -> 0 | AP14: =IF(W14="",0,IF(W14<=0.02,0,(W14/100)/($AP$3/100)/炼钢参数表!S14*1000)) -> 0 | AQ14: =IF(X14="",0,IF(X14<=0.0002,0,(X14/100)/($AQ$3/100)/炼钢参数表!T14*1000)) -> 0 | AR14: =IF(Y14="",0,IF(Y14<=0.02,0,(Y14/100)/($AR$3/100)/炼钢参数表!U14*1000)) -> 0 | AS14: =IF(L14<=0.04,0,((L14-0.04)/100)/($AS$3/100)/炼钢参数表!V14*1000) -> 0 | AT14: =IF(M14<=0.03,0,((M14-0.03)/100)/($AT$3/100)/炼钢参数表!W14*1000) -> 0 | AV14: =SUM(AB14:AU14) -> 5.6967454 | AW14: {=SUMPRODUCT($AB$4:$AU$4,AB14:AU14)/1000} -> 51.079642 | AY14: =F14 -> Q235B-2 | AZ14: =VLOOKUP(AY14,炼钢参数表!$F$5:$J$1027,4,0) -> 0.074405858 | BA14: =I14-AZ14 -> 0.085594142 | BB14: =AB14*$BB$4*炼钢参数表!$X$5/1000 -> 0.006191241 | BC14: =AC14*$BC$4*炼钢参数表!$X$5/1000 -> 0 | BD14: =AD14*$BD$4*炼钢参数表!$X$5/1000 -> 0 | BE14: =AE14*$BE$4*炼钢参数表!$X$5/1000 -> 0 | BF14: =AL14*$BF$4*炼钢参数表!$X$5/1000 -> 0 | BG14: =AM14*$BG$4*炼钢参数表!$X$5/1000 -> 0 | BH14: =SUM(BB14:BG14) -> 0.006191241 | BI14: =AZ14+BH14 -> 0.080597099 | BJ14: =BI14-I14 -> -0.079402901
A15: 11 | B15: Q235B-HX | C15: 01 | D15: 1.45 | E15: 12 | F15: Q235B-1 | G15: A 碳素钢-碳素结构钢-A01 Q235B | H15: 1519 | I15: 0.16 | J15: 0.08 | K15: 0.23 | L15: 0.025 | M15: 0.02 | Q15: 0.01 | AB15: =IF(J15<=0.04,0,IF((BA15-AL15*BF$4*炼钢参数表!$X$5/1000-AM15*BG$4*炼钢参数表!$X$5/1000)<=0.03,0,IF((J15/100/0.1769/炼钢参数表!K15*1000)>(K15-炼钢参数表!J15)/100/0.6566/炼钢参数表!L15*1000,IF(K15<1.6,(K15-炼钢参数表!J15)/100/0.6566/炼钢参数表!L15*1000,(K15-0.08-炼钢参数表!J15)/100/0.6566/炼钢参数表!L15*1000),IF(K15<1.6,J15/100/0.1769/炼钢参数表!K15*1000,(J15-0.08)/100/0.1769/炼钢参数表!K15*1000)))) -> 1.6738627 | AC15: =IF((BA15-AB15*$BB$4*0.9/1000-AL15*BF$4*炼钢参数表!$X$5/1000-AM15*BG$4*炼钢参数表!$X$5/1000)<(K15-炼钢参数表!J15-AB15*0.6566*炼钢参数表!L15/10)*0.082,0,(K15-炼钢参数表!J15-AB15*0.6566*炼钢参数表!L15/10)/100/($AC$3/100)/炼钢参数表!L15*1000) -> 0 | AD15: =IF((BA15-AB15*$BB$4*0.9/1000-AC15*$BC$4*0.9/1000-AL15*BF$4*炼钢参数表!$X$5/1000-AM15*BG$4*炼钢参数表!$X$5/1000)<=(K15-炼钢参数表!J15-AB15*0.6566*炼钢参数表!L15/10-AC15*($AC$3/100)*炼钢参数表!L15/10)*0.02,0,((K15-炼钢参数表!J15-AB15*0.6566*炼钢参数表!L15/10-AC15*($AC$3/100)*炼钢参数表!L15/10)/100/($AD$3/100)/炼钢参数表!L15*1000)) -> 0 | AE15: =(K15-炼钢参数表!J15-AB15*0.6566*炼钢参数表!L15/10-AC15*($AC$3/100)*炼钢参数表!L15/10-AD15*($AD$3/100)*炼钢参数表!L15/10)/100/($AE$3/100)/炼钢参数表!L15*1000 -> 0 | AF15: 0 | AG15: =IF(J15<=0.04,0,((J15-(AB15*0.1769*炼钢参数表!K15/1000*100))/100/炼钢参数表!K15/($AG$3/100)*1000)) -> 1.0668148 | AH15: 1.2022258 | AI15: =IF(N15="",0,IF(N15<=0.002,0,((N15)/100)/($AI$3/100)/炼钢参数表!M15*1000)) -> 0 | AJ15: =IF(O15="",0,IF(O15<=0.002,0,((O15)/100)/($AJ$3/100)/炼钢参数表!N15*1000)) -> 0 | AK15: =IF(P15="",0,IF(P15<=0.002,0,((P15+0.005)/100)/($AK$3/100)/炼钢参数表!O15*1000)) -> 0 | AL15: =IF((BA15-J15*0.00003-K15*0.00024)<=0.05,0,IF(T15="",0,IF(T15<=0.03,0,IF(((BA15-J15*0.00003-K15*0.00024)-0.05)/0.18/100/($AL$3/100)/炼钢参数表!P15*1000<=T15/100/($AL$3/100)/炼钢参数表!P15*1000,((BA15-J15*0.00003-K15*0.00024)-0.05)/0.18/100/($AL$3/100)/炼钢参数表!P15*1000,T15/100/($AL$3/100)/炼钢参数表!P15*1000)))) -> 0 | AM15: =IF(T15="",0,IF(T15<=0.03,0,((T15-AL15*($AL$3/100)*炼钢参数表!P15/10)/100/($AM$3/100)/炼钢参数表!P15*1000))) -> 0 | AN15: =IF(U15="",0,IF(U15<=0.02,0,(U15/100)/($AN$3/100)/炼钢参数表!Q15*1000)) -> 0 | AO15: =IF(V15="",0,IF(V15<=0.02,0,(V15/100)/($AO$3/100)/炼钢参数表!R15*1000)) -> 0 | AP15: =IF(W15="",0,IF(W15<=0.02,0,(W15/100)/($AP$3/100)/炼钢参数表!S15*1000)) -> 0 | AQ15: =IF(X15="",0,IF(X15<=0.0002,0,(X15/100)/($AQ$3/100)/炼钢参数表!T15*1000)) -> 0 | AR15: =IF(Y15="",0,IF(Y15<=0.02,0,(Y15/100)/($AR$3/100)/炼钢参数表!U15*1000)) -> 0 | AS15: =IF(L15<=0.04,0,((L15-0.04)/100)/($AS$3/100)/炼钢参数表!V15*1000) -> 0 | AT15: =IF(M15<=0.03,0,((M15-0.03)/100)/($AT$3/100)/炼钢参数表!W15*1000) -> 0 | AV15: =SUM(AB15:AU15) -> 3.9429033 | AW15: {=SUMPRODUCT($AB$4:$AU$4,AB15:AU15)/1000} -> 41.466986 | AY15: =F15 -> Q235B-1 | AZ15: =VLOOKUP(AY15,炼钢参数表!$F$5:$J$1027,4,0) -> 0.07293667 | BA15: =I15-AZ15 -> 0.08706333 | BB15: =AB15*$BB$4*炼钢参数表!$X$5/1000 -> 0.0025911394 | BC15: =AC15*$BC$4*炼钢参数表!$X$5/1000 -> 0 | BD15: =AD15*$BD$4*炼钢参数表!$X$5/1000 -> 0 | BE15: =AE15*$BE$4*炼钢参数表!$X$5/1000 -> 0 | BF15: =AL15*$BF$4*炼钢参数表!$X$5/1000 -> 0 | BG15: =AM15*$BG$4*炼钢参数表!$X$5/1000 -> 0 | BH15: =SUM(BB15:BG15) -> 0.0025911394 | BI15: =AZ15+BH15 -> 0.075527809 | BJ15: =BI15-I15 -> -0.084472191
A16: 12 | B16: Q235B-HX | C16: 02 | D16: 12.01 | E16: 28 | F16: Q235B-2 | G16: A 碳素钢-碳素结构钢-A01 Q235B | H16: 1519 | I16: 0.16 | J16: 0.08 | K16: 0.38 | L16: 0.025 | M16: 0.02 | Q16: 0.01 | AB16: =IF(J16<=0.04,0,IF((BA16-AL16*BF$4*炼钢参数表!$X$5/1000-AM16*BG$4*炼钢参数表!$X$5/1000)<=0.03,0,IF((J16/100/0.1769/炼钢参数表!K16*1000)>(K16-炼钢参数表!J16)/100/0.6566/炼钢参数表!L16*1000,IF(K16<1.6,(K16-炼钢参数表!J16)/100/0.6566/炼钢参数表!L16*1000,(K16-0.08-炼钢参数表!J16)/100/0.6566/炼钢参数表!L16*1000),IF(K16<1.6,J16/100/0.1769/炼钢参数表!K16*1000,(J16-0.08)/100/0.1769/炼钢参数表!K16*1000)))) -> 3.9995097 | AC16: =IF((BA16-AB16*$BB$4*0.9/1000-AL16*BF$4*炼钢参数表!$X$5/1000-AM16*BG$4*炼钢参数表!$X$5/1000)<(K16-炼钢参数表!J16-AB16*0.6566*炼钢参数表!L16/10)*0.082,0,(K16-炼钢参数表!J16-AB16*0.6566*炼钢参数表!L16/10)/100/($AC$3/100)/炼钢参数表!L16*1000) -> 0 | AD16: =IF((BA16-AB16*$BB$4*0.9/1000-AC16*$BC$4*0.9/1000-AL16*BF$4*炼钢参数表!$X$5/1000-AM16*BG$4*炼钢参数表!$X$5/1000)<=(K16-炼钢参数表!J16-AB16*0.6566*炼钢参数表!L16/10-AC16*($AC$3/100)*炼钢参数表!L16/10)*0.02,0,((K16-炼钢参数表!J16-AB16*0.6566*炼钢参数表!L16/10-AC16*($AC$3/100)*炼钢参数表!L16/10)/100/($AD$3/100)/炼钢参数表!L16*1000)) -> 0 | AE16: =(K16-炼钢参数表!J16-AB16*0.6566*炼钢参数表!L16/10-AC16*($AC$3/100)*炼钢参数表!L16/10-AD16*($AD$3/100)*炼钢参数表!L16/10)/100/($AE$3/100)/炼钢参数表!L16*1000 -> 0 | AF16: 0 | AG16: =IF(J16<=0.04,0,((J16-(AB16*0.1769*炼钢参数表!K16/1000*100))/100/炼钢参数表!K16/($AG$3/100)*1000)) -> 0.49723578 | AH16: 1.2 | AI16: =IF(N16="",0,IF(N16<=0.002,0,((N16)/100)/($AI$3/100)/炼钢参数表!M16*1000)) -> 0 | AJ16: =IF(O16="",0,IF(O16<=0.002,0,((O16)/100)/($AJ$3/100)/炼钢参数表!N16*1000)) -> 0 | AK16: =IF(P16="",0,IF(P16<=0.002,0,((P16+0.005)/100)/($AK$3/100)/炼钢参数表!O16*1000)) -> 0 | AL16: =IF((BA16-J16*0.00003-K16*0.00024)<=0.05,0,IF(T16="",0,IF(T16<=0.03,0,IF(((BA16-J16*0.00003-K16*0.00024)-0.05)/0.18/100/($AL$3/100)/炼钢参数表!P16*1000<=T16/100/($AL$3/100)/炼钢参数表!P16*1000,((BA16-J16*0.00003-K16*0.00024)-0.05)/0.18/100/($AL$3/100)/炼钢参数表!P16*1000,T16/100/($AL$3/100)/炼钢参数表!P16*1000)))) -> 0 | AM16: =IF(T16="",0,IF(T16<=0.03,0,((T16-AL16*($AL$3/100)*炼钢参数表!P16/10)/100/($AM$3/100)/炼钢参数表!P16*1000))) -> 0 | AN16: =IF(U16="",0,IF(U16<=0.02,0,(U16/100)/($AN$3/100)/炼钢参数表!Q16*1000)) -> 0 | AO16: =IF(V16="",0,IF(V16<=0.02,0,(V16/100)/($AO$3/100)/炼钢参数表!R16*1000)) -> 0 | AP16: =IF(W16="",0,IF(W16<=0.02,0,(W16/100)/($AP$3/100)/炼钢参数表!S16*1000)) -> 0 | AQ16: =IF(X16="",0,IF(X16<=0.0002,0,(X16/100)/($AQ$3/100)/炼钢参数表!T16*1000)) -> 0 | AR16: =IF(Y16="",0,IF(Y16<=0.02,0,(Y16/100)/($AR$3/100)/炼钢参数表!U16*1000)) -> 0 | AS16: =IF(L16<=0.04,0,((L16-0.04)/100)/($AS$3/100)/炼钢参数表!V16*1000) -> 0 | AT16: =IF(M16<=0.03,0,((M16-0.03)/100)/($AT$3/100)/炼钢参数表!W16*1000) -> 0 | AV16: =SUM(AB16:AU16) -> 5.6967454 | AW16: {=SUMPRODUCT($AB$4:$AU$4,AB16:AU16)/1000} -> 51.079642 | AY16: =F16 -> Q235B-2 | AZ16: =VLOOKUP(AY16,炼钢参数表!$F$5:$J$1027,4,0) -> 0.074405858 | BA16: =I16-AZ16 -> 0.085594142 | BB16: =AB16*$BB$4*炼钢参数表!$X$5/1000 -> 0.006191241 | BC16: =AC16*$BC$4*炼钢参数表!$X$5/1000 -> 0 | BD16: =AD16*$BD$4*炼钢参数表!$X$5/1000 -> 0 | BE16: =AE16*$BE$4*炼钢参数表!$X$5/1000 -> 0 | BF16: =AL16*$BF$4*炼钢参数表!$X$5/1000 -> 0 | BG16: =AM16*$BG$4*炼钢参数表!$X$5/1000 -> 0 | BH16: =SUM(BB16:BG16) -> 0.006191241 | BI16: =AZ16+BH16 -> 0.080597099 | BJ16: =BI16-I16 -> -0.079402901
A17: 13 | B17: Q235B-GL | C17: 01 | D17: 1.6 | E17: 5 | F17: Q235B-GL1 | G17: A 碳素钢-碳素结构钢-A06 Q235B-GL | H17: 1520 | I17: 0.15 | J17: 0.12 | K17: 0.25 | L17: 0.015 | M17: 0.005 | Q17: 0.015 | AB17: =IF(J17<=0.04,0,IF((BA17-AL17*BF$4*炼钢参数表!$X$5/1000-AM17*BG$4*炼钢参数表!$X$5/1000)<=0.03,0,IF((J17/100/0.1769/炼钢参数表!K17*1000)>(K17-炼钢参数表!J17)/100/0.6566/炼钢参数表!L17*1000,IF(K17<1.6,(K17-炼钢参数表!J17)/100/0.6566/炼钢参数表!L17*1000,(K17-0.08-炼钢参数表!J17)/100/0.6566/炼钢参数表!L17*1000),IF(K17<1.6,J17/100/0.1769/炼钢参数表!K17*1000,(J17-0.08)/100/0.1769/炼钢参数表!K17*1000)))) -> 1.9792072 | AC17: =IF((BA17-AB17*$BB$4*0.9/1000-AL17*BF$4*炼钢参数表!$X$5/1000-AM17*BG$4*炼钢参数表!$X$5/1000)<(K17-炼钢参数表!J17-AB17*0.6566*炼钢参数表!L17/10)*0.082,0,(K17-炼钢参数表!J17-AB17*0.6566*炼钢参数表!L17/10)/100/($AC$3/100)/炼钢参数表!L17*1000) -> 0 | AD17: =IF((BA17-AB17*$BB$4*0.9/1000-AC17*$BC$4*0.9/1000-AL17*BF$4*炼钢参数表!$X$5/1000-AM17*BG$4*炼钢参数表!$X$5/1000)<=(K17-炼钢参数表!J17-AB17*0.6566*炼钢参数表!L17/10-AC17*($AC$3/100)*炼钢参数表!L17/10)*0.02,0,((K17-炼钢参数表!J17-AB17*0.6566*炼钢参数表!L17/10-AC17*($AC$3/100)*炼钢参数表!L17/10)/100/($AD$3/100)/炼钢参数表!L17*1000)) -> 0 | AE17: =(K17-炼钢参数表!J17-AB17*0.6566*炼钢参数表!L17/10-AC17*($AC$3/100)*炼钢参数表!L17/10-AD17*($AD$3/100)*炼钢参数表!L17/10)/100/($AE$3/100)/炼钢参数表!L17*1000 -> 0 | AF17: 0 | AG17: =IF(J17<=0.04,0,((J17-(AB17*0.1769*炼钢参数表!K17/1000*100))/100/炼钢参数表!K17/($AG$3/100)*1000)) -> 1.5919677 | AH17: 1.3 | AI17: =IF(N17="",0,IF(N17<=0.002,0,((N17)/100)/($AI$3/100)/炼钢参数表!M17*1000)) -> 0 | AJ17: =IF(O17="",0,IF(O17<=0.002,0,((O17)/100)/($AJ$3/100)/炼钢参数表!N17*1000)) -> 0 | AK17: =IF(P17="",0,IF(P17<=0.002,0,((P17+0.005)/100)/($AK$3/100)/炼钢参数表!O17*1000)) -> 0 | AL17: =IF((BA17-J17*0.00003-K17*0.00024)<=0.05,0,IF(T17="",0,IF(T17<=0.03,0,IF(((BA17-J17*0.00003-K17*0.00024)-0.05)/0.18/100/($AL$3/100)/炼钢参数表!P17*1000<=T17/100/($AL$3/100)/炼钢参数表!P17*1000,((BA17-J17*0.00003-K17*0.00024)-0.05)/0.18/100/($AL$3/100)/炼钢参数表!P17*1000,T17/100/($AL$3/100)/炼钢参数表!P17*1000)))) -> 0 | AM17: =IF(T17="",0,IF(T17<=0.03,0,((T17-AL17*($AL$3/100)*炼钢参数表!P17/10)/100/($AM$3/100)/炼钢参数表!P17*1000))) -> 0 | AN17: =IF(U17="",0,IF(U17<=0.02,0,(U17/100)/($AN$3/100)/炼钢参数表!Q17*1000)) -> 0 | AO17: =IF(V17="",0,IF(V17<=0.02,0,(V17/100)/($AO$3/100)/炼钢参数表!R17*1000)) -> 0 | AP17: =IF(W17="",0,IF(W17<=0.02,0,(W17/100)/($AP$3/100)/炼钢参数表!S17*1000)) -> 0 | AQ17: =IF(X17="",0,IF(X17<=0.0002,0,(X17/100)/($AQ$3/100)/炼钢参数表!T17*1000)) -> 0 | AR17: =IF(Y17="",0,IF(Y17<=0.02,0,(Y17/100)/($AR$3/100)/炼钢参数表!U17*1000)) -> 0 | AS17: =IF(L17<=0.04,0,((L17-0.04)/100)/($AS$3/100)/炼钢参数表!V17*1000) -> 0 | AT17: =IF(M17<=0.03,0,((M17-0.03)/100)/($AT$3/100)/炼钢参数表!W17*1000) -> 0 | AV17: =SUM(AB17:AU17) -> 4.8711749 | AW17: {=SUMPRODUCT($AB$4:$AU$4,AB17:AU17)/1000} -> 48.03077 | AY17: =F17 -> Q235B-GL1 | AZ17: =VLOOKUP(AY17,炼钢参数表!$F$5:$J$1027,4,0) -> 0.074405858 | BA17: =I17-AZ17 -> 0.075594142 | BB17: =AB17*$BB$4*炼钢参数表!$X$5/1000 -> 0.0030638127 | BC17: =AC17*$BC$4*炼钢参数表!$X$5/1000 -> 0 | BD17: =AD17*$BD$4*炼钢参数表!$X$5/1000 -> 0 | BE17: =AE17*$BE$4*炼钢参数表!$X$5/1000 -> 0 | BF17: =AL17*$BF$4*炼钢参数表!$X$5/1000 -> 0 | BG17: =AM17*$BG$4*炼钢参数表!$X$5/1000 -> 0 | BH17: =SUM(BB17:BG17) -> 0.0030638127 | BI17: =AZ17+BH17 -> 0.07746967 | BJ17: =BI17-I17 -> -0.07253033
A18: 14 | B18: Q235B-GL | C18: 02 | D18: 5.01 | E18: 14 | F18: Q235B-GL2 | G18: A 碳素钢-碳素结构钢-A06 Q235B-GL | H18: 1520 | I18: 0.15 | J18: 0.12 | K18: 0.35 | L18: 0.015 | M18: 0.005 | Q18: 0.015 | AB18: =IF(J18<=0.04,0,IF((BA18-AL18*BF$4*炼钢参数表!$X$5/1000-AM18*BG$4*炼钢参数表!$X$5/1000)<=0.03,0,IF((J18/100/0.1769/炼钢参数表!K18*1000)>(K18-炼钢参数表!J18)/100/0.6566/炼钢参数表!L18*1000,IF(K18<1.6,(K18-炼钢参数表!J18)/100/0.6566/炼钢参数表!L18*1000,(K18-0.08-炼钢参数表!J18)/100/0.6566/炼钢参数表!L18*1000),IF(K18<1.6,J18/100/0.1769/炼钢参数表!K18*1000,(J18-0.08)/100/0.1769/炼钢参数表!K18*1000)))) -> 3.533286 | AC18: =IF((BA18-AB18*$BB$4*0.9/1000-AL18*BF$4*炼钢参数表!$X$5/1000-AM18*BG$4*炼钢参数表!$X$5/1000)<(K18-炼钢参数表!J18-AB18*0.6566*炼钢参数表!L18/10)*0.082,0,(K18-炼钢参数表!J18-AB18*0.6566*炼钢参数表!L18/10)/100/($AC$3/100)/炼钢参数表!L18*1000) -> 0 | AD18: =IF((BA18-AB18*$BB$4*0.9/1000-AC18*$BC$4*0.9/1000-AL18*BF$4*炼钢参数表!$X$5/1000-AM18*BG$4*炼钢参数表!$X$5/1000)<=(K18-炼钢参数表!J18-AB18*0.6566*炼钢参数表!L18/10-AC18*($AC$3/100)*炼钢参数表!L18/10)*0.02,0,((K18-炼钢参数表!J18-AB18*0.6566*炼钢参数表!L18/10-AC18*($AC$3/100)*炼钢参数表!L18/10)/100/($AD$3/100)/炼钢参数表!L18*1000)) -> 0 | AE18: =(K18-炼钢参数表!J18-AB18*0.6566*炼钢参数表!L18/10-AC18*($AC$3/100)*炼钢参数表!L18/10-AD18*($AD$3/100)*炼钢参数表!L18/10)/100/($AE$3/100)/炼钢参数表!L18*1000 -> 0 | AF18: 0 | AG18: =IF(J18<=0.04,0,((J18-(AB18*0.1769*炼钢参数表!K18/1000*100))/100/炼钢参数表!K18/($AG$3/100)*1000)) -> 1.211355 | AH18: 1.3 | AI18: =IF(N18="",0,IF(N18<=0.002,0,((N18)/100)/($AI$3/100)/炼钢参数表!M18*1000)) -> 0 | AJ18: =IF(O18="",0,IF(O18<=0.002,0,((O18)/100)/($AJ$3/100)/炼钢参数表!N18*1000)) -> 0 | AK18: =IF(P18="",0,IF(P18<=0.002,0,((P18+0.005)/100)/($AK$3/100)/炼钢参数表!O18*1000)) -> 0 | AL18: =IF((BA18-J18*0.00003-K18*0.00024)<=0.05,0,IF(T18="",0,IF(T18<=0.03,0,IF(((BA18-J18*0.00003-K18*0.00024)-0.05)/0.18/100/($AL$3/100)/炼钢参数表!P18*1000<=T18/100/($AL$3/100)/炼钢参数表!P18*1000,((BA18-J18*0.00003-K18*0.00024)-0.05)/0.18/100/($AL$3/100)/炼钢参数表!P18*1000,T18/100/($AL$3/100)/炼钢参数表!P18*1000)))) -> 0 | AM18: =IF(T18="",0,IF(T18<=0.03,0,((T18-AL18*($AL$3/100)*炼钢参数表!P18/10)/100/($AM$3/100)/炼钢参数表!P18*1000))) -> 0 | AN18: =IF(U18="",0,IF(U18<=0.02,0,(U18/100)/($AN$3/100)/炼钢参数表!Q18*1000)) -> 0 | AO18: =IF(V18="",0,IF(V18<=0.02,0,(V18/100)/($AO$3/100)/炼钢参数表!R18*1000)) -> 0 | AP18: =IF(W18="",0,IF(W18<=0.02,0,(W18/100)/($AP$3/100)/炼钢参数表!S18*1000)) -> 0 | AQ18: =IF(X18="",0,IF(X18<=0.0002,0,(X18/100)/($AQ$3/100)/炼钢参数表!T18*1000)) -> 0 | AR18: =IF(Y18="",0,IF(Y18<=0.02,0,(Y18/100)/($AR$3/100)/炼钢参数表!U18*1000)) -> 0 | AS18: =IF(L18<=0.04,0,((L18-0.04)/100)/($AS$3/100)/炼钢参数表!V18*1000) -> 0 | AT18: =IF(M18<=0.03,0,((M18-0.03)/100)/($AT$3/100)/炼钢参数表!W18*1000) -> 0 | AV18: =SUM(AB18:AU18) -> 6.044641 | AW18: {=SUMPRODUCT($AB$4:$AU$4,AB18:AU18)/1000} -> 54.487507 | AY18: =F18 -> Q235B-GL2 | AZ18: =VLOOKUP(AY18,炼钢参数表!$F$5:$J$1027,4,0) -> 0.074405858 | BA18: =I18-AZ18 -> 0.075594142 | BB18: =AB18*$BB$4*炼钢参数表!$X$5/1000 -> 0.0054695268 | BC18: =AC18*$BC$4*炼钢参数表!$X$5/1000 -> 0 | BD18: =AD18*$BD$4*炼钢参数表!$X$5/1000 -> 0 | BE18: =AE18*$BE$4*炼钢参数表!$X$5/1000 -> 0 | BF18: =AL18*$BF$4*炼钢参数表!$X$5/1000 -> 0 | BG18: =AM18*$BG$4*炼钢参数表!$X$5/1000 -> 0 | BH18: =SUM(BB18:BG18) -> 0.0054695268 | BI18: =AZ18+BH18 -> 0.079875384 | BJ18: =BI18-I18 -> -0.070124616
