Workbook

Sheet 目标成分
A2: 序号 | B2: 适用 牌号 | C2: 分类 序号 | D2: 最小厚度mm | E2: 最大厚度mm | F2: 炼钢 牌号 | G2: 钢种类型 | H2: 液相线温度℃ | I2: 内控成分目标值/wt% | AA2: 备注
I3: C | J3: Si | K3: Mn | L3: P | M3: S | N3: V | O3: Nb | P3: Ti | Q3: Als | R3: Alt | S3: Ca | T3: Cr | U3: Ni | V3: Cu | W3: Mo | X3: B | Y3: Sb | Z3: N
B4: 合金不含税价格
A5: 1 | B5: Q195 | C5: 01 | D5: 1.5 | E5: 12 | F5: Q195-1 | G5: A 碳素钢-碳素结构钢-A20 Q195 | H5: 1527 | I5: 0.07 | J5: 0.15 | K5: 0.25 | L5: 0.02 | M5: 0.015 | P5: 0.01 | Q5: 0.01 | Z5: 60
A6: 2 | B6: Q195 | C6: 02 | D6: 12.01 | E6: 28 | F6: Q195-2 | G6: A 碳素钢-碳素结构钢-A20 Q195 | H6: 1527 | I6: 0.07 | J6: 0.15 | K6: 0.32 | L6: 0.02 | M6: 0.015 | Q6: 0.01 | Z6: 60
A7: 3 | B7: Q235B | C7: 01 | D7: 1.45 | E7: 12 | F7: Q235B-1 | G7: A 碳素钢-碳素结构钢-A01 Q235B | H7: 1519 | I7: 0.16 | J7: 0.08 | K7: 0.23 | L7: 0.025 | M7: 0.02 | Q7: 0.01
A8: 4 | B8: Q235B | C8: 02 | D8: 12.01 | E8: 28 | F8: Q235B-2 | G8: A 碳素钢-碳素结构钢-A01 Q235B | H8: 1519 | I8: 0.16 | J8: 0.08 | K8: 0.38 | L8: 0.025 | M8: 0.02 | Q8: 0.01
A9: 5 | B9: Q235C | C9: 01 | D9: 1.6 | E9: 12 | F9: Q235C-1 | G9: A 碳素钢-碳素结构钢-A02 Q235C | H9: 1519 | I9: 0.15 | J9: 0.1 | K9: 0.35 | L9: 0.015 | M9: 0.01 | Q9: 0.025
A10: 6 | B10: Q235C | C10: 02 | D10: 12.01 | E10: 25.4 | F10: Q235C-2 | G10: A 碳素钢-碳素结构钢-A02 Q235C | H10: 1519 | I10: 0.15 | J10: 0.1 | K10: 0.5 | L10: 0.015 | M10: 0.01 | Q10: 0.025
A11: 7 | B11: Q235B-WJ | C11: 01 | D11: 1.45 | E11: 12 | F11: Q235B-1 | G11: A 碳素钢-碳素结构钢-A01 Q235B | H11: 1519 | I11: 0.16 | J11: 0.08 | K11: 0.23 | L11: 0.025 | M11: 0.02 | Q11: 0.01
A12: 8 | B12: Q235B-WJ | C12: 02 | D12: 12.01 | E12: 28 | F12: Q235B-2 | G12: A 碳素钢-碳素结构钢-A01 Q235B | H12: 1519 | I12: 0.16 | J12: 0.08 | K12: 0.38 | L12: 0.025 | M12: 0.02 | Q12: 0.01
A13: 9 | B13: Q235B-LX | C13: 01 | D13: 1.45 | E13: 12 | F13: Q235B-1 | G13: A 碳素钢-碳素结构钢-A01 Q235B | H13: 1519 | I13: 0.16 | J13: 0.08 | K13: 0.23 | L13: 0.025 | M13: 0.02 | Q13: 0.01
A14: 10 | B14: Q235B-LX | C14: 02 | D14: 12.01 | E14: 28 | F14: Q235B-2 | G14: A 碳素钢-碳素结构钢-A01 Q235B | H14: 1519 | I14: 0.16 | J14: 0.08 | K14: 0.38 | L14: 0.025 | M14: 0.02 | Q14: 0.01
A15: 11 | B15: Q235B-HX | C15: 01 | D15: 1.45 | E15: 12 | F15: Q235B-1 | G15: A 碳素钢-碳素结构钢-A01 Q235B | H15: 1519 | I15: 0.16 | J15: 0.08 | K15: 0.23 | L15: 0.025 | M15: 0.02 | Q15: 0.01
A16: 12 | B16: Q235B-HX | C16: 02 | D16: 12.01 | E16: 28 | F16: Q235B-2 | G16: A 碳素钢-碳素结构钢-A01 Q235B | H16: 1519 | I16: 0.16 | J16: 0.08 | K16: 0.38 | L16: 0.025 | M16: 0.02 | Q16: 0.01
A17: 13 | B17: Q235B-GL | C17: 01 | D17: 1.6 | E17: 5 | F17: Q235B-GL1 | G17: A 碳素钢-碳素结构钢-A06 Q235B-GL | H17: 1520 | I17: 0.15 | J17: 0.12 | K17: 0.25 | L17: 0.015 | M17: 0.005 | Q17: 0.015
A18: 14 | B18: Q235B-GL | C18: 02 | D18: 5.01 | E18: 14 | F18: Q235B-GL2 | G18: A 碳素钢-碳素结构钢-A06 Q235B-GL | H18: 1520 | I18: 0.15 | J18: 0.12 | K18: 0.35 | L18: 0.015 | M18: 0.005 | Q18: 0.015
... A30: 26 | B30: A36-HW | C30: 01 | D30: 1.5 | E30: 12 | F30: A36-1 | G30: A 碳素钢-碳素结构钢-A09 A36 | H30: 1519 | I30: 0.16 | J30: 0.08 | K30: 0.25 | L30: 0.015 | M30: 0.01 | Q30: 0.02
A31: 27 | B31: Q235-HW | C31: 01 | D31: 1.5 | E31: 16 | F31: Q235-HW | G31: E 花纹板-花纹板类钢材-E01 Q235-HW | H31: 1519 | I31: 0.16 | J31: 0.1 | K31: 0.25 | L31: 0.035 | M31: 0.02
A32: 28 | B32: Q355-HW | C32: 01 | D32: 3 | E32: 6 | F32: Q355-HW1 | G32: E 花纹板-花纹板类钢材-E04 Q355-HW | H32: 1518 | I32: 0.16 | J32: 0.08 | K32: 0.35 | L32: 0.02 | M32: 0.01 | P32: 0.04 | Q32: 0.02 | AA32: Q355级别花纹板
A33: 29 | B33: Q355-HW | C33: 02 | D33: 6.01 | E33: 10 | F33: Q355-HW2 | G33: E 花纹板-花纹板类钢材-E04 Q355-HW | H33: 1517 | I33: 0.16 | J33: 0.08 | K33: 0.5 | L33: 0.02 | M33: 0.01 | P33: 0.04 | Q33: 0.02 | AA33: Q355级别花纹板
A34: 30 | B34: SPHC | C34: 01 | D34: 1.6 | E34: 8 | F34: SPHC-ZT | G34: C 热轧低碳钢-冷轧基料-C01 SPHC | H34: 1531 | I34: 0.05 | J34: 0.015 | K34: 0.23 | L34: 0.015 | M34: 0.01 | Q34: 0.025 | Z34: 40
A35: 31 | B35: SPHC | C35: 02 | D35: 8.01 | E35: 16 | F35: SPHC-SX | G35: C 热轧低碳钢-冷轧基料-C01 SPHC | H35: 1531 | I35: 0.05 | J35: 0.015 | K35: 0.23 | L35: 0.015 | M35: 0.01 | Q35: 0.025 | Z35: 40
A36: 32 | B36: SPHC | C36: 01 | D36: 8.01 | E36: 16 | F36: SPHC-SX | G36: C 热轧低碳钢-冷轧基料-C01 SPHC | H36: 1531 | I36: 0.05 | J36: 0.015 | K36: 0.23 | L36: 0.015 | M36: 0.01 | Q36: 0.025 | Z36: 40 | AA36: SPHC-SX
A37: 33 | B37: SPHC-M | C37: 01 | D37: 2.5 | E37: 5 | F37: SPHC-M | G37: C 热轧低碳钢-冷轧基料-C02 SPHC-M | H37: 1531 | I37: 0.045 | J37: 0.02 | K37: 0.25 | L37: 0.015 | M37: 0.006 | Q37: 0.025 | Z37: 45
A38: 34 | B38: SPHC-M(B) | C38: 01 | D38: 2.5 | E38: 6 | F38: SPHC-M(B) | G38: C 热轧低碳钢-冷轧基料-C05 SPHC-M(B) | H38: 1531 | I38: 0.045 | J38: 0.02 | K38: 0.25 | L38: 0.015 | M38: 0.006 | Q38: 0.025 | X38: 0.0014 | AA38: 含硼马口铁
A39: 35 | B39: MRT2.5 | C39: 01 | D39: 2.5 | E39: 6 | F39: MRT2.5 | G39: C 热轧低碳钢-冷轧基料-C03 MRT2.5 | H39: 1529 | I39: 0.06 | J39: 0 | K39: 0.28 | L39: 0.015 | M39: 0.006 | Q39: 0.03 | AA39: 供日照昱岚新材料有限公司冷轧用热轧卷板
A40: 36 | B40: YFMRT2.5 | C40: 01 | D40: 2.5 | E40: 6 | F40: YFMRT2.5 | G40: C 热轧低碳钢-冷轧基料-C07 YFMRT2.5 | H40: 1529 | I40: 0.06 | J40: 0 | K40: 0.28 | L40: 0.015 | M40: 0.006 | Q40: 0.03 | AA40: 供友富用热轧卷板
A41: 37 | B41: YLMRT3 | C41: 01 | D41: 2.5 | E41: 3.5 | F41: YLMRT3 | G41: C 热轧低碳钢-冷轧基料-C04 YLMRT3 | H41: 1528 | I41: 0.07 | J41: 0 | K41: 0.35 | L41: 0.015 | M41: 0.006 | Q41: 0.03 | AA41: 供日照昱岚新材料有限公司冷轧用热轧卷板
A42: 38 | B42: Q355B | C42: 02 | D42: 0.1 | E42: 5.99 | F42: Q355B-1 | G42: B 结构钢-低合金高强结构钢-B01 Q355B | H42: 1518 | I42: 0.16 | J42: 0.08 | K42: 0.35 | L42: 0.02 | M42: 0.01 | P42: 0.04 | Q42: 0.02
A43: 39 | B43: Q355B | C43: 01 | D43: 6 | E43: 15.99 | F43: Q355B-2 | G43: B 结构钢-低合金高强结构钢-B01 Q355B | H43: 1517 | I43: 0.16 | J43: 0.08 | K43: 0.5 | L43: 0.02 | M43: 0.01 | P43: 0.04 | Q43: 0.02
A44: 40 | B44: Q355B | C44: 03 | D44: 16 | E44: 28 | F44: Q355B-3B | G44: B 低合金钢-低合金高强结构钢-B01 Q355B | H44: 1514 | I44: 0.16 | J44: 0.18 | K44: 1.1 | L44: 0.02 | M44: 0.01 | O44: 0.008 | P44: 0.025 | Q44: 0.02
A45: 41 | B45: Q355C | C45: 01 | D45: 2 | E45: 12 | F45: Q355C-1 | G45: B 低合金钢-低合金高强结构钢-B03 Q355C | H45: 1517 | I45: 0.16 | J45: 0.15 | K45: 1 | L45: 0.018 | M45: 0.01 | P45: 0.03 | Q45: 0.025 | Z45: 40
A46: 42 | B46: Q355C | C46: 02 | D46: 12.01 | E46: 19 | F46: Q355C-2 | G46: B 低合金钢-低合金高强结构钢-B03 Q355C | H46: 1517 | I46: 0.16 | J46: 0.15 | K46: 1.15 | L46: 0.018 | M46: 0.01 | O46: 0.012 | P46: 0.015 | Q46: 0.025 | Z46: 40
A47: 43 | B47: Q355C | C47: 03 | D47: 19.01 | E47: 29 | F47: Q355C-3 | G47: B 低合金钢-低合金高强结构钢-B03 Q355C | H47: 1517 | I47: 0.16 | J47: 0.15 | K47: 1.35 | L47: 0.018 | M47: 0.01 | O47: 0.015 | P47: 0.025 | Q47: 0.025 | Z47: 40
A48: 44 | B48: Q355D | C48: 01 | D48: 2 | E48: 12 | F48: Q355D-1 | G48: B 低合金钢-低合金高强结构钢-B04 Q355D | H48: 1517 | I48: 0.16 | J48: 0.15 | K48: 1 | L48: 0.018 | M48: 0.008 | P48: 0.03 | Q48: 0.025
A49: 45 | B49: Q355D | C49: 02 | D49: 12.01 | E49: 19 | F49: Q355D-2 | G49: B 低合金钢-低合金高强结构钢-B04 Q355D | H49: 1521 | I49: 0.16 | J49: 0.15 | K49: 1.15 | L49: 0.018 | M49: 0.008 | O49: 0.012 | P49: 0.015 | Q49: 0.025 | Z49: 40
A50: 46 | B50: Q355D | C50: 03 | D50: 19.01 | E50: 29 | F50: Q355D-3 | G50: B 低合金钢-低合金高强结构钢-B04 Q355D | H50: 1521 | I50: 0.16 | J50: 0.15 | K50: 1.3 | L50: 0.018 | M50: 0.008 | O50: 0.015 | P50: 0.015 | Q50: 0.025 | Z50: 40
A51: 47 | B51: Q355B-T | C51: 01 | D51: 2 | E51: 7.55 | F51: Q355B-T1 | G51: B 低合金钢-低合金高强结构钢-B17 Q355B-T | H51: 1514 | I51: 0.16 | J51: 0.15 | K51: 1.1 | L51: 0.015 | M51: 0.01 | P51: 0.025 | Q51: 0.02
A52: 48 | B52: Q355B-T | C52: 02 | D52: 7.56 | E52: 16 | F52: Q355B-T2 | G52: B 低合金钢-低合金高强结构钢-B17 Q355B-T | H52: 1514 | I52: 0.16 | J52: 0.15 | K52: 1.1 | L52: 0.015 | M52: 0.01 | P52: 0.035 | Q52: 0.02
...

Sheet 终点成分与元素回收率
A2: 序号 | B2: 适用牌号 | C2: 厚度mm | D2: 厚度mm | E2: 厚度mm | F2: 炼钢牌号 | G2: 钢种类型 | H2: 液相线温度℃ | I2: 终点碳 | J2: 终点锰 | K2: 终点Cr | L2: 硅回收率 | M2: 锰回收率 | N2: 钒回收率 | O2: 铌回收率 | P2: 钛回收率 | Q2: 铬回收率
A5: 1 | B5: Q195 | C5: 01 | D5: 1.5 | E5: 12 | F5: Q195-1 | G5: A 碳素钢-碳素结构钢-A20 Q195 | H5: 1527 | I5: =VLOOKUP(F5,[1]终点成分!$A$5:$C$1000,2,0) -> 0.041666667 | J5: =VLOOKUP(F5,[1]终点成分!$A$5:$C$1000,3,0) -> 0.103 | K5: 0 | L5: 0.75 | M5: 0.98 | N5: 0.98 | O5: 0.98 | P5: 0.7 | Q5: 0.96
A6: 2 | B6: Q195 | C6: 02 | D6: 12.01 | E6: 28 | F6: Q195-2 | G6: A 碳素钢-碳素结构钢-A20 Q195 | H6: 1527 | I6: 0.041666667 | J6: 0.103 | K6: 0 | L6: 0.75 | M6: 0.98 | N6: 0.98 | O6: 0.98 | P6: 0.7 | Q6: 0.96
A7: 3 | B7: Q235B | C7: 01 | D7: 1.45 | E7: 12 | F7: Q235B-1 | G7: A 碳素钢-碳素结构钢-A01 Q235B | H7: 1519 | I7: =VLOOKUP(F7,[1]终点成分!$A$5:$C$1000,2,0) -> 0.07293667 | J7: =VLOOKUP(F7,[1]终点成分!$A$5:$C$1000,3,0) -> 0.12229229 | K7: 0 | L7: 0.75 | M7: 0.98 | N7: 0.98 | O7: 0.98 | P7: 0.7 | Q7: 0.96
A8: 4 | B8: Q235B | C8: 02 | D8: 12.01 | E8: 28 | F8: Q235B-2 | G8: A 碳素钢-碳素结构钢-A01 Q235B | H8: 1519 | I8: =VLOOKUP(F8,[1]终点成分!$A$5:$C$1000,2,0) -> 0.074405858 | J8: =VLOOKUP(F8,[1]终点成分!$A$5:$C$1000,3,0) -> 0.12264435 | K8: 0 | L8: 0.75 | M8: 0.98 | N8: 0.98 | O8: 0.98 | P8: 0.7 | Q8: 0.96
A9: 5 | B9: Q235C | C9: 01 | D9: 1.6 | E9: 12 | F9: Q235C-1 | G9: A 碳素钢-碳素结构钢-A02 Q235C | H9: 1519 | I9: =VLOOKUP(F9,[1]终点成分!$A$5:$C$1000,2,0) -> 0.068953488 | J9: =VLOOKUP(F9,[1]终点成分!$A$5:$C$1000,3,0) -> 0.11909302 | K9: 0 | L9: 0.8 | M9: 0.98 | N9: 0.98 | O9: 0.98 | P9: 0.7 | Q9: 0.96
A10: 6 | B10: Q235C | C10: 02 | D10: 12.01 | E10: 25.4 | F10: Q235C-2 | G10: A 碳素钢-碳素结构钢-A02 Q235C | H10: 1519 | I10: =VLOOKUP(F10,[1]终点成分!$A$5:$C$1000,2,0) -> 0.0625 | J10: =VLOOKUP(F10,[1]终点成分!$A$5:$C$1000,3,0) -> 0.1289 | K10: 0 | L10: 0.8 | M10: 0.98 | N10: 0.98 | O10: 0.98 | P10: 0.7 | Q10: 0.96
A11: 7 | B11: Q235B-WJ | C11: 01 | D11: 1.45 | E11: 12 | F11: Q235B-1 | G11: A 碳素钢-碳素结构钢-A01 Q235B | H11: 1519 | I11: =VLOOKUP(F11,[1]终点成分!$A$5:$C$1000,2,0) -> 0.07293667 | J11: =VLOOKUP(F11,[1]终点成分!$A$5:$C$1000,3,0) -> 0.12229229 | K11: 0 | L11: 0.75 | M11: 0.98 | N11: 0.98 | O11: 0.98 | P11: 0.7 | Q11: 0.96
A12: 8 | B12: Q235B-WJ | C12: 02 | D12: 12.01 | E12: 28 | F12: Q235B-2 | G12: A 碳素钢-碳素结构钢-A01 Q235B | H12: 1519 | I12: =VLOOKUP(F12,[1]终点成分!$A$5:$C$1000,2,0) -> 0.074405858 | J12: =VLOOKUP(F12,[1]终点成分!$A$5:$C$1000,3,0) -> 0.12264435 | K12: 0 | L12: 0.75 | M12: 0.98 | N12: 0.98 | O12: 0.98 | P12: 0.7 | Q12: 0.96
A13: 9 | B13: Q235B-LX | C13: 01 | D13: 1.45 | E13: 12 | F13: Q235B-1 | G13: A 碳素钢-碳素结构钢-A01 Q235B | H13: 1519 | I13: =VLOOKUP(F13,[1]终点成分!$A$5:$C$1000,2,0) -> 0.07293667 | J13: =VLOOKUP(F13,[1]终点成分!$A$5:$C$1000,3,0) -> 0.12229229 | K13: 0 | L13: 0.75 | M13: 0.98 | N13: 0.98 | O13: 0.98 | P13: 0.7 | Q13: 0.96
A14: 10 | B14: Q235B-LX | C14: 02 | D14: 12.01 | E14: 28 | F14: Q235B-2 | G14: A 碳素钢-碳素结构钢-A01 Q235B | H14: 1519 | I14: =VLOOKUP(F14,[1]终点成分!$A$5:$C$1000,2,0) -> 0.074405858 | J14: =VLOOKUP(F14,[1]终点成分!$A$5:$C$1000,3,0) -> 0.12264435 | K14: 0 | L14: 0.75 | M14: 0.98 | N14: 0.98 | O14: 0.98 | P14: 0.7 | Q14: 0.96
A15: 11 | B15: Q235B-HX | C15: 01 | D15: 1.45 | E15: 12 | F15: Q235B-1 | G15: A 碳素钢-碳素结构钢-A01 Q235B | H15: 1519 | I15: =VLOOKUP(F15,[1]终点成分!$A$5:$C$1000,2,0) -> 0.07293667 | J15: =VLOOKUP(F15,[1]终点成分!$A$5:$C$1000,3,0) -> 0.12229229 | K15: 0 | L15: 0.75 | M15: 0.98 | N15: 0.98 | O15: 0.98 | P15: 0.7 | Q15: 0.96
A16: 12 | B16: Q235B-HX | C16: 02 | D16: 12.01 | E16: 28 | F16: Q235B-2 | G16: A 碳素钢-碳素结构钢-A01 Q235B | H16: 1519 | I16: =VLOOKUP(F16,[1]终点成分!$A$5:$C$1000,2,0) -> 0.074405858 | J16: =VLOOKUP(F16,[1]终点成分!$A$5:$C$1000,3,0) -> 0.12264435 | K16: 0 | L16: 0.75 | M16: 0.98 | N16: 0.98 | O16: 0.98 | P16: 0.7 | Q16: 0.96
A17: 13 | B17: Q235B-GL | C17: 01 | D17: 1.6 | E17: 5 | F17: Q235B-GL1 | G17: A 碳素钢-碳素结构钢-A06 Q235B-GL | H17: 1520 | I17: 0.074405858 | J17: 0.12264435 | K17: 0 | L17: 0.8 | M17: 0.98 | N17: 0.98 | O17: 0.98 | P17: 0.7 | Q17: 0.96
A18: 14 | B18: Q235B-GL | C18: 02 | D18: 5.01 | E18: 14 | F18: Q235B-GL2 | G18: A 碳素钢-碳素结构钢-A06 Q235B-GL | H18: 1520 | I18: 0.074405858 | J18: 0.12264435 | K18: 0 | L18: 0.8 | M18: 0.98 | N18: 0.98 | O18: 0.98 | P18: 0.7 | Q18: 0.96
A19: 15 | B19: Q235B-GC | C19: 01 | D19: 3 | E19: 12 | F19: Q235B-GC1 | G19: A 碳素钢-碳素结构钢-A33 Q235B-GC | H19: 1519 | I19: =VLOOKUP(F19,[1]终点成分!$A$5:$C$1000,2,0) -> 0.073875 | J19: =VLOOKUP(F19,[1]终点成分!$A$5:$C$1000,3,0) -> 0.0935 | K19: 0 | L19: 0.75 | M19: 0.98 | N19: 0.98 | O19: 0.98 | P19: 0.7 | Q19: 0.96
A20: 16 | B20: Q235B-GC | C20: 02 | D20: 12.01 | E20: 25.4 | F20: Q235B-GC2 | G20: A 碳素钢-碳素结构钢-A33 Q235B-GC | H20: 1519 | I20: 0.073875 | J20: 0.0935 | K20: 0 | L20: 0.75 | M20: 0.98 | N20: 0.98 | O20: 0.98 | P20: 0.7 | Q20: 0.96
A21: 17 | B21: Q235B-SD | C21: 01 | D21: 3 | E21: 12 | F21: Q235B-SD1 | G21: A 碳素钢-碳素结构钢-A22 Q235B-SD | H21: 1519 | I21: =VLOOKUP(F21,[1]终点成分!$A$5:$C$1000,2,0) -> 0.073305085 | J21: =VLOOKUP(F21,[1]终点成分!$A$5:$C$1000,3,0) -> 0.12259322 | K21: 0 | L21: 0.75 | M21: 0.98 | N21: 0.98 | O21: 0.98 | P21: 0.7 | Q21: 0.96
A22: 18 | B22: Q235B-SD | C22: 02 | D22: 12.01 | E22: 25.4 | F22: Q235B-SD2 | G22: A 碳素钢-碳素结构钢-A22 Q235B-SD | H22: 1519 | I22: =VLOOKUP(F22,[1]终点成分!$A$5:$C$1000,2,0) -> 0.073272727 | J22: =VLOOKUP(F22,[1]终点成分!$A$5:$C$1000,3,0) -> 0.12463636 | K22: 0 | L22: 0.75 | M22: 0.98 | N22: 0.98 | O22: 0.98 | P22: 0.7 | Q22: 0.96
A23: 19 | B23: Q235B-HG | C23: 01 | D23: 1.5 | E23: 28 | F23: Q235B-HG | G23: A 碳素钢-碳素结构钢-A05 Q235B-HG | H23: 1519 | I23: =VLOOKUP(F23,[1]终点成分!$A$5:$C$1000,2,0) -> 0.075793852 | J23: =VLOOKUP(F23,[1]终点成分!$A$5:$C$1000,3,0) -> 0.13061844 | K23: 0 | L23: 0.8 | M23: 0.98 | N23: 0.98 | O23: 0.98 | P23: 0.7 | Q23: 0.96
A24: 20 | B24: A36 | C24: 01 | D24: 1.5 | E24: 12 | F24: A36-1 | G24: A 碳素钢-碳素结构钢-A09 A36 | H24: 1519 | I24: =VLOOKUP(F24,[1]终点成分!$A$5:$C$1000,2,0) -> 0.070300926 | J24: =VLOOKUP(F24,[1]终点成分!$A$5:$C$1000,3,0) -> 0.11168056 | K24: 0 | L24: 0.75 | M24: 0.98 | N24: 0.98 | O24: 0.98 | P24: 0.7 | Q24: 0.96
A25: 21 | B25: A36 | C25: 02 | D25: 12.01 | E25: 25 | F25: A36-2 | G25: A 碳素钢-碳素结构钢-A09 A36 | H25: 1519 | I25: =VLOOKUP(F25,[1]终点成分!$A$5:$C$1000,2,0) -> 0.068611111 | J25: =VLOOKUP(F25,[1]终点成分!$A$5:$C$1000,3,0) -> 0.11275 | K25: 0 | L25: 0.75 | M25: 0.98 | N25: 0.98 | O25: 0.98 | P25: 0.7 | Q25: 0.96
A26: 22 | B26: A36-DX | C26: 01 | D26: 1.5 | E26: 12 | F26: A36-DX1 | G26: A 碳素钢-碳素结构钢-A36 A36-DX | H26: 1519 | I26: =VLOOKUP(F26,[1]终点成分!$A$5:$C$1000,2,0) -> 0.07025 | J26: =VLOOKUP(F26,[1]终点成分!$A$5:$C$1000,3,0) -> 0.12091667 | K26: 0 | L26: 0 | M26: 0.98 | N26: 0.98 | O26: 0.98 | P26: 0.7 | Q26: 0.96
A27: 23 | B27: A36-DX | C27: 02 | D27: 12.01 | E27: 20 | F27: A36-DX2 | G27: A 碳素钢-碳素结构钢-A36 A36-DX | H27: 1519 | I27: =VLOOKUP(F27,[1]终点成分!$A$5:$C$1000,2,0) -> 0.079 | J27: =VLOOKUP(F27,[1]终点成分!$A$5:$C$1000,3,0) -> 0.1325 | K27: 0 | L27: 0 | M27: 0.98 | N27: 0.98 | O27: 0.98 | P27: 0.7 | Q27: 0.96
A28: 24 | B28: SS400 | C28: 01 | D28: 1.6 | E28: 12 | F28: SS400-1 | G28: A 碳素钢-碳素结构钢-A18 SS400 | H28: 1519 | I28: =VLOOKUP(F28,[1]终点成分!$A$5:$C$1000,2,0) -> 0.070962963 | J28: =VLOOKUP(F28,[1]终点成分!$A$5:$C$1000,3,0) -> 0.11677778 | K28: 0 | L28: 0.75 | M28: 0.98 | N28: 0.98 | O28: 0.98 | P28: 0.7 | Q28: 0.96
A29: 25 | B29: SS400 | C29: 02 | D29: 12.01 | E29: 25.4 | F29: SS400-2 | G29: A 碳素钢-碳素结构钢-A18 SS400 | H29: 1519 | I29: =VLOOKUP(F29,[1]终点成分!$A$5:$C$1000,2,0) -> 0.079833333 | J29: =VLOOKUP(F29,[1]终点成分!$A$5:$C$1000,3,0) -> 0.11583333 | K29: 0 | L29: 0.75 | M29: 0.98 | N29: 0.98 | O29: 0.98 | P29: 0.7 | Q29: 0.96
A30: 26 | B30: A36-HW | C30: 01 | D30: 1.5 | E30: 12 | F30: A36-1 | G30: A 碳素钢-碳素结构钢-A09 A36 | H30: 1519 | I30: =VLOOKUP(F30,[1]终点成分!$A$5:$C$1000,2,0) -> 0.070300926 | J30: =VLOOKUP(F30,[1]终点成分!$A$5:$C$1000,3,0) -> 0.11168056 | K30: 0 | L30: 0.75 | M30: 0.98 | N30: 0.98 | O30: 0.98 | P30: 0.7 | Q30: 0.96
A31: 27 | B31: Q235-HW | C31: 01 | D31: 1.5 | E31: 16 | F31: Q235-HW | G31: E 花纹板-花纹板类钢材-E01 Q235-HW | H31: 1519 | I31: =VLOOKUP(F31,[1]终点成分!$A$5:$C$1000,2,0) -> 0.07280137 | J31: =VLOOKUP(F31,[1]终点成分!$A$5:$C$1000,3,0) -> 0.12987329 | K31: 0 | L31: 0.55 | M31: 0.98 | N31: 0.98 | O31: 0.98 | P31: 0.7 | Q31: 0.96
A32: 28 | B32: Q355-HW | C32: 01 | D32: 3 | E32: 6 | F32: Q355-HW1 | G32: E 花纹板-花纹板类钢材-E04 Q355-HW | H32: 1518 | I32: 0.070817568 | J32: 0.12247703 | K32: 0 | L32: 0.75 | M32: 0.98 | N32: 0.98 | O32: 0.98 | P32: 0.7 | Q32: 0.96
A33: 29 | B33: Q355-HW | C33: 02 | D33: 6.01 | E33: 10 | F33: Q355-HW2 | G33: E 花纹板-花纹板类钢材-E04 Q355-HW | H33: 1517 | I33: 0.070817568 | J33: 0.12247703 | K33: 0 | L33: 0.75 | M33: 0.98 | N33: 0.98 | O33: 0.98 | P33: 0.7 | Q33: 0.96
A34: 30 | B34: SPHC | C34: 01 | D34: 1.6 | E34: 8 | F34: SPHC-ZT | G34: C 热轧低碳钢-冷轧基料-C01 SPHC | H34: 1531 | I34: 0.04 | J34: 0.09024 | K34: 0 | L34: 0 | M34: 0.98 | N34: 0.98 | O34: 0.98 | P34: 0.7 | Q34: 0.96
A35: 31 | B35: SPHC | C35: 02 | D35: 8.01 | E35: 16 | F35: SPHC-SX | G35: C 热轧低碳钢-冷轧基料-C01 SPHC | H35: 1531 | I35: 0.04 | J35: =VLOOKUP(F35,[1]终点成分!$A$5:$C$1000,3,0) -> 0.09024 | K35: 0 | L35: 0 | M35: 0.98 | N35: 0.98 | O35: 0.98 | P35: 0.7 | Q35: 0.96
A36: 32 | B36: SPHC | C36: 01 | D36: 8.01 | E36: 16 | F36: SPHC-SX | G36: C 热轧低碳钢-冷轧基料-C01 SPHC | H36: 1531 | I36: 0.04 | J36: =VLOOKUP(F36,[1]终点成分!$A$5:$C$1000,3,0) -> 0.09024 | K36: 0 | L36: 0 | M36: 0.98 | N36: 0.98 | O36: 0.98 | P36: 0.7 | Q36: 0.96
A37: 33 | B37: SPHC-M | C37: 01 | D37: 2.5 | E37: 5 | F37: SPHC-M | G37: C 热轧低碳钢-冷轧基料-C02 SPHC-M | H37: 1531 | I37: 0.04 | J37: =VLOOKUP(F37,[1]终点成分!$A$5:$C$1000,3,0) -> 0.09024 | K37: 0 | L37: 0 | M37: 0.98 | N37: 0.98 | O37: 0.98 | P37: 0.7 | Q37: 0.96
A38: 34 | B38: SPHC-M(B) | C38: 01 | D38: 2.5 | E38: 6 | F38: SPHC-M(B) | G38: C 热轧低碳钢-冷轧基料-C05 SPHC-M(B) | H38: 1531 | I38: 0.04 | J38: =VLOOKUP(F38,[1]终点成分!$A$5:$C$1000,3,0) -> 0.10625 | K38: 0 | L38: 0 | M38: 0.98 | N38: 0.98 | O38: 0.98 | P38: 0.7 | Q38: 0.96
A39: 35 | B39: MRT2.5 | C39: 01 | D39: 2.5 | E39: 6 | F39: MRT2.5 | G39: C 热轧低碳钢-冷轧基料-C03 MRT2.5 | H39: 1529 | I39: 0.04 | J39: =VLOOKUP(F39,[1]终点成分!$A$5:$C$1000,3,0) -> 0.11299078 | K39: 0 | L39: 0 | M39: 0.98 | N39: 0.98 | O39: 0.98 | P39: 0.7 | Q39: 0.96
A40: 36 | B40: YFMRT2.5 | C40: 01 | D40: 2.5 | E40: 6 | F40: YFMRT2.5 | G40: C 热轧低碳钢-冷轧基料-C07 YFMRT2.5 | H40: 1529 | I40: 0.04 | J40: =VLOOKUP(F40,[1]终点成分!$A$5:$C$1000,3,0) -> 0.0985 | K40: 0 | L40: 0 | M40: 0.98 | N40: 0.98 | O40: 0.98 | P40: 0.7 | Q40: 0.96
A41: 37 | B41: YLMRT3 | C41: 01 | D41: 2.5 | E41: 3.5 | F41: YLMRT3 | G41: C 热轧低碳钢-冷轧基料-C04 YLMRT3 | H41: 1528 | I41: 0.04 | J41: 0.0985 | K41: 0 | L41: 0 | M41: 0.98 | N41: 0.98 | O41: 0.98 | P41: 0.7 | Q41: 0.96
A42: 38 | B42: Q355B | C42: 02 | D42: 0.1 | E42: 5.99 | F42: Q355B-1 | G42: B 结构钢-低合金高强结构钢-B01 Q355B | H42: 1518 | I42: =VLOOKUP(F42,[1]终点成分!$A$5:$C$1000,2,0) -> 0.070817568 | J42: =VLOOKUP(F42,[1]终点成分!$A$5:$C$1000,3,0) -> 0.12247703 | K42: 0 | L42: 0.8 | M42: 0.98 | N42: 0.98 | O42: 0.98 | P42: 0.7 | Q42: 0.96
A43: 39 | B43: Q355B | C43: 01 | D43: 6 | E43: 15.99 | F43: Q355B-2 | G43: B 结构钢-低合金高强结构钢-B01 Q355B | H43: 1517 | I43: =VLOOKUP(F43,[1]终点成分!$A$5:$C$1000,2,0) -> 0.074004318 | J43: =VLOOKUP(F43,[1]终点成分!$A$5:$C$1000,3,0) -> 0.12120389 | K43: 0 | L43: 0.8 | M43: 0.98 | N43: 0.98 | O43: 0.98 | P43: 0.7 | Q43: 0.96
...

Sheet 合金品位
A1: 项目 | B1: 价格 | C1: 单耗 | D1: C | E1: Si | F1: Mn | G1: Cr | H1: 备注
A2: 目标成分 | D2: 0.08 | E2: 0.2 | F2: 1.2 | G2: 0.4
A3: 残余元素
A4: 回收率 | D4: 0.9 | E4: 0.75 | F4: 0.98 | G4: 0.95
A5: 硅锰 | D5: 1.72 | E5: 17.69 | F5: 65.66 | H5: 合金成分含量
A6: 高碳锰铁 | D6: 6.69 | F6: 74.6
A7: 中碳锰铁 | D7: 1.5 | F7: 78.54
A8: 低碳锰铁 | D8: 0.64 | F8: 81.19
A9: 硅铁 | D9: 0.2 | E9: 72.23
A10: 高碳铬铁 | D10: 10 | G10: 52
A11: 低碳铬铁 | D11: 0.12 | G11: 59.44
A12: 最优合金成本

Sheet 合金价格
D1: 含税到厂价格（元/吨)
A2: 元素名称 | B2: 物料名称 | C2: 物料价格/元 | D2: 11.27 | E2: 12.11 | F2: 12.18 | G2: 12.25 | H2: 1.8 | I2: 1.15 | J2: 1.22 | K2: 1.29 | L2: 2.5 | M2: 2.12 | N2: 2.19 | O2: 2.26 | P2: 3.12 | Q2: 3.2 | R2: 3.26 | S2: 4.2 | T2: 4.16 | U2: 4.3 | V2: 5.7
A3: Si | B3: 硅铁 | C3: 5142 | D3: 5570 | E3: 5620 | F3: 5610 | G3: 5610 | H3: 5760 | I3: 5760 | J3: 5730 | K3: 5730 | L3: 5730 | M3: 5730 | N3: 5730 | O3: 5620 | P3: 5620 | Q3: 5810 | R3: 5935 | S3: 5935 | T3: 5810 | U3: 5810 | V3: 5810
A4: Mn | B4: 硅锰 | C4: 5252 | D4: 5650 | E4: 5650 | F4: 5600 | G4: 5600 | H4: 5800 | I4: 5800 | J4: 5750 | K4: 5750 | L4: 5750 | M4: 5750 | N4: 5750 | O4: 5750 | P4: 5750 | Q4: 5980 | R4: 5980 | S4: 6180 | T4: 6180 | U4: 6130 | V4: 6130
B5: 高碳锰铁 | C5: 5601 | D5: 6000 | E5: 5940 | F5: 5940 | G5: 5940 | H5: 5940 | I5: 5940 | J5: 6115 | K5: 6115 | L5: 6115 | M5: 6115 | N5: 6115 | O5: 6115 | P5: 6320 | Q5: 6320 | R5: 6320 | S5: 6830 | T5: 6830 | U5: 6830 | V5: 6830
B6: 中碳锰铁 | C6: 7443 | D6: 8230 | E6: 8150 | F6: 8150 | G6: 8150 | H6: 8150 | I6: 8150 | J6: 8320 | K6: 8320 | L6: 8320 | M6: 8320 | N6: 8320 | O6: 8320 | P6: 8385 | Q6: 8385 | R6: 8385 | S6: 8735 | T6: 8735 | U6: 8735 | V6: 8735
B7: 低碳锰铁 | C7: 8224 | D7: 9100 | E7: 8900 | F7: 8900 | G7: 8900 | H7: 8900 | I7: 8900 | J7: 10240 | K7: 10240 | L7: 10240 | M7: 10240 | N7: 10240 | O7: 8900 | P7: 8900 | Q7: 8900 | R7: 9500 | S7: 9500 | T7: 9500 | U7: 10150 | V7: 10150
B8: 金属锰 | C8: 12566 | D8: 14900 | E8: 15800 | F8: 15800 | G8: 15800 | H8: 15800 | I8: 15800 | J8: 15800 | K8: 15800 | L8: 15800 | M8: 15800 | N8: 15800 | O8: 17600 | P8: 17900 | Q8: 18150 | R8: 18150 | S8: 19100 | T8: 18900 | U8: 18900 | V8: 18900
A9: P | B9: 磷铁 | C9: 2761 | D9: 2700 | E9: 2700 | F9: 2700 | G9: 2700 | H9: 2700 | I9: 2700 | J9: 2700 | K9: 2700 | L9: 3200 | M9: 2700 | N9: 3200 | O9: 2900 | P9: 2800 | Q9: 2800 | R9: 2800 | S9: 2800 | T9: 2900 | U9: 2900 | V9: 2900
A10: S | B10: 硫铁线40 | C10: 3982 | D10: 5100 | E10: 5100 | F10: 5100 | G10: 5100 | H10: 5100 | I10: 5100 | J10: 5100 | K10: 5100 | L10: 5100 | M10: 5100 | N10: 5100 | O10: 5100 | P10: 5100 | Q10: 5100 | R10: 5100 | S10: 5100 | T10: 5100 | U10: 5100 | V10: 5100
A11: V | B11: 钒铁 | C11: 75450 | D11: 115900 | E11: 92000 | F11: 90000 | G11: 92000 | H11: 90000 | I11: 87000 | J11: 90000 | K11: 90000 | L11: 91000 | M11: 90000 | N11: 91000 | O11: 96000 | P11: 98000 | Q11: 94000 | R11: 94000 | S11: 94000 | T11: 96500 | U11: 96500 | V11: 96500
A12: Nb | B12: 铌铁 | C12: 217302 | D12: 244125 | E12: 244125 | F12: 244125 | G12: 246148 | H12: 246148 | I12: 246148 | J12: 246148 | K12: 246148 | L12: 246148 | M12: 246148 | N12: 246148 | O12: 246148 | P12: 242625 | Q12: 242625 | R12: 242625 | S12: 242625 | T12: 243375 | U12: 243375 | V12: 243375
A13: Ti | B13: 钛铁 | C13: 23723 | D13: 26750 | E13: 26800 | F13: 26800 | G13: 26800 | H13: 26700 | I13: 26700 | J13: 27100 | K13: 27100 | L13: 27100 | M13: 27100 | N13: 27100 | O13: 27400 | P13: 27600 | Q13: 27600 | R13: 27600 | S13: 27850 | T13: 27850 | U13: 27850 | V13: 27850
A14: Cr | B14: 高碳铬铁 | C14: 7635 | D14: 8700 | E14: 8500 | F14: 8700 | G14: 8600 | H14: 8800 | I14: 8650 | J14: 8900 | K14: 8900 | L14: 9000 | M14: 8900 | N14: 9000 | O14: 8800 | P14: 8700 | Q14: 9000 | R14: 9000 | S14: 9000 | T14: 9070 | U14: 9070 | V14: 8850
B15: 低碳铬铁 | C15: 7739 | D15: 14500 | E15: 15230 | F15: 13200 | G15: 13600 | H15: 13800 | I15: 13300 | J15: 14000 | K15: 14000 | L15: 16900 | M15: 14000 | N15: 16900 | O15: 16300 | P15: 16900 | Q15: 13800 | R15: 14200 | S15: 16900 | T15: 17080 | U15: 17080 | V15: 17080
A16: Ni | B16: 电解镍 | C16: 113628 | D16: 120100 | E16: 120300 | F16: 11900 | G16: 130000 | H16: 146000 | I16: 147000 | J16: 147000 | K16: 147000 | L16: 147000 | M16: 147000 | N16: 147000 | O16: 143750 | P16: 144050 | Q16: 139500 | R16: 139050 | S16: 137300 | T16: 144900 | U16: 155550 | V16: 155700
A17: Cu | B17: 电解铜 | C17: 76098 | D17: 87775 | E17: 94910 | F17: 94400 | G17: 98000 | H17: 103000 | I17: 104940 | J17: 103000 | K17: 103000 | L17: 103200 | M17: 103000 | N17: 103200 | O17: 102980 | P17: 103020 | Q17: 97890 | R17: 97790 | S17: 99720 | T17: 104490 | U17: 104830 | V17: 107010
A18: Mo | B18: 钼铁 | C18: 253301 | D18: 236000 | E18: 240000 | F18: 239000 | G18: 239000 | H18: 270000 | I18: 260000 | J18: 260000 | K18: 260000 | L18: 269500 | M18: 260000 | N18: 269500 | O18: 283000 | P18: 280800 | Q18: 281000 | R18: 280000 | S18: 291000 | T18: 289000 | U18: 295000 | V18: 308000
A19: B | B19: 硼铁 | C19: 17066 | D19: 23000 | E19: 23000 | F19: 23000 | G19: 23000 | H19: 25000 | I19: 24000 | J19: 24000 | K19: 24000 | L19: 21700 | M19: 24000 | N19: 21700 | O19: 21700 | P19: 21700 | Q19: 21700 | R19: 21700 | S19: 25000 | T19: 24350 | U19: 24350 | V19: 27200
A20: Als | B20: 铝块 | C20: 19218 | D20: 22380 | E20: 22380 | F20: 23030 | G20: 23030 | H20: 24950 | I20: 25440 | J20: 25440 | K20: 25600 | L20: 25600 | M20: 25600 | N20: 25600 | O20: 25330 | P20: 25330 | Q20: 25330 | R20: 25330 | S20: 25241 | T20: 25241 | U20: 25241 | V20: 25241
